Workbook
Name Build_Schedule: Inputs!$C$21:$E$30
Name Discount_Rate: Inputs!$C16
Name Learning_Rate: Inputs!$C81

Sheet Inputs
B2: BESS Economic Analysis - JIT Cohort Model
B8: PROJECT BASICS
B9: Project Name | C9: BESS JIT Project | E9: Enter project name
B10: Project ID | C10: JIT-001 | E10: Unique identifier
B11: Location | C11: Substation Z | E11: Site or market location
B12: Total Capacity (MW) | C12: =SUM(D20:D29) -> 0 | E12: Auto-summed from Build Schedule
B13: Duration (hours) | C13: 4 | E13: Storage duration for each cohort
B14: Total Energy (MWh) | C14: =C12*C13 -> 0 | E14: Auto-calculated
B15: Analysis Period (years) | C15: 20 | E15: Economic analysis horizon
B16: Discount Rate (%) | C16: 0.07 | E16: Utility WACC
B17: Ownership Type | C17: Utility | E17: Utility or Merchant
B19: PHASED BUILD SCHEDULE
B20: Cohort | C20: COD (Year) | D20: Capacity (MW) | E20: ITC Rate (%)
B21: Tranche 1 | C21: 0 | D21: 0 | E21: =IF(C21>0, C54+C55, 0) -> 0
B22: Tranche 2 | C22: 0 | D22: 0 | E22: =IF(C22>0, C54+C55, 0) -> 0
B23: Tranche 3 | C23: 0 | D23: 0 | E23: =IF(C23>0, C54+C55, 0) -> 0
B24: Tranche 4 | C24: 0 | D24: 0 | E24: =IF(C24>0, C54+C55, 0) -> 0
B25: Tranche 5 | C25: 0 | D25: 0 | E25: =IF(C25>0, C54+C55, 0) -> 0
B26: Tranche 6 | C26: 0 | D26: 0 | E26: =IF(C26>0, C54+C55, 0) -> 0
B27: Tranche 7 | C27: 0 | D27: 0 | E27: =IF(C27>0, C54+C55, 0) -> 0
B28: Tranche 8 | C28: 0 | D28: 0 | E28: =IF(C28>0, C54+C55, 0) -> 0
B29: Tranche 9 | C29: 0 | D29: 0 | E29: =IF(C29>0, C54+C55, 0) -> 0
B30: Tranche 10 | C30: 0 | D30: 0 | E30: =IF(C30>0, C54+C55, 0) -> 0
B32: T&D DEFERRAL
B33: Capital Cost (K) | C33: 100000000 | E33: Upfront capital cost of the deferred asset
B34: Time Need (t_need) | C34: 0 | E34: Year the traditional asset is needed
B35: Deferral Period (n) | C35: 5 | E35: Number of years the asset is deferred
B36: Growth Rate (g) | C36: 0.02 | E36: Annual growth rate of the capital cost
B37: PV of Deferral ($) | C37: =C32*(1-((1+C35)/(1+C16))^C34) -> 0 | E37: Present value of the T&D deferral benefit
B39: TECHNOLOGY SPECIFICATIONS
B40: Chemistry | C40: LFP | E40: LFP, NMC, or Other
B41: Round-Trip Efficiency (%) | C41: 0.85 | E41: AC-AC efficiency
B42: Annual Degradation (%) | C42: 0.025 | E42: Capacity loss per year
B43: Cycle Life | C43: 6000 | E43: Full-depth cycles before EOL
B44: Augmentation Year | C44: 12 | E44: Year of battery replacement
B45: Cycles per Day | C45: 1 | E45: Average daily charge/discharge cycles
B47: COST INPUTS (BESS)
B48: CapEx ($/kWh) | C48: 160 | D48: $/kWh | E48: Installed capital cost per kWh
B49: Fixed O&M ($/kW-year) | C49: 25 | D49: $/kW-yr | E49: Annual fixed O&M
B50: Variable O&M ($/MWh) | C50: 0 | D50: $/MWh | E50: Per-MWh discharge cost
...

Sheet Results
B2: BESS Economic Analysis Results
B4: KEY FINANCIAL METRICS
B5: Net Present Value (NPV) | C5: =Cash_Flows!I26 -> 0 | D5: Present value of all cash flows
B6: T&D Deferral PV | C6: =Inputs!C36 -> 0 | D6: Value from capital deferral
B7: Total Project Value | C7: =Cash_Flows!I26 + Inputs!C36 -> 0 | D7: NPV plus T&D Deferral Value

Sheet Cash_Flows
B2: Annual Cash Flow Projections (Cohort-Aggregated)
B4: Year | C4: CapEx | D4: O&M | E4: Charging | F4: Total Costs | G4: Benefits | H4: Net CF | I4: PV Net CF
B5: 0 | C5: =SUMPRODUCT(--(INDEX(Build_Schedule,,1)=0), INDEX(Build_Schedule,,2)*1000*Inputs!C13*Inputs!C46*(1-Inputs!C81)^(0-Inputs!C82)) -> 0 | D5: =SUMPRODUCT(--(INDEX(Build_Schedule,,1)<=0), INDEX(Build_Schedule,,2)*1000*Inputs!C47) -> 0 | E5: =SUMPRODUCT(--(INDEX(Build_Schedule,,1)<=0), INDEX(Build_Schedule,,2)*1000*Inputs!C13*Inputs!C44*365*Inputs!C51) -> 0 | F5: =SUM(C5:E5) -> 0 | G5: =SUMPRODUCT(--(INDEX(Build_Schedule,,1)<=0), INDEX(Build_Schedule,,2)*1000 * (1-Inputs!C41)^(0-INDEX(Build_Schedule,,1))) * (Inputs!C72*(1+Inputs!D72)^0) -> 0 | H5: =G5 - F5 + (=SUMPRODUCT(--(INDEX(Build_Schedule,,1)=0), INDEX(Build_Schedule,,2)*1000*Inputs!C13*Inputs!C46*(1-Inputs!C81)^(0-Inputs!C82)*INDEX(Build_Schedule,,3))) -> 0 | I5: =H5/(1+Inputs!C16)^0 -> 0
B6: 1 | C6: =SUMPRODUCT(--(INDEX(Build_Schedule,,1)=1), INDEX(Build_Schedule,,2)*1000*Inputs!C13*Inputs!C46*(1-Inputs!C81)^(1-Inputs!C82)) -> 0 | D6: =SUMPRODUCT(--(INDEX(Build_Schedule,,1)<=1), INDEX(Build_Schedule,,2)*1000*Inputs!C47) -> 0 | E6: =SUMPRODUCT(--(INDEX(Build_Schedule,,1)<=1), INDEX(Build_Schedule,,2)*1000*Inputs!C13*Inputs!C44*365*Inputs!C51) -> 0 | F6: =SUM(C6:E6) -> 0 | G6: =SUMPRODUCT(--(INDEX(Build_Schedule,,1)<=1), INDEX(Build_Schedule,,2)*1000 * (1-Inputs!C41)^(1-INDEX(Build_Schedule,,1))) * (Inputs!C72*(1+Inputs!D72)^1) -> 0 | H6: =G6 - F6 + (=SUMPRODUCT(--(INDEX(Build_Schedule,,1)=1), INDEX(Build_Schedule,,2)*1000*Inputs!C13*Inputs!C46*(1-Inputs!C81)^(1-Inputs!C82)*INDEX(Build_Schedule,,3))) -> 0 | I6: =H6/(1+Inputs!C16)^1 -> 0
B7: 2 | C7: =SUMPRODUCT(--(INDEX(Build_Schedule,,1)=2), INDEX(Build_Schedule,,2)*1000*Inputs!C13*Inputs!C46*(1-Inputs!C81)^(2-Inputs!C82)) -> 0 | D7: =SUMPRODUCT(--(INDEX(Build_Schedule,,1)<=2), INDEX(Build_Schedule,,2)*1000*Inputs!C47) -> 0 | E7: =SUMPRODUCT(--(INDEX(Build_Schedule,,1)<=2), INDEX(Build_Schedule,,2)*1000*Inputs!C13*Inputs!C44*365*Inputs!C51) -> 0 | F7: =SUM(C7:E7) -> 0 | G7: =SUMPRODUCT(--(INDEX(Build_Schedule,,1)<=2), INDEX(Build_Schedule,,2)*1000 * (1-Inputs!C41)^(2-INDEX(Build_Schedule,,1))) * (Inputs!C72*(1+Inputs!D72)^2) -> 0 | H7: =G7 - F7 + (=SUMPRODUCT(--(INDEX(Build_Schedule,,1)=2), INDEX(Build_Schedule,,2)*1000*Inputs!C13*Inputs!C46*(1-Inputs!C81)^(2-Inputs!C82)*INDEX(Build_Schedule,,3))) -> 0 | I7: =H7/(1+Inputs!C16)^2 -> 0
B8: 3 | C8: =SUMPRODUCT(--(INDEX(Build_Schedule,,1)=3), INDEX(Build_Schedule,,2)*1000*Inputs!C13*Inputs!C46*(1-Inputs!C81)^(3-Inputs!C82)) -> 0 | D8: =SUMPRODUCT(--(INDEX(Build_Schedule,,1)<=3), INDEX(Build_Schedule,,2)*1000*Inputs!C47) -> 0 | E8: =SUMPRODUCT(--(INDEX(Build_Schedule,,1)<=3), INDEX(Build_Schedule,,2)*1000*Inputs!C13*Inputs!C44*365*Inputs!C51) -> 0 | F8: =SUM(C8:E8) -> 0 | G8: =SUMPRODUCT(--(INDEX(Build_Schedule,,1)<=3), INDEX(Build_Schedule,,2)*1000 * (1-Inputs!C41)^(3-INDEX(Build_Schedule,,1))) * (Inputs!C72*(1+Inputs!D72)^3) -> 0 | H8: =G8 - F8 + (=SUMPRODUCT(--(INDEX(Build_Schedule,,1)=3), INDEX(Build_Schedule,,2)*1000*Inputs!C13*Inputs!C46*(1-Inputs!C81)^(3-Inputs!C82)*INDEX(Build_Schedule,,3))) -> 0 | I8: =H8/(1+Inputs!C16)^3 -> 0
B9: 4 | C9: =SUMPRODUCT(--(INDEX(Build_Schedule,,1)=4), INDEX(Build_Schedule,,2)*1000*Inputs!C13*Inputs!C46*(1-Inputs!C81)^(4-Inputs!C82)) -> 0 | D9: =SUMPRODUCT(--(INDEX(Build_Schedule,,1)<=4), INDEX(Build_Schedule,,2)*1000*Inputs!C47) -> 0 | E9: =SUMPRODUCT(--(INDEX(Build_Schedule,,1)<=4), INDEX(Build_Schedule,,2)*1000*Inputs!C13*Inputs!C44*365*Inputs!C51) -> 0 | F9: =SUM(C9:E9) -> 0 | G9: =SUMPRODUCT(--(INDEX(Build_Schedule,,1)<=4), INDEX(Build_Schedule,,2)*1000 * (1-Inputs!C41)^(4-INDEX(Build_Schedule,,1))) * (Inputs!C72*(1+Inputs!D72)^4) -> 0 | H9: =G9 - F9 + (=SUMPRODUCT(--(INDEX(Build_Schedule,,1)=4), INDEX(Build_Schedule,,2)*1000*Inputs!C13*Inputs!C46*(1-Inputs!C81)^(4-Inputs!C82)*INDEX(Build_Schedule,,3))) -> 0 | I9: =H9/(1+Inputs!C16)^4 -> 0
B10: 5 | C10: =SUMPRODUCT(--(INDEX(Build_Schedule,,1)=5), INDEX(Build_Schedule,,2)*1000*Inputs!C13*Inputs!C46*(1-Inputs!C81)^(5-Inputs!C82)) -> 0 | D10: =SUMPRODUCT(--(INDEX(Build_Schedule,,1)<=5), INDEX(Build_Schedule,,2)*1000*Inputs!C47) -> 0 | E10: =SUMPRODUCT(--(INDEX(Build_Schedule,,1)<=5), INDEX(Build_Schedule,,2)*1000*Inputs!C13*Inputs!C44*365*Inputs!C51) -> 0 | F10: =SUM(C10:E10) -> 0 | G10: =SUMPRODUCT(--(INDEX(Build_Schedule,,1)<=5), INDEX(Build_Schedule,,2)*1000 * (1-Inputs!C41)^(5-INDEX(Build_Schedule,,1))) * (Inputs!C72*(1+Inputs!D72)^5) -> 0 | H10: =G10 - F10 + (=SUMPRODUCT(--(INDEX(Build_Schedule,,1)=5), INDEX(Build_Schedule,,2)*1000*Inputs!C13*Inputs!C46*(1-Inputs!C81)^(5-Inputs!C82)*INDEX(Build_Schedule,,3))) -> 0 | I10: =H10/(1+Inputs!C16)^5 -> 0
B11: 6 | C11: =SUMPRODUCT(--(INDEX(Build_Schedule,,1)=6), INDEX(Build_Schedule,,2)*1000*Inputs!C13*Inputs!C46*(1-Inputs!C81)^(6-Inputs!C82)) -> 0 | D11: =SUMPRODUCT(--(INDEX(Build_Schedule,,1)<=6), INDEX(Build_Schedule,,2)*1000*Inputs!C47) -> 0 | E11: =SUMPRODUCT(--(INDEX(Build_Schedule,,1)<=6), INDEX(Build_Schedule,,2)*1000*Inputs!C13*Inputs!C44*365*Inputs!C51) -> 0 | F11: =SUM(C11:E11) -> 0 | G11: =SUMPRODUCT(--(INDEX(Build_Schedule,,1)<=6), INDEX(Build_Schedule,,2)*1000 * (1-Inputs!C41)^(6-INDEX(Build_Schedule,,1))) * (Inputs!C72*(1+Inputs!D72)^6) -> 0 | H11: =G11 - F11 + (=SUMPRODUCT(--(INDEX(Build_Schedule,,1)=6), INDEX(Build_Schedule,,2)*1000*Inputs!C13*Inputs!C46*(1-Inputs!C81)^(6-Inputs!C82)*INDEX(Build_Schedule,,3))) -> 0 | I11: =H11/(1+Inputs!C16)^6 -> 0
B12: 7 | C12: =SUMPRODUCT(--(INDEX(Build_Schedule,,1)=7), INDEX(Build_Schedule,,2)*1000*Inputs!C13*Inputs!C46*(1-Inputs!C81)^(7-Inputs!C82)) -> 0 | D12: =SUMPRODUCT(--(INDEX(Build_Schedule,,1)<=7), INDEX(Build_Schedule,,2)*1000*Inputs!C47) -> 0 | E12: =SUMPRODUCT(--(INDEX(Build_Schedule,,1)<=7), INDEX(Build_Schedule,,2)*1000*Inputs!C13*Inputs!C44*365*Inputs!C51) -> 0 | F12: =SUM(C12:E12) -> 0 | G12: =SUMPRODUCT(--(INDEX(Build_Schedule,,1)<=7), INDEX(Build_Schedule,,2)*1000 * (1-Inputs!C41)^(7-INDEX(Build_Schedule,,1))) * (Inputs!C72*(1+Inputs!D72)^7) -> 0 | H12: =G12 - F12 + (=SUMPRODUCT(--(INDEX(Build_Schedule,,1)=7), INDEX(Build_Schedule,,2)*1000*Inputs!C13*Inputs!C46*(1-Inputs!C81)^(7-Inputs!C82)*INDEX(Build_Schedule,,3))) -> 0 | I12: =H12/(1+Inputs!C16)^7 -> 0
B13: 8 | C13: =SUMPRODUCT(--(INDEX(Build_Schedule,,1)=8), INDEX(Build_Schedule,,2)*1000*Inputs!C13*Inputs!C46*(1-Inputs!C81)^(8-Inputs!C82)) -> 0 | D13: =SUMPRODUCT(--(INDEX(Build_Schedule,,1)<=8), INDEX(Build_Schedule,,2)*1000*Inputs!C47) -> 0 | E13: =SUMPRODUCT(--(INDEX(Build_Schedule,,1)<=8), INDEX(Build_Schedule,,2)*1000*Inputs!C13*Inputs!C44*365*Inputs!C51) -> 0 | F13: =SUM(C13:E13) -> 0 | G13: =SUMPRODUCT(--(INDEX(Build_Schedule,,1)<=8), INDEX(Build_Schedule,,2)*1000 * (1-Inputs!C41)^(8-INDEX(Build_Schedule,,1))) * (Inputs!C72*(1+Inputs!D72)^8) -> 0 | H13: =G13 - F13 + (=SUMPRODUCT(--(INDEX(Build_Schedule,,1)=8), INDEX(Build_Schedule,,2)*1000*Inputs!C13*Inputs!C46*(1-Inputs!C81)^(8-Inputs!C82)*INDEX(Build_Schedule,,3))) -> 0 | I13: =H13/(1+Inputs!C16)^8 -> 0
B14: 9 | C14: =SUMPRODUCT(--(INDEX(Build_Schedule,,1)=9), INDEX(Build_Schedule,,2)*1000*Inputs!C13*Inputs!C46*(1-Inputs!C81)^(9-Inputs!C82)) -> 0 | D14: =SUMPRODUCT(--(INDEX(Build_Schedule,,1)<=9), INDEX(Build_Schedule,,2)*1000*Inputs!C47) -> 0 | E14: =SUMPRODUCT(--(INDEX(Build_Schedule,,1)<=9), INDEX(Build_Schedule,,2)*1000*Inputs!C13*Inputs!C44*365*Inputs!C51) -> 0 | F14: =SUM(C14:E14) -> 0 | G14: =SUMPRODUCT(--(INDEX(Build_Schedule,,1)<=9), INDEX(Build_Schedule,,2)*1000 * (1-Inputs!C41)^(9-INDEX(Build_Schedule,,1))) * (Inputs!C72*(1+Inputs!D72)^9) -> 0 | H14: =G14 - F14 + (=SUMPRODUCT(--(INDEX(Build_Schedule,,1)=9), INDEX(Build_Schedule,,2)*1000*Inputs!C13*Inputs!C46*(1-Inputs!C81)^(9-Inputs!C82)*INDEX(Build_Schedule,,3))) -> 0 | I14: =H14/(1+Inputs!C16)^9 -> 0
B15: 10 | C15: =SUMPRODUCT(--(INDEX(Build_Schedule,,1)=10), INDEX(Build_Schedule,,2)*1000*Inputs!C13*Inputs!C46*(1-Inputs!C81)^(10-Inputs!C82)) -> 0 | D15: =SUMPRODUCT(--(INDEX(Build_Schedule,,1)<=10), INDEX(Build_Schedule,,2)*1000*Inputs!C47) -> 0 | E15: =SUMPRODUCT(--(INDEX(Build_Schedule,,1)<=10), INDEX(Build_Schedule,,2)*1000*Inputs!C13*Inputs!C44*365*Inputs!C51) -> 0 | F15: =SUM(C15:E15) -> 0 | G15: =SUMPRODUCT(--(INDEX(Build_Schedule,,1)<=10), INDEX(Build_Schedule,,2)*1000 * (1-Inputs!C41)^(10-INDEX(Build_Schedule,,1))) * (Inputs!C72*(1+Inputs!D72)^10) -> 0 | H15: =G15 - F15 + (=SUMPRODUCT(--(INDEX(Build_Schedule,,1)=10), INDEX(Build_Schedule,,2)*1000*Inputs!C13*Inputs!C46*(1-Inputs!C81)^(10-Inputs!C82)*INDEX(Build_Schedule,,3))) -> 0 | I15: =H15/(1+Inputs!C16)^10 -> 0
B16: 11 | C16: =SUMPRODUCT(--(INDEX(Build_Schedule,,1)=11), INDEX(Build_Schedule,,2)*1000*Inputs!C13*Inputs!C46*(1-Inputs!C81)^(11-Inputs!C82)) -> 0 | D16: =SUMPRODUCT(--(INDEX(Build_Schedule,,1)<=11), INDEX(Build_Schedule,,2)*1000*Inputs!C47) -> 0 | E16: =SUMPRODUCT(--(INDEX(Build_Schedule,,1)<=11), INDEX(Build_Schedule,,2)*1000*Inputs!C13*Inputs!C44*365*Inputs!C51) -> 0 | F16: =SUM(C16:E16) -> 0 | G16: =SUMPRODUCT(--(INDEX(Build_Schedule,,1)<=11), INDEX(Build_Schedule,,2)*1000 * (1-Inputs!C41)^(11-INDEX(Build_Schedule,,1))) * (Inputs!C72*(1+Inputs!D72)^11) -> 0 | H16: =G16 - F16 + (=SUMPRODUCT(--(INDEX(Build_Schedule,,1)=11), INDEX(Build_Schedule,,2)*1000*Inputs!C13*Inputs!C46*(1-Inputs!C81)^(11-Inputs!C82)*INDEX(Build_Schedule,,3))) -> 0 | I16: =H16/(1+Inputs!C16)^11 -> 0
B17: 12 | C17: =SUMPRODUCT(--(INDEX(Build_Schedule,,1)=12), INDEX(Build_Schedule,,2)*1000*Inputs!C13*Inputs!C46*(1-Inputs!C81)^(12-Inputs!C82)) -> 0 | D17: =SUMPRODUCT(--(INDEX(Build_Schedule,,1)<=12), INDEX(Build_Schedule,,2)*1000*Inputs!C47) -> 0 | E17: =SUMPRODUCT(--(INDEX(Build_Schedule,,1)<=12), INDEX(Build_Schedule,,2)*1000*Inputs!C13*Inputs!C44*365*Inputs!C51) -> 0 | F17: =SUM(C17:E17) -> 0 | G17: =SUMPRODUCT(--(INDEX(Build_Schedule,,1)<=12), INDEX(Build_Schedule,,2)*1000 * (1-Inputs!C41)^(12-INDEX(Build_Schedule,,1))) * (Inputs!C72*(1+Inputs!D72)^12) -> 0 | H17: =G17 - F17 + (=SUMPRODUCT(--(INDEX(Build_Schedule,,1)=12), INDEX(Build_Schedule,,2)*1000*Inputs!C13*Inputs!C46*(1-Inputs!C81)^(12-Inputs!C82)*INDEX(Build_Schedule,,3))) -> 0 | I17: =H17/(1+Inputs!C16)^12 -> 0
B18: 13 | C18: =SUMPRODUCT(--(INDEX(Build_Schedule,,1)=13), INDEX(Build_Schedule,,2)*1000*Inputs!C13*Inputs!C46*(1-Inputs!C81)^(13-Inputs!C82)) -> 0 | D18: =SUMPRODUCT(--(INDEX(Build_Schedule,,1)<=13), INDEX(Build_Schedule,,2)*1000*Inputs!C47) -> 0 | E18: =SUMPRODUCT(--(INDEX(Build_Schedule,,1)<=13), INDEX(Build_Schedule,,2)*1000*Inputs!C13*Inputs!C44*365*Inputs!C51) -> 0 | F18: =SUM(C18:E18) -> 0 | G18: =SUMPRODUCT(--(INDEX(Build_Schedule,,1)<=13), INDEX(Build_Schedule,,2)*1000 * (1-Inputs!C41)^(13-INDEX(Build_Schedule,,1))) * (Inputs!C72*(1+Inputs!D72)^13) -> 0 | H18: =G18 - F18 + (=SUMPRODUCT(--(INDEX(Build_Schedule,,1)=13), INDEX(Build_Schedule,,2)*1000*Inputs!C13*Inputs!C46*(1-Inputs!C81)^(13-Inputs!C82)*INDEX(Build_Schedule,,3))) -> 0 | I18: =H18/(1+Inputs!C16)^13 -> 0
B19: 14 | C19: =SUMPRODUCT(--(INDEX(Build_Schedule,,1)=14), INDEX(Build_Schedule,,2)*1000*Inputs!C13*Inputs!C46*(1-Inputs!C81)^(14-Inputs!C82)) -> 0 | D19: =SUMPRODUCT(--(INDEX(Build_Schedule,,1)<=14), INDEX(Build_Schedule,,2)*1000*Inputs!C47) -> 0 | E19: =SUMPRODUCT(--(INDEX(Build_Schedule,,1)<=14), INDEX(Build_Schedule,,2)*1000*Inputs!C13*Inputs!C44*365*Inputs!C51) -> 0 | F19: =SUM(C19:E19) -> 0 | G19: =SUMPRODUCT(--(INDEX(Build_Schedule,,1)<=14), INDEX(Build_Schedule,,2)*1000 * (1-Inputs!C41)^(14-INDEX(Build_Schedule,,1))) * (Inputs!C72*(1+Inputs!D72)^14) -> 0 | H19: =G19 - F19 + (=SUMPRODUCT(--(INDEX(Build_Schedule,,1)=14), INDEX(Build_Schedule,,2)*1000*Inputs!C13*Inputs!C46*(1-Inputs!C81)^(14-Inputs!C82)*INDEX(Build_Schedule,,3))) -> 0 | I19: =H19/(1+Inputs!C16)^14 -> 0
B20: 15 | C20: =SUMPRODUCT(--(INDEX(Build_Schedule,,1)=15), INDEX(Build_Schedule,,2)*1000*Inputs!C13*Inputs!C46*(1-Inputs!C81)^(15-Inputs!C82)) -> 0 | D20: =SUMPRODUCT(--(INDEX(Build_Schedule,,1)<=15), INDEX(Build_Schedule,,2)*1000*Inputs!C47) -> 0 | E20: =SUMPRODUCT(--(INDEX(Build_Schedule,,1)<=15), INDEX(Build_Schedule,,2)*1000*Inputs!C13*Inputs!C44*365*Inputs!C51) -> 0 | F20: =SUM(C20:E20) -> 0 | G20: =SUMPRODUCT(--(INDEX(Build_Schedule,,1)<=15), INDEX(Build_Schedule,,2)*1000 * (1-Inputs!C41)^(15-INDEX(Build_Schedule,,1))) * (Inputs!C72*(1+Inputs!D72)^15) -> 0 | H20: =G20 - F20 + (=SUMPRODUCT(--(INDEX(Build_Schedule,,1)=15), INDEX(Build_Schedule,,2)*1000*Inputs!C13*Inputs!C46*(1-Inputs!C81)^(15-Inputs!C82)*INDEX(Build_Schedule,,3))) -> 0 | I20: =H20/(1+Inputs!C16)^15 -> 0
B21: 16 | C21: =SUMPRODUCT(--(INDEX(Build_Schedule,,1)=16), INDEX(Build_Schedule,,2)*1000*Inputs!C13*Inputs!C46*(1-Inputs!C81)^(16-Inputs!C82)) -> 0 | D21: =SUMPRODUCT(--(INDEX(Build_Schedule,,1)<=16), INDEX(Build_Schedule,,2)*1000*Inputs!C47) -> 0 | E21: =SUMPRODUCT(--(INDEX(Build_Schedule,,1)<=16), INDEX(Build_Schedule,,2)*1000*Inputs!C13*Inputs!C44*365*Inputs!C51) -> 0 | F21: =SUM(C21:E21) -> 0 | G21: =SUMPRODUCT(--(INDEX(Build_Schedule,,1)<=16), INDEX(Build_Schedule,,2)*1000 * (1-Inputs!C41)^(16-INDEX(Build_Schedule,,1))) * (Inputs!C72*(1+Inputs!D72)^16) -> 0 | H21: =G21 - F21 + (=SUMPRODUCT(--(INDEX(Build_Schedule,,1)=16), INDEX(Build_Schedule,,2)*1000*Inputs!C13*Inputs!C46*(1-Inputs!C81)^(16-Inputs!C82)*INDEX(Build_Schedule,,3))) -> 0 | I21: =H21/(1+Inputs!C16)^16 -> 0
B22: 17 | C22: =SUMPRODUCT(--(INDEX(Build_Schedule,,1)=17), INDEX(Build_Schedule,,2)*1000*Inputs!C13*Inputs!C46*(1-Inputs!C81)^(17-Inputs!C82)) -> 0 | D22: =SUMPRODUCT(--(INDEX(Build_Schedule,,1)<=17), INDEX(Build_Schedule,,2)*1000*Inputs!C47) -> 0 | E22: =SUMPRODUCT(--(INDEX(Build_Schedule,,1)<=17), INDEX(Build_Schedule,,2)*1000*Inputs!C13*Inputs!C44*365*Inputs!C51) -> 0 | F22: =SUM(C22:E22) -> 0 | G22: =SUMPRODUCT(--(INDEX(Build_Schedule,,1)<=17), INDEX(Build_Schedule,,2)*1000 * (1-Inputs!C41)^(17-INDEX(Build_Schedule,,1))) * (Inputs!C72*(1+Inputs!D72)^17) -> 0 | H22: =G22 - F22 + (=SUMPRODUCT(--(INDEX(Build_Schedule,,1)=17), INDEX(Build_Schedule,,2)*1000*Inputs!C13*Inputs!C46*(1-Inputs!C81)^(17-Inputs!C82)*INDEX(Build_Schedule,,3))) -> 0 | I22: =H22/(1+Inputs!C16)^17 -> 0
B23: 18 | C23: =SUMPRODUCT(--(INDEX(Build_Schedule,,1)=18), INDEX(Build_Schedule,,2)*1000*Inputs!C13*Inputs!C46*(1-Inputs!C81)^(18-Inputs!C82)) -> 0 | D23: =SUMPRODUCT(--(INDEX(Build_Schedule,,1)<=18), INDEX(Build_Schedule,,2)*1000*Inputs!C47) -> 0 | E23: =SUMPRODUCT(--(INDEX(Build_Schedule,,1)<=18), INDEX(Build_Schedule,,2)*1000*Inputs!C13*Inputs!C44*365*Inputs!C51) -> 0 | F23: =SUM(C23:E23) -> 0 | G23: =SUMPRODUCT(--(INDEX(Build_Schedule,,1)<=18), INDEX(Build_Schedule,,2)*1000 * (1-Inputs!C41)^(18-INDEX(Build_Schedule,,1))) * (Inputs!C72*(1+Inputs!D72)^18) -> 0 | H23: =G23 - F23 + (=SUMPRODUCT(--(INDEX(Build_Schedule,,1)=18), INDEX(Build_Schedule,,2)*1000*Inputs!C13*Inputs!C46*(1-Inputs!C81)^(18-Inputs!C82)*INDEX(Build_Schedule,,3))) -> 0 | I23: =H23/(1+Inputs!C16)^18 -> 0
B24: 19 | C24: =SUMPRODUCT(--(INDEX(Build_Schedule,,1)=19), INDEX(Build_Schedule,,2)*1000*Inputs!C13*Inputs!C46*(1-Inputs!C81)^(19-Inputs!C82)) -> 0 | D24: =SUMPRODUCT(--(INDEX(Build_Schedule,,1)<=19), INDEX(Build_Schedule,,2)*1000*Inputs!C47) -> 0 | E24: =SUMPRODUCT(--(INDEX(Build_Schedule,,1)<=19), INDEX(Build_Schedule,,2)*1000*Inputs!C13*Inputs!C44*365*Inputs!C51) -> 0 | F24: =SUM(C24:E24) -> 0 | G24: =SUMPRODUCT(--(INDEX(Build_Schedule,,1)<=19), INDEX(Build_Schedule,,2)*1000 * (1-Inputs!C41)^(19-INDEX(Build_Schedule,,1))) * (Inputs!C72*(1+Inputs!D72)^19) -> 0 | H24: =G24 - F24 + (=SUMPRODUCT(--(INDEX(Build_Schedule,,1)=19), INDEX(Build_Schedule,,2)*1000*Inputs!C13*Inputs!C46*(1-Inputs!C81)^(19-Inputs!C82)*INDEX(Build_Schedule,,3))) -> 0 | I24: =H24/(1+Inputs!C16)^19 -> 0
B25: 20 | C25: =SUMPRODUCT(--(INDEX(Build_Schedule,,1)=20), INDEX(Build_Schedule,,2)*1000*Inputs!C13*Inputs!C46*(1-Inputs!C81)^(20-Inputs!C82)) -> 0 | D25: =SUMPRODUCT(--(INDEX(Build_Schedule,,1)<=20), INDEX(Build_Schedule,,2)*1000*Inputs!C47) -> 0 | E25: =SUMPRODUCT(--(INDEX(Build_Schedule,,1)<=20), INDEX(Build_Schedule,,2)*1000*Inputs!C13*Inputs!C44*365*Inputs!C51) -> 0 | F25: =SUM(C25:E25) -> 0 | G25: =SUMPRODUCT(--(INDEX(Build_Schedule,,1)<=20), INDEX(Build_Schedule,,2)*1000 * (1-Inputs!C41)^(20-INDEX(Build_Schedule,,1))) * (Inputs!C72*(1+Inputs!D72)^20) -> 0 | H25: =G25 - F25 + (=SUMPRODUCT(--(INDEX(Build_Schedule,,1)=20), INDEX(Build_Schedule,,2)*1000*Inputs!C13*Inputs!C46*(1-Inputs!C81)^(20-Inputs!C82)*INDEX(Build_Schedule,,3))) -> 0 | I25: =H25/(1+Inputs!C16)^20 -> 0
B26: TOTALS | I26: =SUM(I5:I25) -> 0

Sheet Calculations
B2: Calculation Engine (Cohort-Based)
B4: COHORT-BASED CALCULATIONS
B5: Total Capacity (kW) | C5: =Inputs!C12*1000 -> 0 | D5: Sum of all cohort capacities in kW
B6: Total Energy (kWh) | C6: =Inputs!C14*1000 -> 0 | D6: Sum of all cohort energies in kWh
B7: Total Battery CapEx ($) | C7: =SUMPRODUCT(INDEX(Build_Schedule,,2)*1000*Inputs!C13, Inputs!C46*(1-Inputs!C81)^(INDEX(Build_Schedule,,1)-Inputs!C82)) -> 0 | D7: Sum of CapEx for each cohort, adjusted for learning rate based on COD
B8: Total ITC Credit ($) | C8: =SUMPRODUCT(INDEX(Build_Schedule,,2)*1000*Inputs!C13, Inputs!C46*(1-Inputs!C81)^(INDEX(Build_Schedule,,1)-Inputs!C82), INDEX(Build_Schedule,,3)) -> 0 | D8: Sum of ITC for each cohort based on its specific CapEx
B9: Net Year 0 Cost ($) | C9: =C7-C8 -> 0 | D9: Total CapEx minus Total ITC
