Workbook
Name Build_Schedule: Inputs!$C$20:$E$29
Name Discount_Rate: Inputs!$C16
Name Learning_Rate: Inputs!$C81

Sheet Inputs
B2: BESS Economic Analyzer — JIT Cohort Model
B3: Version 2.0 | February 2026 | For Electric Utility Engineering & Finance
B5: ASSUMPTION LIBRARY
B6: Selected Library | C6: NREL ATB 2024 - Moderate Scenario | D6: ↑ Overrides defaults below | F6: Options: NREL ATB 2024 - Moderate Scenario | Lazard LCOS v10.0 - 2025 | CPUC California 2024
B8: PROJECT BASICS
B9: Project Name | C9: My BESS Project | F9: Descriptive project name
B10: Project ID | C10: BESS-001 | F10: Unique identifier for tracking
B11: Location / Market | C11: CAISO NP15 | F11: ISO zone or substation name
B12: Total Capacity (MW) | C12: =SUM(D20:D29) -> 0 | F12: Auto-summed from Build Schedule
B13: Duration (hours) | C13: 4 | F13: 1–8 hrs typical utility-scale
B14: Total Energy (MWh) | C14: =C12*C13 -> 0 | F14: Auto-calculated
B15: Analysis Period (years) | C15: 20 | F15: 15–25 yrs typical
B16: Discount Rate (WACC) | C16: 0.07 | F16: 6–10% utility; 8–12% merchant
B17: Ownership Type | C17: Utility | F17: "Utility" or "Merchant"
B18: PHASED BUILD SCHEDULE (JIT Cohort Model)
B19: Cohort | C19: COD Year | D19: Capacity (MW) | E19: ITC Rate (%)
B20: Tranche 1 | C20: 2027 | D20: 20 | E20: =IF(D20>0,Inputs!C54+Inputs!C55,0) -> 0
B21: Tranche 2 | C21: 2028 | D21: 20 | E21: =IF(D21>0,Inputs!C54+Inputs!C55,0) -> 0
B22: Tranche 3 | C22: 2029 | D22: 20 | E22: =IF(D22>0,Inputs!C54+Inputs!C55,0) -> 0
B23: Tranche 4 | C23: 2030 | D23: 20 | E23: =IF(D23>0,Inputs!C54+Inputs!C55,0) -> 0
B24: Tranche 5 | C24: 2031 | D24: 20 | E24: =IF(D24>0,Inputs!C54+Inputs!C55,0) -> 0
B25: Tranche 6 | C25: 2032 | D25: 0 | E25: =IF(D25>0,Inputs!C54+Inputs!C55,0) -> 0
B26: Tranche 7 | C26: 0 | D26: 0 | E26: =IF(D26>0,Inputs!C54+Inputs!C55,0) -> 0
B27: Tranche 8 | C27: 0 | D27: 0 | E27: =IF(D27>0,Inputs!C54+Inputs!C55,0) -> 0
B28: Tranche 9 | C28: 0 | D28: 0 | E28: =IF(D28>0,Inputs!C54+Inputs!C55,0) -> 0
B29: Tranche 10 | C29: 0 | D29: 0 | E29: =IF(D29>0,Inputs!C54+Inputs!C55,0) -> 0
B31: T&D CAPITAL DEFERRAL | PV = K × [1 − ((1+g)/(1+r))^n]
B32: Deferred Capital Cost (K) | C32: 100000000 | F32: Total traditional wires capital cost deferred ($)
B33: Year Asset Needed (t_need) | C33: 2032 | F33: Calendar year the T&D asset would otherwise be needed
B34: Deferral Period (n years) | C34: 5 | F34: Number of years the traditional investment is deferred
B35: Load Growth Rate (g) | C35: 0.02 | F35: Annual growth / inflation of the deferred capital cost
B36: PV of Deferral Benefit ($) | C36: =C32*(1-((1+C35)/(1+C16))^C34) -> 0 | F36: Present value of the T&D deferral benefit — added to Results
B38: TECHNOLOGY SPECIFICATIONS
B39: Battery Chemistry | C39: LFP | F39: LFP (default) | NMC | Other
B40: Round-Trip Efficiency (RTE) | C40: 0.85 | F40: AC-AC efficiency including inverter losses (70–95%)
B41: Annual Degradation Rate | C41: 0.025 | F41: Capacity loss per year; 2.5% typical for LFP
B42: Cycle Life (full cycles) | C42: 6000 | F42: Number of full-depth cycles before end-of-life
B43: Augmentation Year | C43: 12 | F43: Year battery modules are replaced; typically 10–12
B44: Cycles per Day | C44: 1 | F44: Average daily full charge-discharge cycles (0.1–3.0)
B45: COST INPUTS — BESS
...

Sheet Calculations
B2: CALCULATION ENGINE — Cohort-Based SUMPRODUCT Formulas
B4: COHORT-BASED COST AGGREGATION
B5: Total Capacity (kW) | C5: =Inputs!C12*1000 -> 0 | D5: Sum of all online cohort capacities in kW
B6: Total Energy (kWh) | C6: =Inputs!C14*1000 -> 0 | D6: Total energy capacity kWh
B7: Total Battery CapEx ($) | C7: =SUMPRODUCT((INDEX(Build_Schedule,,2)*1000*Inputs!C13)*(Inputs!C46*(1-Inputs!C81)^MAX(0,INDEX(Build_Schedule,,1)-Inputs!C82))) -> 0 | D7: Cohort CapEx with learning-curve adjustment by COD year
B8: Total ITC Credit ($) | C8: =SUMPRODUCT((INDEX(Build_Schedule,,2)*1000*Inputs!C13)*(Inputs!C46*(1-Inputs!C81)^MAX(0,INDEX(Build_Schedule,,1)-Inputs!C82))*INDEX(Build_Schedule,,3)) -> 0 | D8: ITC credit per cohort based on its learning-curve-adjusted CapEx
B9: Net Year-0 Battery Cost ($) | C9: =C7-C8 -> 0 | D9: Total CapEx minus ITC (before infrastructure costs)
B10: Infrastructure Costs ($) | C10: =Inputs!C12*1000*(Inputs!C57+Inputs!C58+Inputs!C59) -> 0 | D10: Interconnection + land + permitting (one-time, Year 0)
B11: Total Net Year-0 Cost ($) | C11: =C9+C10 -> 0 | D11: Battery net cost + infrastructure
B12: Annual Fixed O&M ($) | C12: =Inputs!C12*1000*Inputs!C47 -> 0 | D12: Fixed O&M when all tranches are online
B13: Annual Charging Cost ($) | C13: =Inputs!C14*Inputs!C44*365*Inputs!C51 -> 0 | D13: Annual electricity cost for charging (all tranches online)
B14: Annual Insurance ($) | C14: =C7*Inputs!C60 -> 0 | D14: Insurance = total CapEx × insurance rate
B15: Augmentation Cost (Year {aug_yr}) ($) | C15: =Inputs!C14*1000*Inputs!C49*(1-Inputs!C81)^Inputs!C43 -> 0 | D15: Augmentation adjusted for learning curve

Sheet Cash_Flows
B2: Annual Cash Flow Projections — Cohort-Aggregated
B4: Year | C4: CapEx (net ITC) | D4: Fixed O&M | E4: Charging | F4: Augment | G4: Infra | H4: Total Costs | I4: PV Costs | J4: Total Benefits | K4: PV Benefits | L4: Net CF | M4: PV Net CF | N4: Cumul CF | O4: Energy (MWh)
B5: 0 | C5: =SUMPRODUCT(--(INDEX(Build_Schedule,,1)=0),(INDEX(Build_Schedule,,2)*1000*Inputs!C13)*(Inputs!C46*(1-Inputs!C81)^MAX(0,0-Inputs!C82))*(1-INDEX(Build_Schedule,,3))) -> 0 | D5: =0 -> 0 | E5: =0 -> 0 | F5: =0 -> 0 | G5: =SUMPRODUCT(--(INDEX(Build_Schedule,,1)=0),INDEX(Build_Schedule,,2)*1000*(Inputs!C57+Inputs!C58+Inputs!C59)) -> 0 | H5: =SUM(C5:G5) -> 0 | I5: =H5/(1+Inputs!C16)^0 -> 0 | J5: =0 -> 0 | K5: =J5/(1+Inputs!C16)^0 -> 0 | L5: =J5-H5 -> 0 | M5: =L5/(1+Inputs!C16)^0 -> 0 | N5: =L5 -> 0 | O5: =0 -> 0
B6: 1 | C6: =SUMPRODUCT(--(INDEX(Build_Schedule,,1)=1),(INDEX(Build_Schedule,,2)*1000*Inputs!C13)*(Inputs!C46*(1-Inputs!C81)^MAX(0,1-Inputs!C82))*(1-INDEX(Build_Schedule,,3))) -> 0 | D6: =SUMPRODUCT(--(INDEX(Build_Schedule,,1)<1),INDEX(Build_Schedule,,2)*1000*Inputs!C47) -> 0 | E6: =SUMPRODUCT(--(INDEX(Build_Schedule,,1)<1),INDEX(Build_Schedule,,2)*1000*Inputs!C13*Inputs!C44*365*Inputs!C40*(1-Inputs!C41)^(1-INDEX(Build_Schedule,,1))*Inputs!C51) -> 0 | F6: =SUMPRODUCT(--(INDEX(Build_Schedule,,1)+Inputs!C43=1),INDEX(Build_Schedule,,2)*1000*Inputs!C13*Inputs!C49*(1-Inputs!C81)^MAX(0,Inputs!C43)) -> 0 | G6: =SUMPRODUCT(--(INDEX(Build_Schedule,,1)=1),INDEX(Build_Schedule,,2)*1000*(Inputs!C57+Inputs!C58+Inputs!C59)) -> 0 | H6: =SUM(C6:G6) -> 0 | I6: =H6/(1+Inputs!C16)^1 -> 0 | J6: =SUMPRODUCT(--(INDEX(Build_Schedule,,1)<1),INDEX(Build_Schedule,,2)*1000*(1-Inputs!C41)^(1-INDEX(Build_Schedule,,1)))*Inputs!C72*(1+Inputs!D72)^0/IFERROR(Inputs!C12*1000,1)+SUMPRODUCT(--(INDEX(Build_Schedule,,1)<1),INDEX(Build_Schedule,,2)*1000*(1-Inputs!C41)^(1-INDEX(Build_Schedule,,1)))*Inputs!C73*(1+Inputs!D73)^0/IFERROR(Inputs!C12*1000,1)+SUMPRODUCT(--(INDEX(Build_Schedule,,1)<1),INDEX(Build_Schedule,,2)*1000*(1-Inputs!C41)^(1-INDEX(Build_Schedule,,1)))*Inputs!C74*(1+Inputs!D74)^0/IFERROR(Inputs!C12*1000,1)+SUMPRODUCT(--(INDEX(Build_Schedule,,1)<1),INDEX(Build_Schedule,,2)*1000*(1-Inputs!C41)^(1-INDEX(Build_Schedule,,1)))*Inputs!C75*(1+Inputs!D75)^0/IFERROR(Inputs!C12*1000,1)+SUMPRODUCT(--(INDEX(Build_Schedule,,1)<1),INDEX(Build_Schedule,,2)*1000*(1-Inputs!C41)^(1-INDEX(Build_Schedule,,1)))*Inputs!C76*(1+Inputs!D76)^0/IFERROR(Inputs!C12*1000,1)+SUMPRODUCT(--(INDEX(Build_Schedule,,1)<1),INDEX(Build_Schedule,,2)*1000*(1-Inputs!C41)^(1-INDEX(Build_Schedule,,1)))*Inputs!C77*(1+Inputs!D77)^0/IFERROR(Inputs!C12*1000,1)+SUMPRODUCT(--(INDEX(Build_Schedule,,1)<1),INDEX(Build_Schedule,,2)*1000*(1-Inputs!C41)^(1-INDEX(Build_Schedule,,1)))*Inputs!C78*(1+Inputs!D78)^0/IFERROR(Inputs!C12*1000,1)+SUMPRODUCT(--(INDEX(Build_Schedule,,1)<1),INDEX(Build_Schedule,,2)*1000*(1-Inputs!C41)^(1-INDEX(Build_Schedule,,1)))*Inputs!C79*(1+Inputs!D79)^0/IFERROR(Inputs!C12*1000,1) -> 0 | K6: =J6/(1+Inputs!C16)^1 -> 0 | L6: =J6-H6 -> 0 | M6: =L6/(1+Inputs!C16)^1 -> 0 | N6: =N5+L6 -> 0 | O6: =SUMPRODUCT(--(INDEX(Build_Schedule,,1)<1),INDEX(Build_Schedule,,2)*Inputs!C13*Inputs!C44*365*Inputs!C40*(1-Inputs!C41)^(1-INDEX(Build_Schedule,,1))) -> 0
B7: 2 | C7: =SUMPRODUCT(--(INDEX(Build_Schedule,,1)=2),(INDEX(Build_Schedule,,2)*1000*Inputs!C13)*(Inputs!C46*(1-Inputs!C81)^MAX(0,2-Inputs!C82))*(1-INDEX(Build_Schedule,,3))) -> 0 | D7: =SUMPRODUCT(--(INDEX(Build_Schedule,,1)<2),INDEX(Build_Schedule,,2)*1000*Inputs!C47) -> 0 | E7: =SUMPRODUCT(--(INDEX(Build_Schedule,,1)<2),INDEX(Build_Schedule,,2)*1000*Inputs!C13*Inputs!C44*365*Inputs!C40*(1-Inputs!C41)^(2-INDEX(Build_Schedule,,1))*Inputs!C51) -> 0 | F7: =SUMPRODUCT(--(INDEX(Build_Schedule,,1)+Inputs!C43=2),INDEX(Build_Schedule,,2)*1000*Inputs!C13*Inputs!C49*(1-Inputs!C81)^MAX(0,Inputs!C43)) -> 0 | G7: =SUMPRODUCT(--(INDEX(Build_Schedule,,1)=2),INDEX(Build_Schedule,,2)*1000*(Inputs!C57+Inputs!C58+Inputs!C59)) -> 0 | H7: =SUM(C7:G7) -> 0 | I7: =H7/(1+Inputs!C16)^2 -> 0 | J7: =SUMPRODUCT(--(INDEX(Build_Schedule,,1)<2),INDEX(Build_Schedule,,2)*1000*(1-Inputs!C41)^(2-INDEX(Build_Schedule,,1)))*Inputs!C72*(1+Inputs!D72)^1/IFERROR(Inputs!C12*1000,1)+SUMPRODUCT(--(INDEX(Build_Schedule,,1)<2),INDEX(Build_Schedule,,2)*1000*(1-Inputs!C41)^(2-INDEX(Build_Schedule,,1)))*Inputs!C73*(1+Inputs!D73)^1/IFERROR(Inputs!C12*1000,1)+SUMPRODUCT(--(INDEX(Build_Schedule,,1)<2),INDEX(Build_Schedule,,2)*1000*(1-Inputs!C41)^(2-INDEX(Build_Schedule,,1)))*Inputs!C74*(1+Inputs!D74)^1/IFERROR(Inputs!C12*1000,1)+SUMPRODUCT(--(INDEX(Build_Schedule,,1)<2),INDEX(Build_Schedule,,2)*1000*(1-Inputs!C41)^(2-INDEX(Build_Schedule,,1)))*Inputs!C75*(1+Inputs!D75)^1/IFERROR(Inputs!C12*1000,1)+SUMPRODUCT(--(INDEX(Build_Schedule,,1)<2),INDEX(Build_Schedule,,2)*1000*(1-Inputs!C41)^(2-INDEX(Build_Schedule,,1)))*Inputs!C76*(1+Inputs!D76)^1/IFERROR(Inputs!C12*1000,1)+SUMPRODUCT(--(INDEX(Build_Schedule,,1)<2),INDEX(Build_Schedule,,2)*1000*(1-Inputs!C41)^(2-INDEX(Build_Schedule,,1)))*Inputs!C77*(1+Inputs!D77)^1/IFERROR(Inputs!C12*1000,1)+SUMPRODUCT(--(INDEX(Build_Schedule,,1)<2),INDEX(Build_Schedule,,2)*1000*(1-Inputs!C41)^(2-INDEX(Build_Schedule,,1)))*Inputs!C78*(1+Inputs!D78)^1/IFERROR(Inputs!C12*1000,1)+SUMPRODUCT(--(INDEX(Build_Schedule,,1)<2),INDEX(Build_Schedule,,2)*1000*(1-Inputs!C41)^(2-INDEX(Build_Schedule,,1)))*Inputs!C79*(1+Inputs!D79)^1/IFERROR(Inputs!C12*1000,1) -> 0 | K7: =J7/(1+Inputs!C16)^2 -> 0 | L7: =J7-H7 -> 0 | M7: =L7/(1+Inputs!C16)^2 -> 0 | N7: =N6+L7 -> 0 | O7: =SUMPRODUCT(--(INDEX(Build_Schedule,,1)<2),INDEX(Build_Schedule,,2)*Inputs!C13*Inputs!C44*365*Inputs!C40*(1-Inputs!C41)^(2-INDEX(Build_Schedule,,1))) -> 0
B8: 3 | C8: =SUMPRODUCT(--(INDEX(Build_Schedule,,1)=3),(INDEX(Build_Schedule,,2)*1000*Inputs!C13)*(Inputs!C46*(1-Inputs!C81)^MAX(0,3-Inputs!C82))*(1-INDEX(Build_Schedule,,3))) -> 0 | D8: =SUMPRODUCT(--(INDEX(Build_Schedule,,1)<3),INDEX(Build_Schedule,,2)*1000*Inputs!C47) -> 0 | E8: =SUMPRODUCT(--(INDEX(Build_Schedule,,1)<3),INDEX(Build_Schedule,,2)*1000*Inputs!C13*Inputs!C44*365*Inputs!C40*(1-Inputs!C41)^(3-INDEX(Build_Schedule,,1))*Inputs!C51) -> 0 | F8: =SUMPRODUCT(--(INDEX(Build_Schedule,,1)+Inputs!C43=3),INDEX(Build_Schedule,,2)*1000*Inputs!C13*Inputs!C49*(1-Inputs!C81)^MAX(0,Inputs!C43)) -> 0 | G8: =SUMPRODUCT(--(INDEX(Build_Schedule,,1)=3),INDEX(Build_Schedule,,2)*1000*(Inputs!C57+Inputs!C58+Inputs!C59)) -> 0 | H8: =SUM(C8:G8) -> 0 | I8: =H8/(1+Inputs!C16)^3 -> 0 | J8: =SUMPRODUCT(--(INDEX(Build_Schedule,,1)<3),INDEX(Build_Schedule,,2)*1000*(1-Inputs!C41)^(3-INDEX(Build_Schedule,,1)))*Inputs!C72*(1+Inputs!D72)^2/IFERROR(Inputs!C12*1000,1)+SUMPRODUCT(--(INDEX(Build_Schedule,,1)<3),INDEX(Build_Schedule,,2)*1000*(1-Inputs!C41)^(3-INDEX(Build_Schedule,,1)))*Inputs!C73*(1+Inputs!D73)^2/IFERROR(Inputs!C12*1000,1)+SUMPRODUCT(--(INDEX(Build_Schedule,,1)<3),INDEX(Build_Schedule,,2)*1000*(1-Inputs!C41)^(3-INDEX(Build_Schedule,,1)))*Inputs!C74*(1+Inputs!D74)^2/IFERROR(Inputs!C12*1000,1)+SUMPRODUCT(--(INDEX(Build_Schedule,,1)<3),INDEX(Build_Schedule,,2)*1000*(1-Inputs!C41)^(3-INDEX(Build_Schedule,,1)))*Inputs!C75*(1+Inputs!D75)^2/IFERROR(Inputs!C12*1000,1)+SUMPRODUCT(--(INDEX(Build_Schedule,,1)<3),INDEX(Build_Schedule,,2)*1000*(1-Inputs!C41)^(3-INDEX(Build_Schedule,,1)))*Inputs!C76*(1+Inputs!D76)^2/IFERROR(Inputs!C12*1000,1)+SUMPRODUCT(--(INDEX(Build_Schedule,,1)<3),INDEX(Build_Schedule,,2)*1000*(1-Inputs!C41)^(3-INDEX(Build_Schedule,,1)))*Inputs!C77*(1+Inputs!D77)^2/IFERROR(Inputs!C12*1000,1)+SUMPRODUCT(--(INDEX(Build_Schedule,,1)<3),INDEX(Build_Schedule,,2)*1000*(1-Inputs!C41)^(3-INDEX(Build_Schedule,,1)))*Inputs!C78*(1+Inputs!D78)^2/IFERROR(Inputs!C12*1000,1)+SUMPRODUCT(--(INDEX(Build_Schedule,,1)<3),INDEX(Build_Schedule,,2)*1000*(1-Inputs!C41)^(3-INDEX(Build_Schedule,,1)))*Inputs!C79*(1+Inputs!D79)^2/IFERROR(Inputs!C12*1000,1) -> 0 | K8: =J8/(1+Inputs!C16)^3 -> 0 | L8: =J8-H8 -> 0 | M8: =L8/(1+Inputs!C16)^3 -> 0 | N8: =N7+L8 -> 0 | O8: =SUMPRODUCT(--(INDEX(Build_Schedule,,1)<3),INDEX(Build_Schedule,,2)*Inputs!C13*Inputs!C44*365*Inputs!C40*(1-Inputs!C41)^(3-INDEX(Build_Schedule,,1))) -> 0
B9: 4 | C9: =SUMPRODUCT(--(INDEX(Build_Schedule,,1)=4),(INDEX(Build_Schedule,,2)*1000*Inputs!C13)*(Inputs!C46*(1-Inputs!C81)^MAX(0,4-Inputs!C82))*(1-INDEX(Build_Schedule,,3))) -> 0 | D9: =SUMPRODUCT(--(INDEX(Build_Schedule,,1)<4),INDEX(Build_Schedule,,2)*1000*Inputs!C47) -> 0 | E9: =SUMPRODUCT(--(INDEX(Build_Schedule,,1)<4),INDEX(Build_Schedule,,2)*1000*Inputs!C13*Inputs!C44*365*Inputs!C40*(1-Inputs!C41)^(4-INDEX(Build_Schedule,,1))*Inputs!C51) -> 0 | F9: =SUMPRODUCT(--(INDEX(Build_Schedule,,1)+Inputs!C43=4),INDEX(Build_Schedule,,2)*1000*Inputs!C13*Inputs!C49*(1-Inputs!C81)^MAX(0,Inputs!C43)) -> 0 | G9: =SUMPRODUCT(--(INDEX(Build_Schedule,,1)=4),INDEX(Build_Schedule,,2)*1000*(Inputs!C57+Inputs!C58+Inputs!C59)) -> 0 | H9: =SUM(C9:G9) -> 0 | I9: =H9/(1+Inputs!C16)^4 -> 0 | J9: =SUMPRODUCT(--(INDEX(Build_Schedule,,1)<4),INDEX(Build_Schedule,,2)*1000*(1-Inputs!C41)^(4-INDEX(Build_Schedule,,1)))*Inputs!C72*(1+Inputs!D72)^3/IFERROR(Inputs!C12*1000,1)+SUMPRODUCT(--(INDEX(Build_Schedule,,1)<4),INDEX(Build_Schedule,,2)*1000*(1-Inputs!C41)^(4-INDEX(Build_Schedule,,1)))*Inputs!C73*(1+Inputs!D73)^3/IFERROR(Inputs!C12*1000,1)+SUMPRODUCT(--(INDEX(Build_Schedule,,1)<4),INDEX(Build_Schedule,,2)*1000*(1-Inputs!C41)^(4-INDEX(Build_Schedule,,1)))*Inputs!C74*(1+Inputs!D74)^3/IFERROR(Inputs!C12*1000,1)+SUMPRODUCT(--(INDEX(Build_Schedule,,1)<4),INDEX(Build_Schedule,,2)*1000*(1-Inputs!C41)^(4-INDEX(Build_Schedule,,1)))*Inputs!C75*(1+Inputs!D75)^3/IFERROR(Inputs!C12*1000,1)+SUMPRODUCT(--(INDEX(Build_Schedule,,1)<4),INDEX(Build_Schedule,,2)*1000*(1-Inputs!C41)^(4-INDEX(Build_Schedule,,1)))*Inputs!C76*(1+Inputs!D76)^3/IFERROR(Inputs!C12*1000,1)+SUMPRODUCT(--(INDEX(Build_Schedule,,1)<4),INDEX(Build_Schedule,,2)*1000*(1-Inputs!C41)^(4-INDEX(Build_Schedule,,1)))*Inputs!C77*(1+Inputs!D77)^3/IFERROR(Inputs!C12*1000,1)+SUMPRODUCT(--(INDEX(Build_Schedule,,1)<4),INDEX(Build_Schedule,,2)*1000*(1-Inputs!C41)^(4-INDEX(Build_Schedule,,1)))*Inputs!C78*(1+Inputs!D78)^3/IFERROR(Inputs!C12*1000,1)+SUMPRODUCT(--(INDEX(Build_Schedule,,1)<4),INDEX(Build_Schedule,,2)*1000*(1-Inputs!C41)^(4-INDEX(Build_Schedule,,1)))*Inputs!C79*(1+Inputs!D79)^3/IFERROR(Inputs!C12*1000,1) -> 0 | K9: =J9/(1+Inputs!C16)^4 -> 0 | L9: =J9-H9 -> 0 | M9: =L9/(1+Inputs!C16)^4 -> 0 | N9: =N8+L9 -> 0 | O9: =SUMPRODUCT(--(INDEX(Build_Schedule,,1)<4),INDEX(Build_Schedule,,2)*Inputs!C13*Inputs!C44*365*Inputs!C40*(1-Inputs!C41)^(4-INDEX(Build_Schedule,,1))) -> 0
B10: 5 | C10: =SUMPRODUCT(--(INDEX(Build_Schedule,,1)=5),(INDEX(Build_Schedule,,2)*1000*Inputs!C13)*(Inputs!C46*(1-Inputs!C81)^MAX(0,5-Inputs!C82))*(1-INDEX(Build_Schedule,,3))) -> 0 | D10: =SUMPRODUCT(--(INDEX(Build_Schedule,,1)<5),INDEX(Build_Schedule,,2)*1000*Inputs!C47) -> 0 | E10: =SUMPRODUCT(--(INDEX(Build_Schedule,,1)<5),INDEX(Build_Schedule,,2)*1000*Inputs!C13*Inputs!C44*365*Inputs!C40*(1-Inputs!C41)^(5-INDEX(Build_Schedule,,1))*Inputs!C51) -> 0 | F10: =SUMPRODUCT(--(INDEX(Build_Schedule,,1)+Inputs!C43=5),INDEX(Build_Schedule,,2)*1000*Inputs!C13*Inputs!C49*(1-Inputs!C81)^MAX(0,Inputs!C43)) -> 0 | G10: =SUMPRODUCT(--(INDEX(Build_Schedule,,1)=5),INDEX(Build_Schedule,,2)*1000*(Inputs!C57+Inputs!C58+Inputs!C59)) -> 0 | H10: =SUM(C10:G10) -> 0 | I10: =H10/(1+Inputs!C16)^5 -> 0 | J10: =SUMPRODUCT(--(INDEX(Build_Schedule,,1)<5),INDEX(Build_Schedule,,2)*1000*(1-Inputs!C41)^(5-INDEX(Build_Schedule,,1)))*Inputs!C72*(1+Inputs!D72)^4/IFERROR(Inputs!C12*1000,1)+SUMPRODUCT(--(INDEX(Build_Schedule,,1)<5),INDEX(Build_Schedule,,2)*1000*(1-Inputs!C41)^(5-INDEX(Build_Schedule,,1)))*Inputs!C73*(1+Inputs!D73)^4/IFERROR(Inputs!C12*1000,1)+SUMPRODUCT(--(INDEX(Build_Schedule,,1)<5),INDEX(Build_Schedule,,2)*1000*(1-Inputs!C41)^(5-INDEX(Build_Schedule,,1)))*Inputs!C74*(1+Inputs!D74)^4/IFERROR(Inputs!C12*1000,1)+SUMPRODUCT(--(INDEX(Build_Schedule,,1)<5),INDEX(Build_Schedule,,2)*1000*(1-Inputs!C41)^(5-INDEX(Build_Schedule,,1)))*Inputs!C75*(1+Inputs!D75)^4/IFERROR(Inputs!C12*1000,1)+SUMPRODUCT(--(INDEX(Build_Schedule,,1)<5),INDEX(Build_Schedule,,2)*1000*(1-Inputs!C41)^(5-INDEX(Build_Schedule,,1)))*Inputs!C76*(1+Inputs!D76)^4/IFERROR(Inputs!C12*1000,1)+SUMPRODUCT(--(INDEX(Build_Schedule,,1)<5),INDEX(Build_Schedule,,2)*1000*(1-Inputs!C41)^(5-INDEX(Build_Schedule,,1)))*Inputs!C77*(1+Inputs!D77)^4/IFERROR(Inputs!C12*1000,1)+SUMPRODUCT(--(INDEX(Build_Schedule,,1)<5),INDEX(Build_Schedule,,2)*1000*(1-Inputs!C41)^(5-INDEX(Build_Schedule,,1)))*Inputs!C78*(1+Inputs!D78)^4/IFERROR(Inputs!C12*1000,1)+SUMPRODUCT(--(INDEX(Build_Schedule,,1)<5),INDEX(Build_Schedule,,2)*1000*(1-Inputs!C41)^(5-INDEX(Build_Schedule,,1)))*Inputs!C79*(1+Inputs!D79)^4/IFERROR(Inputs!C12*1000,1) -> 0 | K10: =J10/(1+Inputs!C16)^5 -> 0 | L10: =J10-H10 -> 0 | M10: =L10/(1+Inputs!C16)^5 -> 0 | N10: =N9+L10 -> 0 | O10: =SUMPRODUCT(--(INDEX(Build_Schedule,,1)<5),INDEX(Build_Schedule,,2)*Inputs!C13*Inputs!C44*365*Inputs!C40*(1-Inputs!C41)^(5-INDEX(Build_Schedule,,1))) -> 0
B11: 6 | C11: =SUMPRODUCT(--(INDEX(Build_Schedule,,1)=6),(INDEX(Build_Schedule,,2)*1000*Inputs!C13)*(Inputs!C46*(1-Inputs!C81)^MAX(0,6-Inputs!C82))*(1-INDEX(Build_Schedule,,3))) -> 0 | D11: =SUMPRODUCT(--(INDEX(Build_Schedule,,1)<6),INDEX(Build_Schedule,,2)*1000*Inputs!C47) -> 0 | E11: =SUMPRODUCT(--(INDEX(Build_Schedule,,1)<6),INDEX(Build_Schedule,,2)*1000*Inputs!C13*Inputs!C44*365*Inputs!C40*(1-Inputs!C41)^(6-INDEX(Build_Schedule,,1))*Inputs!C51) -> 0 | F11: =SUMPRODUCT(--(INDEX(Build_Schedule,,1)+Inputs!C43=6),INDEX(Build_Schedule,,2)*1000*Inputs!C13*Inputs!C49*(1-Inputs!C81)^MAX(0,Inputs!C43)) -> 0 | G11: =SUMPRODUCT(--(INDEX(Build_Schedule,,1)=6),INDEX(Build_Schedule,,2)*1000*(Inputs!C57+Inputs!C58+Inputs!C59)) -> 0 | H11: =SUM(C11:G11) -> 0 | I11: =H11/(1+Inputs!C16)^6 -> 0 | J11: =SUMPRODUCT(--(INDEX(Build_Schedule,,1)<6),INDEX(Build_Schedule,,2)*1000*(1-Inputs!C41)^(6-INDEX(Build_Schedule,,1)))*Inputs!C72*(1+Inputs!D72)^5/IFERROR(Inputs!C12*1000,1)+SUMPRODUCT(--(INDEX(Build_Schedule,,1)<6),INDEX(Build_Schedule,,2)*1000*(1-Inputs!C41)^(6-INDEX(Build_Schedule,,1)))*Inputs!C73*(1+Inputs!D73)^5/IFERROR(Inputs!C12*1000,1)+SUMPRODUCT(--(INDEX(Build_Schedule,,1)<6),INDEX(Build_Schedule,,2)*1000*(1-Inputs!C41)^(6-INDEX(Build_Schedule,,1)))*Inputs!C74*(1+Inputs!D74)^5/IFERROR(Inputs!C12*1000,1)+SUMPRODUCT(--(INDEX(Build_Schedule,,1)<6),INDEX(Build_Schedule,,2)*1000*(1-Inputs!C41)^(6-INDEX(Build_Schedule,,1)))*Inputs!C75*(1+Inputs!D75)^5/IFERROR(Inputs!C12*1000,1)+SUMPRODUCT(--(INDEX(Build_Schedule,,1)<6),INDEX(Build_Schedule,,2)*1000*(1-Inputs!C41)^(6-INDEX(Build_Schedule,,1)))*Inputs!C76*(1+Inputs!D76)^5/IFERROR(Inputs!C12*1000,1)+SUMPRODUCT(--(INDEX(Build_Schedule,,1)<6),INDEX(Build_Schedule,,2)*1000*(1-Inputs!C41)^(6-INDEX(Build_Schedule,,1)))*Inputs!C77*(1+Inputs!D77)^5/IFERROR(Inputs!C12*1000,1)+SUMPRODUCT(--(INDEX(Build_Schedule,,1)<6),INDEX(Build_Schedule,,2)*1000*(1-Inputs!C41)^(6-INDEX(Build_Schedule,,1)))*Inputs!C78*(1+Inputs!D78)^5/IFERROR(Inputs!C12*1000,1)+SUMPRODUCT(--(INDEX(Build_Schedule,,1)<6),INDEX(Build_Schedule,,2)*1000*(1-Inputs!C41)^(6-INDEX(Build_Schedule,,1)))*Inputs!C79*(1+Inputs!D79)^5/IFERROR(Inputs!C12*1000,1) -> 0 | K11: =J11/(1+Inputs!C16)^6 -> 0 | L11: =J11-H11 -> 0 | M11: =L11/(1+Inputs!C16)^6 -> 0 | N11: =N10+L11 -> 0 | O11: =SUMPRODUCT(--(INDEX(Build_Schedule,,1)<6),INDEX(Build_Schedule,,2)*Inputs!C13*Inputs!C44*365*Inputs!C40*(1-Inputs!C41)^(6-INDEX(Build_Schedule,,1))) -> 0
B12: 7 | C12: =SUMPRODUCT(--(INDEX(Build_Schedule,,1)=7),(INDEX(Build_Schedule,,2)*1000*Inputs!C13)*(Inputs!C46*(1-Inputs!C81)^MAX(0,7-Inputs!C82))*(1-INDEX(Build_Schedule,,3))) -> 0 | D12: =SUMPRODUCT(--(INDEX(Build_Schedule,,1)<7),INDEX(Build_Schedule,,2)*1000*Inputs!C47) -> 0 | E12: =SUMPRODUCT(--(INDEX(Build_Schedule,,1)<7),INDEX(Build_Schedule,,2)*1000*Inputs!C13*Inputs!C44*365*Inputs!C40*(1-Inputs!C41)^(7-INDEX(Build_Schedule,,1))*Inputs!C51) -> 0 | F12: =SUMPRODUCT(--(INDEX(Build_Schedule,,1)+Inputs!C43=7),INDEX(Build_Schedule,,2)*1000*Inputs!C13*Inputs!C49*(1-Inputs!C81)^MAX(0,Inputs!C43)) -> 0 | G12: =SUMPRODUCT(--(INDEX(Build_Schedule,,1)=7),INDEX(Build_Schedule,,2)*1000*(Inputs!C57+Inputs!C58+Inputs!C59)) -> 0 | H12: =SUM(C12:G12) -> 0 | I12: =H12/(1+Inputs!C16)^7 -> 0 | J12: =SUMPRODUCT(--(INDEX(Build_Schedule,,1)<7),INDEX(Build_Schedule,,2)*1000*(1-Inputs!C41)^(7-INDEX(Build_Schedule,,1)))*Inputs!C72*(1+Inputs!D72)^6/IFERROR(Inputs!C12*1000,1)+SUMPRODUCT(--(INDEX(Build_Schedule,,1)<7),INDEX(Build_Schedule,,2)*1000*(1-Inputs!C41)^(7-INDEX(Build_Schedule,,1)))*Inputs!C73*(1+Inputs!D73)^6/IFERROR(Inputs!C12*1000,1)+SUMPRODUCT(--(INDEX(Build_Schedule,,1)<7),INDEX(Build_Schedule,,2)*1000*(1-Inputs!C41)^(7-INDEX(Build_Schedule,,1)))*Inputs!C74*(1+Inputs!D74)^6/IFERROR(Inputs!C12*1000,1)+SUMPRODUCT(--(INDEX(Build_Schedule,,1)<7),INDEX(Build_Schedule,,2)*1000*(1-Inputs!C41)^(7-INDEX(Build_Schedule,,1)))*Inputs!C75*(1+Inputs!D75)^6/IFERROR(Inputs!C12*1000,1)+SUMPRODUCT(--(INDEX(Build_Schedule,,1)<7),INDEX(Build_Schedule,,2)*1000*(1-Inputs!C41)^(7-INDEX(Build_Schedule,,1)))*Inputs!C76*(1+Inputs!D76)^6/IFERROR(Inputs!C12*1000,1)+SUMPRODUCT(--(INDEX(Build_Schedule,,1)<7),INDEX(Build_Schedule,,2)*1000*(1-Inputs!C41)^(7-INDEX(Build_Schedule,,1)))*Inputs!C77*(1+Inputs!D77)^6/IFERROR(Inputs!C12*1000,1)+SUMPRODUCT(--(INDEX(Build_Schedule,,1)<7),INDEX(Build_Schedule,,2)*1000*(1-Inputs!C41)^(7-INDEX(Build_Schedule,,1)))*Inputs!C78*(1+Inputs!D78)^6/IFERROR(Inputs!C12*1000,1)+SUMPRODUCT(--(INDEX(Build_Schedule,,1)<7),INDEX(Build_Schedule,,2)*1000*(1-Inputs!C41)^(7-INDEX(Build_Schedule,,1)))*Inputs!C79*(1+Inputs!D79)^6/IFERROR(Inputs!C12*1000,1) -> 0 | K12: =J12/(1+Inputs!C16)^7 -> 0 | L12: =J12-H12 -> 0 | M12: =L12/(1+Inputs!C16)^7 -> 0 | N12: =N11+L12 -> 0 | O12: =SUMPRODUCT(--(INDEX(Build_Schedule,,1)<7),INDEX(Build_Schedule,,2)*Inputs!C13*Inputs!C44*365*Inputs!C40*(1-Inputs!C41)^(7-INDEX(Build_Schedule,,1))) -> 0
B13: 8 | C13: =SUMPRODUCT(--(INDEX(Build_Schedule,,1)=8),(INDEX(Build_Schedule,,2)*1000*Inputs!C13)*(Inputs!C46*(1-Inputs!C81)^MAX(0,8-Inputs!C82))*(1-INDEX(Build_Schedule,,3))) -> 0 | D13: =SUMPRODUCT(--(INDEX(Build_Schedule,,1)<8),INDEX(Build_Schedule,,2)*1000*Inputs!C47) -> 0 | E13: =SUMPRODUCT(--(INDEX(Build_Schedule,,1)<8),INDEX(Build_Schedule,,2)*1000*Inputs!C13*Inputs!C44*365*Inputs!C40*(1-Inputs!C41)^(8-INDEX(Build_Schedule,,1))*Inputs!C51) -> 0 | F13: =SUMPRODUCT(--(INDEX(Build_Schedule,,1)+Inputs!C43=8),INDEX(Build_Schedule,,2)*1000*Inputs!C13*Inputs!C49*(1-Inputs!C81)^MAX(0,Inputs!C43)) -> 0 | G13: =SUMPRODUCT(--(INDEX(Build_Schedule,,1)=8),INDEX(Build_Schedule,,2)*1000*(Inputs!C57+Inputs!C58+Inputs!C59)) -> 0 | H13: =SUM(C13:G13) -> 0 | I13: =H13/(1+Inputs!C16)^8 -> 0 | J13: =SUMPRODUCT(--(INDEX(Build_Schedule,,1)<8),INDEX(Build_Schedule,,2)*1000*(1-Inputs!C41)^(8-INDEX(Build_Schedule,,1)))*Inputs!C72*(1+Inputs!D72)^7/IFERROR(Inputs!C12*1000,1)+SUMPRODUCT(--(INDEX(Build_Schedule,,1)<8),INDEX(Build_Schedule,,2)*1000*(1-Inputs!C41)^(8-INDEX(Build_Schedule,,1)))*Inputs!C73*(1+Inputs!D73)^7/IFERROR(Inputs!C12*1000,1)+SUMPRODUCT(--(INDEX(Build_Schedule,,1)<8),INDEX(Build_Schedule,,2)*1000*(1-Inputs!C41)^(8-INDEX(Build_Schedule,,1)))*Inputs!C74*(1+Inputs!D74)^7/IFERROR(Inputs!C12*1000,1)+SUMPRODUCT(--(INDEX(Build_Schedule,,1)<8),INDEX(Build_Schedule,,2)*1000*(1-Inputs!C41)^(8-INDEX(Build_Schedule,,1)))*Inputs!C75*(1+Inputs!D75)^7/IFERROR(Inputs!C12*1000,1)+SUMPRODUCT(--(INDEX(Build_Schedule,,1)<8),INDEX(Build_Schedule,,2)*1000*(1-Inputs!C41)^(8-INDEX(Build_Schedule,,1)))*Inputs!C76*(1+Inputs!D76)^7/IFERROR(Inputs!C12*1000,1)+SUMPRODUCT(--(INDEX(Build_Schedule,,1)<8),INDEX(Build_Schedule,,2)*1000*(1-Inputs!C41)^(8-INDEX(Build_Schedule,,1)))*Inputs!C77*(1+Inputs!D77)^7/IFERROR(Inputs!C12*1000,1)+SUMPRODUCT(--(INDEX(Build_Schedule,,1)<8),INDEX(Build_Schedule,,2)*1000*(1-Inputs!C41)^(8-INDEX(Build_Schedule,,1)))*Inputs!C78*(1+Inputs!D78)^7/IFERROR(Inputs!C12*1000,1)+SUMPRODUCT(--(INDEX(Build_Schedule,,1)<8),INDEX(Build_Schedule,,2)*1000*(1-Inputs!C41)^(8-INDEX(Build_Schedule,,1)))*Inputs!C79*(1+Inputs!D79)^7/IFERROR(Inputs!C12*1000,1) -> 0 | K13: =J13/(1+Inputs!C16)^8 -> 0 | L13: =J13-H13 -> 0 | M13: =L13/(1+Inputs!C16)^8 -> 0 | N13: =N12+L13 -> 0 | O13: =SUMPRODUCT(--(INDEX(Build_Schedule,,1)<8),INDEX(Build_Schedule,,2)*Inputs!C13*Inputs!C44*365*Inputs!C40*(1-Inputs!C41)^(8-INDEX(Build_Schedule,,1))) -> 0
B14: 9 | C14: =SUMPRODUCT(--(INDEX(Build_Schedule,,1)=9),(INDEX(Build_Schedule,,2)*1000*Inputs!C13)*(Inputs!C46*(1-Inputs!C81)^MAX(0,9-Inputs!C82))*(1-INDEX(Build_Schedule,,3))) -> 0 | D14: =SUMPRODUCT(--(INDEX(Build_Schedule,,1)<9),INDEX(Build_Schedule,,2)*1000*Inputs!C47) -> 0 | E14: =SUMPRODUCT(--(INDEX(Build_Schedule,,1)<9),INDEX(Build_Schedule,,2)*1000*Inputs!C13*Inputs!C44*365*Inputs!C40*(1-Inputs!C41)^(9-INDEX(Build_Schedule,,1))*Inputs!C51) -> 0 | F14: =SUMPRODUCT(--(INDEX(Build_Schedule,,1)+Inputs!C43=9),INDEX(Build_Schedule,,2)*1000*Inputs!C13*Inputs!C49*(1-Inputs!C81)^MAX(0,Inputs!C43)) -> 0 | G14: =SUMPRODUCT(--(INDEX(Build_Schedule,,1)=9),INDEX(Build_Schedule,,2)*1000*(Inputs!C57+Inputs!C58+Inputs!C59)) -> 0 | H14: =SUM(C14:G14) -> 0 | I14: =H14/(1+Inputs!C16)^9 -> 0 | J14: =SUMPRODUCT(--(INDEX(Build_Schedule,,1)<9),INDEX(Build_Schedule,,2)*1000*(1-Inputs!C41)^(9-INDEX(Build_Schedule,,1)))*Inputs!C72*(1+Inputs!D72)^8/IFERROR(Inputs!C12*1000,1)+SUMPRODUCT(--(INDEX(Build_Schedule,,1)<9),INDEX(Build_Schedule,,2)*1000*(1-Inputs!C41)^(9-INDEX(Build_Schedule,,1)))*Inputs!C73*(1+Inputs!D73)^8/IFERROR(Inputs!C12*1000,1)+SUMPRODUCT(--(INDEX(Build_Schedule,,1)<9),INDEX(Build_Schedule,,2)*1000*(1-Inputs!C41)^(9-INDEX(Build_Schedule,,1)))*Inputs!C74*(1+Inputs!D74)^8/IFERROR(Inputs!C12*1000,1)+SUMPRODUCT(--(INDEX(Build_Schedule,,1)<9),INDEX(Build_Schedule,,2)*1000*(1-Inputs!C41)^(9-INDEX(Build_Schedule,,1)))*Inputs!C75*(1+Inputs!D75)^8/IFERROR(Inputs!C12*1000,1)+SUMPRODUCT(--(INDEX(Build_Schedule,,1)<9),INDEX(Build_Schedule,,2)*1000*(1-Inputs!C41)^(9-INDEX(Build_Schedule,,1)))*Inputs!C76*(1+Inputs!D76)^8/IFERROR(Inputs!C12*1000,1)+SUMPRODUCT(--(INDEX(Build_Schedule,,1)<9),INDEX(Build_Schedule,,2)*1000*(1-Inputs!C41)^(9-INDEX(Build_Schedule,,1)))*Inputs!C77*(1+Inputs!D77)^8/IFERROR(Inputs!C12*1000,1)+SUMPRODUCT(--(INDEX(Build_Schedule,,1)<9),INDEX(Build_Schedule,,2)*1000*(1-Inputs!C41)^(9-INDEX(Build_Schedule,,1)))*Inputs!C78*(1+Inputs!D78)^8/IFERROR(Inputs!C12*1000,1)+SUMPRODUCT(--(INDEX(Build_Schedule,,1)<9),INDEX(Build_Schedule,,2)*1000*(1-Inputs!C41)^(9-INDEX(Build_Schedule,,1)))*Inputs!C79*(1+Inputs!D79)^8/IFERROR(Inputs!C12*1000,1) -> 0 | K14: =J14/(1+Inputs!C16)^9 -> 0 | L14: =J14-H14 -> 0 | M14: =L14/(1+Inputs!C16)^9 -> 0 | N14: =N13+L14 -> 0 | O14: =SUMPRODUCT(--(INDEX(Build_Schedule,,1)<9),INDEX(Build_Schedule,,2)*Inputs!C13*Inputs!C44*365*Inputs!C40*(1-Inputs!C41)^(9-INDEX(Build_Schedule,,1))) -> 0
B15: 10 | C15: =SUMPRODUCT(--(INDEX(Build_Schedule,,1)=10),(INDEX(Build_Schedule,,2)*1000*Inputs!C13)*(Inputs!C46*(1-Inputs!C81)^MAX(0,10-Inputs!C82))*(1-INDEX(Build_Schedule,,3))) -> 0 | D15: =SUMPRODUCT(--(INDEX(Build_Schedule,,1)<10),INDEX(Build_Schedule,,2)*1000*Inputs!C47) -> 0 | E15: =SUMPRODUCT(--(INDEX(Build_Schedule,,1)<10),INDEX(Build_Schedule,,2)*1000*Inputs!C13*Inputs!C44*365*Inputs!C40*(1-Inputs!C41)^(10-INDEX(Build_Schedule,,1))*Inputs!C51) -> 0 | F15: =SUMPRODUCT(--(INDEX(Build_Schedule,,1)+Inputs!C43=10),INDEX(Build_Schedule,,2)*1000*Inputs!C13*Inputs!C49*(1-Inputs!C81)^MAX(0,Inputs!C43)) -> 0 | G15: =SUMPRODUCT(--(INDEX(Build_Schedule,,1)=10),INDEX(Build_Schedule,,2)*1000*(Inputs!C57+Inputs!C58+Inputs!C59)) -> 0 | H15: =SUM(C15:G15) -> 0 | I15: =H15/(1+Inputs!C16)^10 -> 0 | J15: =SUMPRODUCT(--(INDEX(Build_Schedule,,1)<10),INDEX(Build_Schedule,,2)*1000*(1-Inputs!C41)^(10-INDEX(Build_Schedule,,1)))*Inputs!C72*(1+Inputs!D72)^9/IFERROR(Inputs!C12*1000,1)+SUMPRODUCT(--(INDEX(Build_Schedule,,1)<10),INDEX(Build_Schedule,,2)*1000*(1-Inputs!C41)^(10-INDEX(Build_Schedule,,1)))*Inputs!C73*(1+Inputs!D73)^9/IFERROR(Inputs!C12*1000,1)+SUMPRODUCT(--(INDEX(Build_Schedule,,1)<10),INDEX(Build_Schedule,,2)*1000*(1-Inputs!C41)^(10-INDEX(Build_Schedule,,1)))*Inputs!C74*(1+Inputs!D74)^9/IFERROR(Inputs!C12*1000,1)+SUMPRODUCT(--(INDEX(Build_Schedule,,1)<10),INDEX(Build_Schedule,,2)*1000*(1-Inputs!C41)^(10-INDEX(Build_Schedule,,1)))*Inputs!C75*(1+Inputs!D75)^9/IFERROR(Inputs!C12*1000,1)+SUMPRODUCT(--(INDEX(Build_Schedule,,1)<10),INDEX(Build_Schedule,,2)*1000*(1-Inputs!C41)^(10-INDEX(Build_Schedule,,1)))*Inputs!C76*(1+Inputs!D76)^9/IFERROR(Inputs!C12*1000,1)+SUMPRODUCT(--(INDEX(Build_Schedule,,1)<10),INDEX(Build_Schedule,,2)*1000*(1-Inputs!C41)^(10-INDEX(Build_Schedule,,1)))*Inputs!C77*(1+Inputs!D77)^9/IFERROR(Inputs!C12*1000,1)+SUMPRODUCT(--(INDEX(Build_Schedule,,1)<10),INDEX(Build_Schedule,,2)*1000*(1-Inputs!C41)^(10-INDEX(Build_Schedule,,1)))*Inputs!C78*(1+Inputs!D78)^9/IFERROR(Inputs!C12*1000,1)+SUMPRODUCT(--(INDEX(Build_Schedule,,1)<10),INDEX(Build_Schedule,,2)*1000*(1-Inputs!C41)^(10-INDEX(Build_Schedule,,1)))*Inputs!C79*(1+Inputs!D79)^9/IFERROR(Inputs!C12*1000,1) -> 0 | K15: =J15/(1+Inputs!C16)^10 -> 0 | L15: =J15-H15 -> 0 | M15: =L15/(1+Inputs!C16)^10 -> 0 | N15: =N14+L15 -> 0 | O15: =SUMPRODUCT(--(INDEX(Build_Schedule,,1)<10),INDEX(Build_Schedule,,2)*Inputs!C13*Inputs!C44*365*Inputs!C40*(1-Inputs!C41)^(10-INDEX(Build_Schedule,,1))) -> 0
B16: 11 | C16: =SUMPRODUCT(--(INDEX(Build_Schedule,,1)=11),(INDEX(Build_Schedule,,2)*1000*Inputs!C13)*(Inputs!C46*(1-Inputs!C81)^MAX(0,11-Inputs!C82))*(1-INDEX(Build_Schedule,,3))) -> 0 | D16: =SUMPRODUCT(--(INDEX(Build_Schedule,,1)<11),INDEX(Build_Schedule,,2)*1000*Inputs!C47) -> 0 | E16: =SUMPRODUCT(--(INDEX(Build_Schedule,,1)<11),INDEX(Build_Schedule,,2)*1000*Inputs!C13*Inputs!C44*365*Inputs!C40*(1-Inputs!C41)^(11-INDEX(Build_Schedule,,1))*Inputs!C51) -> 0 | F16: =SUMPRODUCT(--(INDEX(Build_Schedule,,1)+Inputs!C43=11),INDEX(Build_Schedule,,2)*1000*Inputs!C13*Inputs!C49*(1-Inputs!C81)^MAX(0,Inputs!C43)) -> 0 | G16: =SUMPRODUCT(--(INDEX(Build_Schedule,,1)=11),INDEX(Build_Schedule,,2)*1000*(Inputs!C57+Inputs!C58+Inputs!C59)) -> 0 | H16: =SUM(C16:G16) -> 0 | I16: =H16/(1+Inputs!C16)^11 -> 0 | J16: =SUMPRODUCT(--(INDEX(Build_Schedule,,1)<11),INDEX(Build_Schedule,,2)*1000*(1-Inputs!C41)^(11-INDEX(Build_Schedule,,1)))*Inputs!C72*(1+Inputs!D72)^10/IFERROR(Inputs!C12*1000,1)+SUMPRODUCT(--(INDEX(Build_Schedule,,1)<11),INDEX(Build_Schedule,,2)*1000*(1-Inputs!C41)^(11-INDEX(Build_Schedule,,1)))*Inputs!C73*(1+Inputs!D73)^10/IFERROR(Inputs!C12*1000,1)+SUMPRODUCT(--(INDEX(Build_Schedule,,1)<11),INDEX(Build_Schedule,,2)*1000*(1-Inputs!C41)^(11-INDEX(Build_Schedule,,1)))*Inputs!C74*(1+Inputs!D74)^10/IFERROR(Inputs!C12*1000,1)+SUMPRODUCT(--(INDEX(Build_Schedule,,1)<11),INDEX(Build_Schedule,,2)*1000*(1-Inputs!C41)^(11-INDEX(Build_Schedule,,1)))*Inputs!C75*(1+Inputs!D75)^10/IFERROR(Inputs!C12*1000,1)+SUMPRODUCT(--(INDEX(Build_Schedule,,1)<11),INDEX(Build_Schedule,,2)*1000*(1-Inputs!C41)^(11-INDEX(Build_Schedule,,1)))*Inputs!C76*(1+Inputs!D76)^10/IFERROR(Inputs!C12*1000,1)+SUMPRODUCT(--(INDEX(Build_Schedule,,1)<11),INDEX(Build_Schedule,,2)*1000*(1-Inputs!C41)^(11-INDEX(Build_Schedule,,1)))*Inputs!C77*(1+Inputs!D77)^10/IFERROR(Inputs!C12*1000,1)+SUMPRODUCT(--(INDEX(Build_Schedule,,1)<11),INDEX(Build_Schedule,,2)*1000*(1-Inputs!C41)^(11-INDEX(Build_Schedule,,1)))*Inputs!C78*(1+Inputs!D78)^10/IFERROR(Inputs!C12*1000,1)+SUMPRODUCT(--(INDEX(Build_Schedule,,1)<11),INDEX(Build_Schedule,,2)*1000*(1-Inputs!C41)^(11-INDEX(Build_Schedule,,1)))*Inputs!C79*(1+Inputs!D79)^10/IFERROR(Inputs!C12*1000,1) -> 0 | K16: =J16/(1+Inputs!C16)^11 -> 0 | L16: =J16-H16 -> 0 | M16: =L16/(1+Inputs!C16)^11 -> 0 | N16: =N15+L16 -> 0 | O16: =SUMPRODUCT(--(INDEX(Build_Schedule,,1)<11),INDEX(Build_Schedule,,2)*Inputs!C13*Inputs!C44*365*Inputs!C40*(1-Inputs!C41)^(11-INDEX(Build_Schedule,,1))) -> 0
B17: 12 | C17: =SUMPRODUCT(--(INDEX(Build_Schedule,,1)=12),(INDEX(Build_Schedule,,2)*1000*Inputs!C13)*(Inputs!C46*(1-Inputs!C81)^MAX(0,12-Inputs!C82))*(1-INDEX(Build_Schedule,,3))) -> 0 | D17: =SUMPRODUCT(--(INDEX(Build_Schedule,,1)<12),INDEX(Build_Schedule,,2)*1000*Inputs!C47) -> 0 | E17: =SUMPRODUCT(--(INDEX(Build_Schedule,,1)<12),INDEX(Build_Schedule,,2)*1000*Inputs!C13*Inputs!C44*365*Inputs!C40*(1-Inputs!C41)^(12-INDEX(Build_Schedule,,1))*Inputs!C51) -> 0 | F17: =SUMPRODUCT(--(INDEX(Build_Schedule,,1)+Inputs!C43=12),INDEX(Build_Schedule,,2)*1000*Inputs!C13*Inputs!C49*(1-Inputs!C81)^MAX(0,Inputs!C43)) -> 0 | G17: =SUMPRODUCT(--(INDEX(Build_Schedule,,1)=12),INDEX(Build_Schedule,,2)*1000*(Inputs!C57+Inputs!C58+Inputs!C59)) -> 0 | H17: =SUM(C17:G17) -> 0 | I17: =H17/(1+Inputs!C16)^12 -> 0 | J17: =SUMPRODUCT(--(INDEX(Build_Schedule,,1)<12),INDEX(Build_Schedule,,2)*1000*(1-Inputs!C41)^(12-INDEX(Build_Schedule,,1)))*Inputs!C72*(1+Inputs!D72)^11/IFERROR(Inputs!C12*1000,1)+SUMPRODUCT(--(INDEX(Build_Schedule,,1)<12),INDEX(Build_Schedule,,2)*1000*(1-Inputs!C41)^(12-INDEX(Build_Schedule,,1)))*Inputs!C73*(1+Inputs!D73)^11/IFERROR(Inputs!C12*1000,1)+SUMPRODUCT(--(INDEX(Build_Schedule,,1)<12),INDEX(Build_Schedule,,2)*1000*(1-Inputs!C41)^(12-INDEX(Build_Schedule,,1)))*Inputs!C74*(1+Inputs!D74)^11/IFERROR(Inputs!C12*1000,1)+SUMPRODUCT(--(INDEX(Build_Schedule,,1)<12),INDEX(Build_Schedule,,2)*1000*(1-Inputs!C41)^(12-INDEX(Build_Schedule,,1)))*Inputs!C75*(1+Inputs!D75)^11/IFERROR(Inputs!C12*1000,1)+SUMPRODUCT(--(INDEX(Build_Schedule,,1)<12),INDEX(Build_Schedule,,2)*1000*(1-Inputs!C41)^(12-INDEX(Build_Schedule,,1)))*Inputs!C76*(1+Inputs!D76)^11/IFERROR(Inputs!C12*1000,1)+SUMPRODUCT(--(INDEX(Build_Schedule,,1)<12),INDEX(Build_Schedule,,2)*1000*(1-Inputs!C41)^(12-INDEX(Build_Schedule,,1)))*Inputs!C77*(1+Inputs!D77)^11/IFERROR(Inputs!C12*1000,1)+SUMPRODUCT(--(INDEX(Build_Schedule,,1)<12),INDEX(Build_Schedule,,2)*1000*(1-Inputs!C41)^(12-INDEX(Build_Schedule,,1)))*Inputs!C78*(1+Inputs!D78)^11/IFERROR(Inputs!C12*1000,1)+SUMPRODUCT(--(INDEX(Build_Schedule,,1)<12),INDEX(Build_Schedule,,2)*1000*(1-Inputs!C41)^(12-INDEX(Build_Schedule,,1)))*Inputs!C79*(1+Inputs!D79)^11/IFERROR(Inputs!C12*1000,1) -> 0 | K17: =J17/(1+Inputs!C16)^12 -> 0 | L17: =J17-H17 -> 0 | M17: =L17/(1+Inputs!C16)^12 -> 0 | N17: =N16+L17 -> 0 | O17: =SUMPRODUCT(--(INDEX(Build_Schedule,,1)<12),INDEX(Build_Schedule,,2)*Inputs!C13*Inputs!C44*365*Inputs!C40*(1-Inputs!C41)^(12-INDEX(Build_Schedule,,1))) -> 0
B18: 13 | C18: =SUMPRODUCT(--(INDEX(Build_Schedule,,1)=13),(INDEX(Build_Schedule,,2)*1000*Inputs!C13)*(Inputs!C46*(1-Inputs!C81)^MAX(0,13-Inputs!C82))*(1-INDEX(Build_Schedule,,3))) -> 0 | D18: =SUMPRODUCT(--(INDEX(Build_Schedule,,1)<13),INDEX(Build_Schedule,,2)*1000*Inputs!C47) -> 0 | E18: =SUMPRODUCT(--(INDEX(Build_Schedule,,1)<13),INDEX(Build_Schedule,,2)*1000*Inputs!C13*Inputs!C44*365*Inputs!C40*(1-Inputs!C41)^(13-INDEX(Build_Schedule,,1))*Inputs!C51) -> 0 | F18: =SUMPRODUCT(--(INDEX(Build_Schedule,,1)+Inputs!C43=13),INDEX(Build_Schedule,,2)*1000*Inputs!C13*Inputs!C49*(1-Inputs!C81)^MAX(0,Inputs!C43)) -> 0 | G18: =SUMPRODUCT(--(INDEX(Build_Schedule,,1)=13),INDEX(Build_Schedule,,2)*1000*(Inputs!C57+Inputs!C58+Inputs!C59)) -> 0 | H18: =SUM(C18:G18) -> 0 | I18: =H18/(1+Inputs!C16)^13 -> 0 | J18: =SUMPRODUCT(--(INDEX(Build_Schedule,,1)<13),INDEX(Build_Schedule,,2)*1000*(1-Inputs!C41)^(13-INDEX(Build_Schedule,,1)))*Inputs!C72*(1+Inputs!D72)^12/IFERROR(Inputs!C12*1000,1)+SUMPRODUCT(--(INDEX(Build_Schedule,,1)<13),INDEX(Build_Schedule,,2)*1000*(1-Inputs!C41)^(13-INDEX(Build_Schedule,,1)))*Inputs!C73*(1+Inputs!D73)^12/IFERROR(Inputs!C12*1000,1)+SUMPRODUCT(--(INDEX(Build_Schedule,,1)<13),INDEX(Build_Schedule,,2)*1000*(1-Inputs!C41)^(13-INDEX(Build_Schedule,,1)))*Inputs!C74*(1+Inputs!D74)^12/IFERROR(Inputs!C12*1000,1)+SUMPRODUCT(--(INDEX(Build_Schedule,,1)<13),INDEX(Build_Schedule,,2)*1000*(1-Inputs!C41)^(13-INDEX(Build_Schedule,,1)))*Inputs!C75*(1+Inputs!D75)^12/IFERROR(Inputs!C12*1000,1)+SUMPRODUCT(--(INDEX(Build_Schedule,,1)<13),INDEX(Build_Schedule,,2)*1000*(1-Inputs!C41)^(13-INDEX(Build_Schedule,,1)))*Inputs!C76*(1+Inputs!D76)^12/IFERROR(Inputs!C12*1000,1)+SUMPRODUCT(--(INDEX(Build_Schedule,,1)<13),INDEX(Build_Schedule,,2)*1000*(1-Inputs!C41)^(13-INDEX(Build_Schedule,,1)))*Inputs!C77*(1+Inputs!D77)^12/IFERROR(Inputs!C12*1000,1)+SUMPRODUCT(--(INDEX(Build_Schedule,,1)<13),INDEX(Build_Schedule,,2)*1000*(1-Inputs!C41)^(13-INDEX(Build_Schedule,,1)))*Inputs!C78*(1+Inputs!D78)^12/IFERROR(Inputs!C12*1000,1)+SUMPRODUCT(--(INDEX(Build_Schedule,,1)<13),INDEX(Build_Schedule,,2)*1000*(1-Inputs!C41)^(13-INDEX(Build_Schedule,,1)))*Inputs!C79*(1+Inputs!D79)^12/IFERROR(Inputs!C12*1000,1) -> 0 | K18: =J18/(1+Inputs!C16)^13 -> 0 | L18: =J18-H18 -> 0 | M18: =L18/(1+Inputs!C16)^13 -> 0 | N18: =N17+L18 -> 0 | O18: =SUMPRODUCT(--(INDEX(Build_Schedule,,1)<13),INDEX(Build_Schedule,,2)*Inputs!C13*Inputs!C44*365*Inputs!C40*(1-Inputs!C41)^(13-INDEX(Build_Schedule,,1))) -> 0
B19: 14 | C19: =SUMPRODUCT(--(INDEX(Build_Schedule,,1)=14),(INDEX(Build_Schedule,,2)*1000*Inputs!C13)*(Inputs!C46*(1-Inputs!C81)^MAX(0,14-Inputs!C82))*(1-INDEX(Build_Schedule,,3))) -> 0 | D19: =SUMPRODUCT(--(INDEX(Build_Schedule,,1)<14),INDEX(Build_Schedule,,2)*1000*Inputs!C47) -> 0 | E19: =SUMPRODUCT(--(INDEX(Build_Schedule,,1)<14),INDEX(Build_Schedule,,2)*1000*Inputs!C13*Inputs!C44*365*Inputs!C40*(1-Inputs!C41)^(14-INDEX(Build_Schedule,,1))*Inputs!C51) -> 0 | F19: =SUMPRODUCT(--(INDEX(Build_Schedule,,1)+Inputs!C43=14),INDEX(Build_Schedule,,2)*1000*Inputs!C13*Inputs!C49*(1-Inputs!C81)^MAX(0,Inputs!C43)) -> 0 | G19: =SUMPRODUCT(--(INDEX(Build_Schedule,,1)=14),INDEX(Build_Schedule,,2)*1000*(Inputs!C57+Inputs!C58+Inputs!C59)) -> 0 | H19: =SUM(C19:G19) -> 0 | I19: =H19/(1+Inputs!C16)^14 -> 0 | J19: =SUMPRODUCT(--(INDEX(Build_Schedule,,1)<14),INDEX(Build_Schedule,,2)*1000*(1-Inputs!C41)^(14-INDEX(Build_Schedule,,1)))*Inputs!C72*(1+Inputs!D72)^13/IFERROR(Inputs!C12*1000,1)+SUMPRODUCT(--(INDEX(Build_Schedule,,1)<14),INDEX(Build_Schedule,,2)*1000*(1-Inputs!C41)^(14-INDEX(Build_Schedule,,1)))*Inputs!C73*(1+Inputs!D73)^13/IFERROR(Inputs!C12*1000,1)+SUMPRODUCT(--(INDEX(Build_Schedule,,1)<14),INDEX(Build_Schedule,,2)*1000*(1-Inputs!C41)^(14-INDEX(Build_Schedule,,1)))*Inputs!C74*(1+Inputs!D74)^13/IFERROR(Inputs!C12*1000,1)+SUMPRODUCT(--(INDEX(Build_Schedule,,1)<14),INDEX(Build_Schedule,,2)*1000*(1-Inputs!C41)^(14-INDEX(Build_Schedule,,1)))*Inputs!C75*(1+Inputs!D75)^13/IFERROR(Inputs!C12*1000,1)+SUMPRODUCT(--(INDEX(Build_Schedule,,1)<14),INDEX(Build_Schedule,,2)*1000*(1-Inputs!C41)^(14-INDEX(Build_Schedule,,1)))*Inputs!C76*(1+Inputs!D76)^13/IFERROR(Inputs!C12*1000,1)+SUMPRODUCT(--(INDEX(Build_Schedule,,1)<14),INDEX(Build_Schedule,,2)*1000*(1-Inputs!C41)^(14-INDEX(Build_Schedule,,1)))*Inputs!C77*(1+Inputs!D77)^13/IFERROR(Inputs!C12*1000,1)+SUMPRODUCT(--(INDEX(Build_Schedule,,1)<14),INDEX(Build_Schedule,,2)*1000*(1-Inputs!C41)^(14-INDEX(Build_Schedule,,1)))*Inputs!C78*(1+Inputs!D78)^13/IFERROR(Inputs!C12*1000,1)+SUMPRODUCT(--(INDEX(Build_Schedule,,1)<14),INDEX(Build_Schedule,,2)*1000*(1-Inputs!C41)^(14-INDEX(Build_Schedule,,1)))*Inputs!C79*(1+Inputs!D79)^13/IFERROR(Inputs!C12*1000,1) -> 0 | K19: =J19/(1+Inputs!C16)^14 -> 0 | L19: =J19-H19 -> 0 | M19: =L19/(1+Inputs!C16)^14 -> 0 | N19: =N18+L19 -> 0 | O19: =SUMPRODUCT(--(INDEX(Build_Schedule,,1)<14),INDEX(Build_Schedule,,2)*Inputs!C13*Inputs!C44*365*Inputs!C40*(1-Inputs!C41)^(14-INDEX(Build_Schedule,,1))) -> 0
B20: 15 | C20: =SUMPRODUCT(--(INDEX(Build_Schedule,,1)=15),(INDEX(Build_Schedule,,2)*1000*Inputs!C13)*(Inputs!C46*(1-Inputs!C81)^MAX(0,15-Inputs!C82))*(1-INDEX(Build_Schedule,,3))) -> 0 | D20: =SUMPRODUCT(--(INDEX(Build_Schedule,,1)<15),INDEX(Build_Schedule,,2)*1000*Inputs!C47) -> 0 | E20: =SUMPRODUCT(--(INDEX(Build_Schedule,,1)<15),INDEX(Build_Schedule,,2)*1000*Inputs!C13*Inputs!C44*365*Inputs!C40*(1-Inputs!C41)^(15-INDEX(Build_Schedule,,1))*Inputs!C51) -> 0 | F20: =SUMPRODUCT(--(INDEX(Build_Schedule,,1)+Inputs!C43=15),INDEX(Build_Schedule,,2)*1000*Inputs!C13*Inputs!C49*(1-Inputs!C81)^MAX(0,Inputs!C43)) -> 0 | G20: =SUMPRODUCT(--(INDEX(Build_Schedule,,1)=15),INDEX(Build_Schedule,,2)*1000*(Inputs!C57+Inputs!C58+Inputs!C59)) -> 0 | H20: =SUM(C20:G20) -> 0 | I20: =H20/(1+Inputs!C16)^15 -> 0 | J20: =SUMPRODUCT(--(INDEX(Build_Schedule,,1)<15),INDEX(Build_Schedule,,2)*1000*(1-Inputs!C41)^(15-INDEX(Build_Schedule,,1)))*Inputs!C72*(1+Inputs!D72)^14/IFERROR(Inputs!C12*1000,1)+SUMPRODUCT(--(INDEX(Build_Schedule,,1)<15),INDEX(Build_Schedule,,2)*1000*(1-Inputs!C41)^(15-INDEX(Build_Schedule,,1)))*Inputs!C73*(1+Inputs!D73)^14/IFERROR(Inputs!C12*1000,1)+SUMPRODUCT(--(INDEX(Build_Schedule,,1)<15),INDEX(Build_Schedule,,2)*1000*(1-Inputs!C41)^(15-INDEX(Build_Schedule,,1)))*Inputs!C74*(1+Inputs!D74)^14/IFERROR(Inputs!C12*1000,1)+SUMPRODUCT(--(INDEX(Build_Schedule,,1)<15),INDEX(Build_Schedule,,2)*1000*(1-Inputs!C41)^(15-INDEX(Build_Schedule,,1)))*Inputs!C75*(1+Inputs!D75)^14/IFERROR(Inputs!C12*1000,1)+SUMPRODUCT(--(INDEX(Build_Schedule,,1)<15),INDEX(Build_Schedule,,2)*1000*(1-Inputs!C41)^(15-INDEX(Build_Schedule,,1)))*Inputs!C76*(1+Inputs!D76)^14/IFERROR(Inputs!C12*1000,1)+SUMPRODUCT(--(INDEX(Build_Schedule,,1)<15),INDEX(Build_Schedule,,2)*1000*(1-Inputs!C41)^(15-INDEX(Build_Schedule,,1)))*Inputs!C77*(1+Inputs!D77)^14/IFERROR(Inputs!C12*1000,1)+SUMPRODUCT(--(INDEX(Build_Schedule,,1)<15),INDEX(Build_Schedule,,2)*1000*(1-Inputs!C41)^(15-INDEX(Build_Schedule,,1)))*Inputs!C78*(1+Inputs!D78)^14/IFERROR(Inputs!C12*1000,1)+SUMPRODUCT(--(INDEX(Build_Schedule,,1)<15),INDEX(Build_Schedule,,2)*1000*(1-Inputs!C41)^(15-INDEX(Build_Schedule,,1)))*Inputs!C79*(1+Inputs!D79)^14/IFERROR(Inputs!C12*1000,1) -> 0 | K20: =J20/(1+Inputs!C16)^15 -> 0 | L20: =J20-H20 -> 0 | M20: =L20/(1+Inputs!C16)^15 -> 0 | N20: =N19+L20 -> 0 | O20: =SUMPRODUCT(--(INDEX(Build_Schedule,,1)<15),INDEX(Build_Schedule,,2)*Inputs!C13*Inputs!C44*365*Inputs!C40*(1-Inputs!C41)^(15-INDEX(Build_Schedule,,1))) -> 0
B21: 16 | C21: =SUMPRODUCT(--(INDEX(Build_Schedule,,1)=16),(INDEX(Build_Schedule,,2)*1000*Inputs!C13)*(Inputs!C46*(1-Inputs!C81)^MAX(0,16-Inputs!C82))*(1-INDEX(Build_Schedule,,3))) -> 0 | D21: =SUMPRODUCT(--(INDEX(Build_Schedule,,1)<16),INDEX(Build_Schedule,,2)*1000*Inputs!C47) -> 0 | E21: =SUMPRODUCT(--(INDEX(Build_Schedule,,1)<16),INDEX(Build_Schedule,,2)*1000*Inputs!C13*Inputs!C44*365*Inputs!C40*(1-Inputs!C41)^(16-INDEX(Build_Schedule,,1))*Inputs!C51) -> 0 | F21: =SUMPRODUCT(--(INDEX(Build_Schedule,,1)+Inputs!C43=16),INDEX(Build_Schedule,,2)*1000*Inputs!C13*Inputs!C49*(1-Inputs!C81)^MAX(0,Inputs!C43)) -> 0 | G21: =SUMPRODUCT(--(INDEX(Build_Schedule,,1)=16),INDEX(Build_Schedule,,2)*1000*(Inputs!C57+Inputs!C58+Inputs!C59)) -> 0 | H21: =SUM(C21:G21) -> 0 | I21: =H21/(1+Inputs!C16)^16 -> 0 | J21: =SUMPRODUCT(--(INDEX(Build_Schedule,,1)<16),INDEX(Build_Schedule,,2)*1000*(1-Inputs!C41)^(16-INDEX(Build_Schedule,,1)))*Inputs!C72*(1+Inputs!D72)^15/IFERROR(Inputs!C12*1000,1)+SUMPRODUCT(--(INDEX(Build_Schedule,,1)<16),INDEX(Build_Schedule,,2)*1000*(1-Inputs!C41)^(16-INDEX(Build_Schedule,,1)))*Inputs!C73*(1+Inputs!D73)^15/IFERROR(Inputs!C12*1000,1)+SUMPRODUCT(--(INDEX(Build_Schedule,,1)<16),INDEX(Build_Schedule,,2)*1000*(1-Inputs!C41)^(16-INDEX(Build_Schedule,,1)))*Inputs!C74*(1+Inputs!D74)^15/IFERROR(Inputs!C12*1000,1)+SUMPRODUCT(--(INDEX(Build_Schedule,,1)<16),INDEX(Build_Schedule,,2)*1000*(1-Inputs!C41)^(16-INDEX(Build_Schedule,,1)))*Inputs!C75*(1+Inputs!D75)^15/IFERROR(Inputs!C12*1000,1)+SUMPRODUCT(--(INDEX(Build_Schedule,,1)<16),INDEX(Build_Schedule,,2)*1000*(1-Inputs!C41)^(16-INDEX(Build_Schedule,,1)))*Inputs!C76*(1+Inputs!D76)^15/IFERROR(Inputs!C12*1000,1)+SUMPRODUCT(--(INDEX(Build_Schedule,,1)<16),INDEX(Build_Schedule,,2)*1000*(1-Inputs!C41)^(16-INDEX(Build_Schedule,,1)))*Inputs!C77*(1+Inputs!D77)^15/IFERROR(Inputs!C12*1000,1)+SUMPRODUCT(--(INDEX(Build_Schedule,,1)<16),INDEX(Build_Schedule,,2)*1000*(1-Inputs!C41)^(16-INDEX(Build_Schedule,,1)))*Inputs!C78*(1+Inputs!D78)^15/IFERROR(Inputs!C12*1000,1)+SUMPRODUCT(--(INDEX(Build_Schedule,,1)<16),INDEX(Build_Schedule,,2)*1000*(1-Inputs!C41)^(16-INDEX(Build_Schedule,,1)))*Inputs!C79*(1+Inputs!D79)^15/IFERROR(Inputs!C12*1000,1) -> 0 | K21: =J21/(1+Inputs!C16)^16 -> 0 | L21: =J21-H21 -> 0 | M21: =L21/(1+Inputs!C16)^16 -> 0 | N21: =N20+L21 -> 0 | O21: =SUMPRODUCT(--(INDEX(Build_Schedule,,1)<16),INDEX(Build_Schedule,,2)*Inputs!C13*Inputs!C44*365*Inputs!C40*(1-Inputs!C41)^(16-INDEX(Build_Schedule,,1))) -> 0
B22: 17 | C22: =SUMPRODUCT(--(INDEX(Build_Schedule,,1)=17),(INDEX(Build_Schedule,,2)*1000*Inputs!C13)*(Inputs!C46*(1-Inputs!C81)^MAX(0,17-Inputs!C82))*(1-INDEX(Build_Schedule,,3))) -> 0 | D22: =SUMPRODUCT(--(INDEX(Build_Schedule,,1)<17),INDEX(Build_Schedule,,2)*1000*Inputs!C47) -> 0 | E22: =SUMPRODUCT(--(INDEX(Build_Schedule,,1)<17),INDEX(Build_Schedule,,2)*1000*Inputs!C13*Inputs!C44*365*Inputs!C40*(1-Inputs!C41)^(17-INDEX(Build_Schedule,,1))*Inputs!C51) -> 0 | F22: =SUMPRODUCT(--(INDEX(Build_Schedule,,1)+Inputs!C43=17),INDEX(Build_Schedule,,2)*1000*Inputs!C13*Inputs!C49*(1-Inputs!C81)^MAX(0,Inputs!C43)) -> 0 | G22: =SUMPRODUCT(--(INDEX(Build_Schedule,,1)=17),INDEX(Build_Schedule,,2)*1000*(Inputs!C57+Inputs!C58+Inputs!C59)) -> 0 | H22: =SUM(C22:G22) -> 0 | I22: =H22/(1+Inputs!C16)^17 -> 0 | J22: =SUMPRODUCT(--(INDEX(Build_Schedule,,1)<17),INDEX(Build_Schedule,,2)*1000*(1-Inputs!C41)^(17-INDEX(Build_Schedule,,1)))*Inputs!C72*(1+Inputs!D72)^16/IFERROR(Inputs!C12*1000,1)+SUMPRODUCT(--(INDEX(Build_Schedule,,1)<17),INDEX(Build_Schedule,,2)*1000*(1-Inputs!C41)^(17-INDEX(Build_Schedule,,1)))*Inputs!C73*(1+Inputs!D73)^16/IFERROR(Inputs!C12*1000,1)+SUMPRODUCT(--(INDEX(Build_Schedule,,1)<17),INDEX(Build_Schedule,,2)*1000*(1-Inputs!C41)^(17-INDEX(Build_Schedule,,1)))*Inputs!C74*(1+Inputs!D74)^16/IFERROR(Inputs!C12*1000,1)+SUMPRODUCT(--(INDEX(Build_Schedule,,1)<17),INDEX(Build_Schedule,,2)*1000*(1-Inputs!C41)^(17-INDEX(Build_Schedule,,1)))*Inputs!C75*(1+Inputs!D75)^16/IFERROR(Inputs!C12*1000,1)+SUMPRODUCT(--(INDEX(Build_Schedule,,1)<17),INDEX(Build_Schedule,,2)*1000*(1-Inputs!C41)^(17-INDEX(Build_Schedule,,1)))*Inputs!C76*(1+Inputs!D76)^16/IFERROR(Inputs!C12*1000,1)+SUMPRODUCT(--(INDEX(Build_Schedule,,1)<17),INDEX(Build_Schedule,,2)*1000*(1-Inputs!C41)^(17-INDEX(Build_Schedule,,1)))*Inputs!C77*(1+Inputs!D77)^16/IFERROR(Inputs!C12*1000,1)+SUMPRODUCT(--(INDEX(Build_Schedule,,1)<17),INDEX(Build_Schedule,,2)*1000*(1-Inputs!C41)^(17-INDEX(Build_Schedule,,1)))*Inputs!C78*(1+Inputs!D78)^16/IFERROR(Inputs!C12*1000,1)+SUMPRODUCT(--(INDEX(Build_Schedule,,1)<17),INDEX(Build_Schedule,,2)*1000*(1-Inputs!C41)^(17-INDEX(Build_Schedule,,1)))*Inputs!C79*(1+Inputs!D79)^16/IFERROR(Inputs!C12*1000,1) -> 0 | K22: =J22/(1+Inputs!C16)^17 -> 0 | L22: =J22-H22 -> 0 | M22: =L22/(1+Inputs!C16)^17 -> 0 | N22: =N21+L22 -> 0 | O22: =SUMPRODUCT(--(INDEX(Build_Schedule,,1)<17),INDEX(Build_Schedule,,2)*Inputs!C13*Inputs!C44*365*Inputs!C40*(1-Inputs!C41)^(17-INDEX(Build_Schedule,,1))) -> 0
B23: 18 | C23: =SUMPRODUCT(--(INDEX(Build_Schedule,,1)=18),(INDEX(Build_Schedule,,2)*1000*Inputs!C13)*(Inputs!C46*(1-Inputs!C81)^MAX(0,18-Inputs!C82))*(1-INDEX(Build_Schedule,,3))) -> 0 | D23: =SUMPRODUCT(--(INDEX(Build_Schedule,,1)<18),INDEX(Build_Schedule,,2)*1000*Inputs!C47) -> 0 | E23: =SUMPRODUCT(--(INDEX(Build_Schedule,,1)<18),INDEX(Build_Schedule,,2)*1000*Inputs!C13*Inputs!C44*365*Inputs!C40*(1-Inputs!C41)^(18-INDEX(Build_Schedule,,1))*Inputs!C51) -> 0 | F23: =SUMPRODUCT(--(INDEX(Build_Schedule,,1)+Inputs!C43=18),INDEX(Build_Schedule,,2)*1000*Inputs!C13*Inputs!C49*(1-Inputs!C81)^MAX(0,Inputs!C43)) -> 0 | G23: =SUMPRODUCT(--(INDEX(Build_Schedule,,1)=18),INDEX(Build_Schedule,,2)*1000*(Inputs!C57+Inputs!C58+Inputs!C59)) -> 0 | H23: =SUM(C23:G23) -> 0 | I23: =H23/(1+Inputs!C16)^18 -> 0 | J23: =SUMPRODUCT(--(INDEX(Build_Schedule,,1)<18),INDEX(Build_Schedule,,2)*1000*(1-Inputs!C41)^(18-INDEX(Build_Schedule,,1)))*Inputs!C72*(1+Inputs!D72)^17/IFERROR(Inputs!C12*1000,1)+SUMPRODUCT(--(INDEX(Build_Schedule,,1)<18),INDEX(Build_Schedule,,2)*1000*(1-Inputs!C41)^(18-INDEX(Build_Schedule,,1)))*Inputs!C73*(1+Inputs!D73)^17/IFERROR(Inputs!C12*1000,1)+SUMPRODUCT(--(INDEX(Build_Schedule,,1)<18),INDEX(Build_Schedule,,2)*1000*(1-Inputs!C41)^(18-INDEX(Build_Schedule,,1)))*Inputs!C74*(1+Inputs!D74)^17/IFERROR(Inputs!C12*1000,1)+SUMPRODUCT(--(INDEX(Build_Schedule,,1)<18),INDEX(Build_Schedule,,2)*1000*(1-Inputs!C41)^(18-INDEX(Build_Schedule,,1)))*Inputs!C75*(1+Inputs!D75)^17/IFERROR(Inputs!C12*1000,1)+SUMPRODUCT(--(INDEX(Build_Schedule,,1)<18),INDEX(Build_Schedule,,2)*1000*(1-Inputs!C41)^(18-INDEX(Build_Schedule,,1)))*Inputs!C76*(1+Inputs!D76)^17/IFERROR(Inputs!C12*1000,1)+SUMPRODUCT(--(INDEX(Build_Schedule,,1)<18),INDEX(Build_Schedule,,2)*1000*(1-Inputs!C41)^(18-INDEX(Build_Schedule,,1)))*Inputs!C77*(1+Inputs!D77)^17/IFERROR(Inputs!C12*1000,1)+SUMPRODUCT(--(INDEX(Build_Schedule,,1)<18),INDEX(Build_Schedule,,2)*1000*(1-Inputs!C41)^(18-INDEX(Build_Schedule,,1)))*Inputs!C78*(1+Inputs!D78)^17/IFERROR(Inputs!C12*1000,1)+SUMPRODUCT(--(INDEX(Build_Schedule,,1)<18),INDEX(Build_Schedule,,2)*1000*(1-Inputs!C41)^(18-INDEX(Build_Schedule,,1)))*Inputs!C79*(1+Inputs!D79)^17/IFERROR(Inputs!C12*1000,1) -> 0 | K23: =J23/(1+Inputs!C16)^18 -> 0 | L23: =J23-H23 -> 0 | M23: =L23/(1+Inputs!C16)^18 -> 0 | N23: =N22+L23 -> 0 | O23: =SUMPRODUCT(--(INDEX(Build_Schedule,,1)<18),INDEX(Build_Schedule,,2)*Inputs!C13*Inputs!C44*365*Inputs!C40*(1-Inputs!C41)^(18-INDEX(Build_Schedule,,1))) -> 0
B24: 19 | C24: =SUMPRODUCT(--(INDEX(Build_Schedule,,1)=19),(INDEX(Build_Schedule,,2)*1000*Inputs!C13)*(Inputs!C46*(1-Inputs!C81)^MAX(0,19-Inputs!C82))*(1-INDEX(Build_Schedule,,3))) -> 0 | D24: =SUMPRODUCT(--(INDEX(Build_Schedule,,1)<19),INDEX(Build_Schedule,,2)*1000*Inputs!C47) -> 0 | E24: =SUMPRODUCT(--(INDEX(Build_Schedule,,1)<19),INDEX(Build_Schedule,,2)*1000*Inputs!C13*Inputs!C44*365*Inputs!C40*(1-Inputs!C41)^(19-INDEX(Build_Schedule,,1))*Inputs!C51) -> 0 | F24: =SUMPRODUCT(--(INDEX(Build_Schedule,,1)+Inputs!C43=19),INDEX(Build_Schedule,,2)*1000*Inputs!C13*Inputs!C49*(1-Inputs!C81)^MAX(0,Inputs!C43)) -> 0 | G24: =SUMPRODUCT(--(INDEX(Build_Schedule,,1)=19),INDEX(Build_Schedule,,2)*1000*(Inputs!C57+Inputs!C58+Inputs!C59)) -> 0 | H24: =SUM(C24:G24) -> 0 | I24: =H24/(1+Inputs!C16)^19 -> 0 | J24: =SUMPRODUCT(--(INDEX(Build_Schedule,,1)<19),INDEX(Build_Schedule,,2)*1000*(1-Inputs!C41)^(19-INDEX(Build_Schedule,,1)))*Inputs!C72*(1+Inputs!D72)^18/IFERROR(Inputs!C12*1000,1)+SUMPRODUCT(--(INDEX(Build_Schedule,,1)<19),INDEX(Build_Schedule,,2)*1000*(1-Inputs!C41)^(19-INDEX(Build_Schedule,,1)))*Inputs!C73*(1+Inputs!D73)^18/IFERROR(Inputs!C12*1000,1)+SUMPRODUCT(--(INDEX(Build_Schedule,,1)<19),INDEX(Build_Schedule,,2)*1000*(1-Inputs!C41)^(19-INDEX(Build_Schedule,,1)))*Inputs!C74*(1+Inputs!D74)^18/IFERROR(Inputs!C12*1000,1)+SUMPRODUCT(--(INDEX(Build_Schedule,,1)<19),INDEX(Build_Schedule,,2)*1000*(1-Inputs!C41)^(19-INDEX(Build_Schedule,,1)))*Inputs!C75*(1+Inputs!D75)^18/IFERROR(Inputs!C12*1000,1)+SUMPRODUCT(--(INDEX(Build_Schedule,,1)<19),INDEX(Build_Schedule,,2)*1000*(1-Inputs!C41)^(19-INDEX(Build_Schedule,,1)))*Inputs!C76*(1+Inputs!D76)^18/IFERROR(Inputs!C12*1000,1)+SUMPRODUCT(--(INDEX(Build_Schedule,,1)<19),INDEX(Build_Schedule,,2)*1000*(1-Inputs!C41)^(19-INDEX(Build_Schedule,,1)))*Inputs!C77*(1+Inputs!D77)^18/IFERROR(Inputs!C12*1000,1)+SUMPRODUCT(--(INDEX(Build_Schedule,,1)<19),INDEX(Build_Schedule,,2)*1000*(1-Inputs!C41)^(19-INDEX(Build_Schedule,,1)))*Inputs!C78*(1+Inputs!D78)^18/IFERROR(Inputs!C12*1000,1)+SUMPRODUCT(--(INDEX(Build_Schedule,,1)<19),INDEX(Build_Schedule,,2)*1000*(1-Inputs!C41)^(19-INDEX(Build_Schedule,,1)))*Inputs!C79*(1+Inputs!D79)^18/IFERROR(Inputs!C12*1000,1) -> 0 | K24: =J24/(1+Inputs!C16)^19 -> 0 | L24: =J24-H24 -> 0 | M24: =L24/(1+Inputs!C16)^19 -> 0 | N24: =N23+L24 -> 0 | O24: =SUMPRODUCT(--(INDEX(Build_Schedule,,1)<19),INDEX(Build_Schedule,,2)*Inputs!C13*Inputs!C44*365*Inputs!C40*(1-Inputs!C41)^(19-INDEX(Build_Schedule,,1))) -> 0
B25: 20 | C25: =SUMPRODUCT(--(INDEX(Build_Schedule,,1)=20),(INDEX(Build_Schedule,,2)*1000*Inputs!C13)*(Inputs!C46*(1-Inputs!C81)^MAX(0,20-Inputs!C82))*(1-INDEX(Build_Schedule,,3))) -> 0 | D25: =SUMPRODUCT(--(INDEX(Build_Schedule,,1)<20),INDEX(Build_Schedule,,2)*1000*Inputs!C47) -> 0 | E25: =SUMPRODUCT(--(INDEX(Build_Schedule,,1)<20),INDEX(Build_Schedule,,2)*1000*Inputs!C13*Inputs!C44*365*Inputs!C40*(1-Inputs!C41)^(20-INDEX(Build_Schedule,,1))*Inputs!C51) -> 0 | F25: =SUMPRODUCT(--(INDEX(Build_Schedule,,1)+Inputs!C43=20),INDEX(Build_Schedule,,2)*1000*Inputs!C13*Inputs!C49*(1-Inputs!C81)^MAX(0,Inputs!C43)) -> 0 | G25: =SUMPRODUCT(--(INDEX(Build_Schedule,,1)=20),INDEX(Build_Schedule,,2)*1000*(Inputs!C57+Inputs!C58+Inputs!C59)) -> 0 | H25: =SUM(C25:G25) -> 0 | I25: =H25/(1+Inputs!C16)^20 -> 0 | J25: =SUMPRODUCT(--(INDEX(Build_Schedule,,1)<20),INDEX(Build_Schedule,,2)*1000*(1-Inputs!C41)^(20-INDEX(Build_Schedule,,1)))*Inputs!C72*(1+Inputs!D72)^19/IFERROR(Inputs!C12*1000,1)+SUMPRODUCT(--(INDEX(Build_Schedule,,1)<20),INDEX(Build_Schedule,,2)*1000*(1-Inputs!C41)^(20-INDEX(Build_Schedule,,1)))*Inputs!C73*(1+Inputs!D73)^19/IFERROR(Inputs!C12*1000,1)+SUMPRODUCT(--(INDEX(Build_Schedule,,1)<20),INDEX(Build_Schedule,,2)*1000*(1-Inputs!C41)^(20-INDEX(Build_Schedule,,1)))*Inputs!C74*(1+Inputs!D74)^19/IFERROR(Inputs!C12*1000,1)+SUMPRODUCT(--(INDEX(Build_Schedule,,1)<20),INDEX(Build_Schedule,,2)*1000*(1-Inputs!C41)^(20-INDEX(Build_Schedule,,1)))*Inputs!C75*(1+Inputs!D75)^19/IFERROR(Inputs!C12*1000,1)+SUMPRODUCT(--(INDEX(Build_Schedule,,1)<20),INDEX(Build_Schedule,,2)*1000*(1-Inputs!C41)^(20-INDEX(Build_Schedule,,1)))*Inputs!C76*(1+Inputs!D76)^19/IFERROR(Inputs!C12*1000,1)+SUMPRODUCT(--(INDEX(Build_Schedule,,1)<20),INDEX(Build_Schedule,,2)*1000*(1-Inputs!C41)^(20-INDEX(Build_Schedule,,1)))*Inputs!C77*(1+Inputs!D77)^19/IFERROR(Inputs!C12*1000,1)+SUMPRODUCT(--(INDEX(Build_Schedule,,1)<20),INDEX(Build_Schedule,,2)*1000*(1-Inputs!C41)^(20-INDEX(Build_Schedule,,1)))*Inputs!C78*(1+Inputs!D78)^19/IFERROR(Inputs!C12*1000,1)+SUMPRODUCT(--(INDEX(Build_Schedule,,1)<20),INDEX(Build_Schedule,,2)*1000*(1-Inputs!C41)^(20-INDEX(Build_Schedule,,1)))*Inputs!C79*(1+Inputs!D79)^19/IFERROR(Inputs!C12*1000,1) -> 0 | K25: =J25/(1+Inputs!C16)^20 -> 0 | L25: =J25-H25 -> 0 | M25: =L25/(1+Inputs!C16)^20 -> 0 | N25: =N24+L25 -> 0 | O25: =SUMPRODUCT(--(INDEX(Build_Schedule,,1)<20),INDEX(Build_Schedule,,2)*Inputs!C13*Inputs!C44*365*Inputs!C40*(1-Inputs!C41)^(20-INDEX(Build_Schedule,,1))) -> 0
B26: TOTALS / PV SUM | I26: =SUM(I5:I25) -> 0 | K26: =SUM(K5:K25) -> 0 | M26: =SUM(M5:M25) -> 0 | O26: =SUM(O5:O25) -> 0

Sheet Results
B2: BESS Economic Analysis — Results Dashboard
B3: Project: [auto from Inputs!C9] | Analysis Date: February 20, 2026
B5: KEY FINANCIAL METRICS
B6: Metric | C6: Value | D6: Benchmark | E6: Interpretation
B7: Net Present Value (NPV) | C7: =SUM(Cash_Flows!M5:Cash_Flows!M25)+Inputs!C36 -> 0 | D7: > $0 | E7: Positive NPV creates shareholder/ratepayer value
B8: T&D Deferral PV | C8: =Inputs!C36 -> 0 | D8: — | E8: Present value of deferred T&D capital investment
B9: Total Project Value | C9: =SUM(Cash_Flows!M5:Cash_Flows!M25)+Inputs!C36 -> 0 | D9: > $0 | E9: NPV inclusive of T&D deferral benefit
B10: Benefit-Cost Ratio (BCR) | C10: =IFERROR(SUM(Cash_Flows!K5:Cash_Flows!K25)/SUM(Cash_Flows!I5:Cash_Flows!I25),0) -> 0 | D10: ≥ 1.0 approve | E10: ≥1.5 strong | 1.0–1.5 marginal | <1.0 reject (CPUC SPM)
B11: Internal Rate of Return (IRR) | C11: =IFERROR(IRR(Cash_Flows!L5:Cash_Flows!L25),"N/A") -> 0 | D11: > WACC | E11: IRR > WACC creates value above cost of capital
B12: Simple Payback (years) | C12: =IFERROR(MATCH(TRUE,Cash_Flows!N5:Cash_Flows!N25>0,0)-1,"Never") -> 0 | D12: < 10 yrs | E12: < 7 yrs strong; 7–10 acceptable; > 10 yrs challenging
B13: LCOS ($/MWh) | C13: =IFERROR(SUM(Cash_Flows!I5:Cash_Flows!I25)/SUM(Cash_Flows!O5:Cash_Flows!O25),0) -> 0 | D13: $100–200/MWh | E13: Levelized cost per MWh discharged (Lazard methodology)
B14: Breakeven CapEx ($/kWh) | C14: =IFERROR((SUM(Cash_Flows!K5:Cash_Flows!K25)-(SUM(Cash_Flows!I5:Cash_Flows!I25)-Cash_Flows!I5))/(Inputs!C12*Inputs!C13*1000),0) -> 0 | D14: > CapEx input | E14: Max CapEx where BCR = 1.0 (margin of safety)
B16: PROJECT SUMMARY
B17: Project Name | C17: =Inputs!C9 -> 0
B18: Capacity (MW) | C18: =Inputs!C12 -> 0
B19: Duration (hrs) | C19: =Inputs!C13 -> 0
B20: Analysis Period | C20: =Inputs!C15&" years" -> 0
B21: Discount Rate | C21: =Inputs!C16 -> 0
B22: WACC (Financing) | C22: =Inputs!C68 -> 0
B23: Ownership Type | C23: =Inputs!C17 -> 0
B24: CapEx ($/kWh) | C24: =Inputs!C46 -> 0
B25: ITC Rate | C25: =Inputs!C54+Inputs!C55 -> 0

Sheet Sensitivity
B2: SENSITIVITY ANALYSIS — Tornado Chart Parameters
B3: Each row shows the base case and ±20% deviation for one input parameter. Recalculate NPV in Python GUI for exact values; Excel shows analytical estimates.
B5: PARAMETER SENSITIVITY TABLE
B6: Parameter | C6: Low Case | D6: Base Case | E6: High Case | F6: Low NPV (est.) | G6: Base NPV | H6: High NPV (est.)
B7: CapEx ($/kWh) | C7: Inputs!C46 × 0.80 (−20% CapEx) | D7: =Inputs!C46 -> 0 | E7: Inputs!C46 × 1.20 (+20% CapEx) | F7: ← run Python GUI for exact | G7: =SUM(Cash_Flows!M5:Cash_Flows!M25)+Inputs!C36 -> 0 | H7: ← run Python GUI for exact
B8: Discount Rate | C8: Inputs!C16 × 0.80 (−20% rate) | D8: =Inputs!C16 -> 0 | E8: Inputs!C16 × 1.20 (+20% rate) | F8: ← run Python GUI for exact | G8: =SUM(Cash_Flows!M5:Cash_Flows!M25)+Inputs!C36 -> 0 | H8: ← run Python GUI for exact
B9: Resource Adequacy ($/kW-yr) | C9: Inputs!C72 × 0.75 (−25% RA) | D9: =Inputs!C72 -> 0 | E9: Inputs!C72 × 1.25 (+25% RA) | F9: ← run Python GUI for exact | G9: =SUM(Cash_Flows!M5:Cash_Flows!M25)+Inputs!C36 -> 0 | H9: ← run Python GUI for exact
B10: Learning Rate | C10: Inputs!C81 × 0.42 (5% rate) | D10: =Inputs!C81 -> 0 | E10: Inputs!C81 × 1.25 (15% rate) | F10: ← run Python GUI for exact | G10: =SUM(Cash_Flows!M5:Cash_Flows!M25)+Inputs!C36 -> 0 | H10: ← run Python GUI for exact
B11: Round-Trip Efficiency | C11: Inputs!C40 × 0.90 (−10% RTE) | D11: =Inputs!C40 -> 0 | E11: Inputs!C40 × 1.05 (+5% RTE) | F11: ← run Python GUI for exact | G11: =SUM(Cash_Flows!M5:Cash_Flows!M25)+Inputs!C36 -> 0 | H11: ← run Python GUI for exact
B12: Analysis Period (yrs) | C12: Inputs!C15 × 0.80 (−20% years) | D12: =Inputs!C15 -> 0 | E12: Inputs!C15 × 1.20 (+20% years) | F12: ← run Python GUI for exact | G12: =SUM(Cash_Flows!M5:Cash_Flows!M25)+Inputs!C36 -> 0 | H12: ← run Python GUI for exact
B13: ITC Rate | C13: Inputs!C54 × 0.67 (No adders) | D13: =Inputs!C54 -> 0 | E13: Inputs!C54 × 1.00 (+10% adder) | F13: ← run Python GUI for exact | G13: =SUM(Cash_Flows!M5:Cash_Flows!M25)+Inputs!C36 -> 0 | H13: ← run Python GUI for exact
B14: Fixed O&M ($/kW-yr) | C14: Inputs!C47 × 0.80 (−20% O&M) | D14: =Inputs!C47 -> 0 | E14: Inputs!C47 × 1.20 (+20% O&M) | F14: ← run Python GUI for exact | G14: =SUM(Cash_Flows!M5:Cash_Flows!M25)+Inputs!C36 -> 0 | H14: ← run Python GUI for exact
B16: HOW TO READ A TORNADO CHART
B17: • Parameters are sorted by impact (longest bar = highest sensitivity)
B18: • Bars extending left (negative) show parameters where increase hurts NPV
B19: • CapEx and Discount Rate typically dominate BESS sensitivity
B20: • RA value is the largest single benefit driver in capacity-constrained markets
