Workbook
Name Analysis_Years: Inputs!$C15
Name Capacity_MW: Inputs!$C12
Name Discount_Rate: Inputs!$C16
Name Duration_Hours: Inputs!$C13
Name Energy_MWh: Inputs!$C14
Name Learning_Rate: Inputs!$C61

Sheet Inputs
B2: BESS Economic Analysis - Project Inputs
B3: LIBRARY SELECTION
B6: Selected Library: | C6: Custom
B8: PROJECT BASICS
B9: Project Name | E9: Enter project name
B10: Project ID | E10: Unique identifier
B11: Location | E11: Site or market location
B12: Capacity (MW) | C12: 100 | E12: Nameplate power capacity
B13: Duration (hours) | C13: 4 | E13: Storage duration
B14: Energy Capacity (MWh) | C14: =C12*C13 -> 0 | E14: Auto-calculated: MW x hours
B15: Analysis Period (years) | C15: 20 | E15: Economic analysis horizon
B16: Discount Rate (%) | C16: 0.07 | E16: Nominal discount rate for NPV
B17: Ownership Type | C17: Utility | E17: Utility (6-7% WACC) or Merchant (8-10%)
B18: TECHNOLOGY SPECIFICATIONS
B19: Chemistry | C19: LFP | E19: LFP, NMC, or Other
B20: Round-Trip Efficiency (%) | C20: 0.85 | E20: AC-AC efficiency
B21: Annual Degradation (%) | C21: 0.025 | E21: Capacity loss per year
B22: Cycle Life | C22: 6000 | E22: Full-depth cycles before EOL
B23: Augmentation Year | C23: 12 | E23: Year of battery replacement
B24: Cycles per Day | C24: 1 | E24: Average daily charge/discharge cycles
B25: COST INPUTS (BESS)
B26: CapEx ($/kWh) | C26: 160 | D26: $/kWh | E26: Installed capital cost per kWh
B27: Fixed O&M ($/kW-year) | C27: 25 | D27: $/kW-yr | E27: Annual fixed O&M
B28: Variable O&M ($/MWh) | C28: 0 | D28: $/MWh | E28: Per-MWh discharge cost
B29: Augmentation Cost ($/kWh) | C29: 55 | D29: $/kWh | E29: Battery replacement cost
B30: Decommissioning ($/kW) | C30: 10 | D30: $/kW | E30: End-of-life cost
B31: Charging Cost ($/MWh) | C31: 30 | D31: $/MWh | E31: Grid electricity cost for charging
B32: Residual Value (%) | C32: 0.1 | D32: % | E32: End-of-life asset value as % of CapEx
B33: TAX CREDITS (BESS-Specific under IRA)
B34: ITC Base Rate (%) | C34: 0.3 | E34: 30% Investment Tax Credit under IRA
B35: ITC Adders (%) | C35: 0 | E35: Energy community +10%, Domestic content +10%
B36: INFRASTRUCTURE COSTS (Common to all projects)
B37: Interconnection ($/kW) | C37: 100 | D37: $/kW | E37: Network upgrades, studies
B38: Land ($/kW) | C38: 10 | D38: $/kW | E38: Site acquisition/lease
B39: Permitting ($/kW) | C39: 15 | D39: $/kW | E39: Permits, environmental review
B40: Insurance (% of CapEx) | C40: 0.005 | D40: % | E40: Annual insurance cost
B41: Property Tax (%) | C41: 0.01 | D41: % | E41: Annual property tax rate
B42: FINANCING STRUCTURE (For WACC Calculation)
B43: Debt Percentage (%) | C43: 0.6 | E43: Debt/equity split (0.60 = 60% debt)
B44: Interest Rate (%) | C44: 0.05 | E44: Annual interest rate on debt
...

Sheet Results
B2: BESS Economic Analysis Results
B4: PROJECT SUMMARY
B5: Project | C5: =Inputs!C9 -> 0
B6: Location | C6: =Inputs!C11 -> 0
B7: Capacity | C7: =Inputs!C12&" MW / "&Inputs!C14&" MWh" -> 0
B8: Total Investment | C8: =Calculations!C9 -> 0
B10: KEY FINANCIAL METRICS
B11: Benefit-Cost Ratio (BCR) | C11: =Cash_Flows!X27/Cash_Flows!W27 -> 0 | E11: BCR >= 1.0 indicates benefits exceed costs
B12: Net Present Value (NPV) | C12: =Cash_Flows!X27-Cash_Flows!W27 -> 0 | E12: Positive NPV indicates value creation
B13: Internal Rate of Return (IRR) | C13: =IRR(Cash_Flows!U5:U25) -> 0 | E13: Rate where NPV = 0
B14: Simple Payback (years) | C14: =MATCH(TRUE,INDEX(Cash_Flows!Y5:Y25>0,0),0)-1 -> 0 | E14: Year when cumulative CF turns positive
B15: PV of Total Costs | C15: =Cash_Flows!W27 -> 0 | E15: Present value of all costs
B16: PV of Total Benefits | C16: =Cash_Flows!X27 -> 0 | E16: Present value of all benefits
B18: RECOMMENDATION
B19: =IF(C11>=1.5,"APPROVE - Strong economic case",IF(C11>=1,"FURTHER STUDY - Marginal economics","REJECT - Costs exceed benefits")) -> 0
B21: LEVELIZED COST OF STORAGE (LCOS)
B22: LCOS ($/MWh) | C22: =Cash_Flows!W27/(Calculations!C13*NPV(Inputs!C16,Cash_Flows!V5:V25)) -> 0 | E22: Levelized cost per MWh discharged
B24: BREAKEVEN ANALYSIS
B25: Breakeven CapEx ($/kWh) | C25: =(Cash_Flows!X27-(Cash_Flows!W27-Calculations!C11))/(Inputs!C14*1000) -> 0 | E25: Maximum CapEx for BCR = 1.0

Sheet Cash_Flows
B2: Annual Cash Flow Projections
B4: Year | C4: CapEx | D4: Fixed O&M | E4: Var O&M | F4: Charging | G4: Insurance | H4: Prop Tax | I4: Augment | J4: Decommission | K4: Total Costs | L4: RA | M4: Arbitrage | N4: Ancillary | O4: T&D | P4: Resilience | Q4: Renew Int | R4: GHG | S4: Voltage | T4: Total Benefits | U4: Net CF | V4: Disc Factor | W4: PV Costs | X4: PV Benefits | Y4: Cumul CF
B5: 0 | C5: =Calculations!C11 -> 0 | D5: =0 -> 0 | E5: =0 -> 0 | F5: =0 -> 0 | G5: =0 -> 0 | H5: =0 -> 0 | I5: =0 -> 0 | J5: =0 -> 0 | K5: =SUM(C5:J5) -> 0 | L5: =0 -> 0 | M5: =0 -> 0 | N5: =0 -> 0 | O5: =0 -> 0 | P5: =0 -> 0 | Q5: =0 -> 0 | R5: =0 -> 0 | S5: =0 -> 0 | T5: =SUM(L5:S5) -> 0 | U5: =T5-K5 -> 0 | V5: =1/(1+Inputs!$C16)^B5 -> 0 | W5: =K5*V5 -> 0 | X5: =T5*V5 -> 0 | Y5: =U5 -> 0
B6: 1 | C6: =0 -> 0 | D6: =Calculations!C12 -> 0 | E6: =Inputs!$C28*Calculations!$C$13 -> 0 | F6: =Calculations!C14 -> 0 | G6: =Calculations!C9*Inputs!$C40 -> 0 | H6: =Calculations!$C$9*(1-1/Inputs!$C15)*Inputs!$C41 -> 0 | I6: =IF(B6=Inputs!$C23,Inputs!$C29*Calculations!C6*(1-Inputs!$C61)^B6,0) -> 0 | J6: =IF(B6=Inputs!$C15,Inputs!$C30*Calculations!C5-Calculations!C15,0) -> 0 | K6: =SUM(C6:J6) -> 0 | L6: =Inputs!$C$52*Inputs!$C12*1000*(1+Inputs!$D$52)^0*(1-Inputs!$C21)^0 -> 0 | M6: =Inputs!$C$53*Inputs!$C12*1000*(1+Inputs!$D$53)^0*(1-Inputs!$C21)^0 -> 0 | N6: =Inputs!$C$54*Inputs!$C12*1000*(1+Inputs!$D$54)^0*(1-Inputs!$C21)^0 -> 0 | O6: =Inputs!$C$55*Inputs!$C12*1000*(1+Inputs!$D$55)^0*(1-Inputs!$C21)^0 -> 0 | P6: =Inputs!$C$56*Inputs!$C12*1000*(1+Inputs!$D$56)^0*(1-Inputs!$C21)^0 -> 0 | Q6: =Inputs!$C$57*Inputs!$C12*1000*(1+Inputs!$D$57)^0*(1-Inputs!$C21)^0 -> 0 | R6: =Inputs!$C$58*Inputs!$C12*1000*(1+Inputs!$D$58)^0*(1-Inputs!$C21)^0 -> 0 | S6: =Inputs!$C$59*Inputs!$C12*1000*(1+Inputs!$D$59)^0*(1-Inputs!$C21)^0 -> 0 | T6: =SUM(L6:S6) -> 0 | U6: =T6-K6 -> 0 | V6: =1/(1+Inputs!$C16)^B6 -> 0 | W6: =K6*V6 -> 0 | X6: =T6*V6 -> 0 | Y6: =Y5+U6 -> 0
B7: 2 | C7: =0 -> 0 | D7: =Calculations!C12 -> 0 | E7: =Inputs!$C28*Calculations!$C$13 -> 0 | F7: =Calculations!C14 -> 0 | G7: =Calculations!C9*Inputs!$C40 -> 0 | H7: =Calculations!$C$9*(1-2/Inputs!$C15)*Inputs!$C41 -> 0 | I7: =IF(B7=Inputs!$C23,Inputs!$C29*Calculations!C6*(1-Inputs!$C61)^B7,0) -> 0 | J7: =IF(B7=Inputs!$C15,Inputs!$C30*Calculations!C5-Calculations!C15,0) -> 0 | K7: =SUM(C7:J7) -> 0 | L7: =Inputs!$C$52*Inputs!$C12*1000*(1+Inputs!$D$52)^1*(1-Inputs!$C21)^1 -> 0 | M7: =Inputs!$C$53*Inputs!$C12*1000*(1+Inputs!$D$53)^1*(1-Inputs!$C21)^1 -> 0 | N7: =Inputs!$C$54*Inputs!$C12*1000*(1+Inputs!$D$54)^1*(1-Inputs!$C21)^1 -> 0 | O7: =Inputs!$C$55*Inputs!$C12*1000*(1+Inputs!$D$55)^1*(1-Inputs!$C21)^1 -> 0 | P7: =Inputs!$C$56*Inputs!$C12*1000*(1+Inputs!$D$56)^1*(1-Inputs!$C21)^1 -> 0 | Q7: =Inputs!$C$57*Inputs!$C12*1000*(1+Inputs!$D$57)^1*(1-Inputs!$C21)^1 -> 0 | R7: =Inputs!$C$58*Inputs!$C12*1000*(1+Inputs!$D$58)^1*(1-Inputs!$C21)^1 -> 0 | S7: =Inputs!$C$59*Inputs!$C12*1000*(1+Inputs!$D$59)^1*(1-Inputs!$C21)^1 -> 0 | T7: =SUM(L7:S7) -> 0 | U7: =T7-K7 -> 0 | V7: =1/(1+Inputs!$C16)^B7 -> 0 | W7: =K7*V7 -> 0 | X7: =T7*V7 -> 0 | Y7: =Y6+U7 -> 0
B8: 3 | C8: =0 -> 0 | D8: =Calculations!C12 -> 0 | E8: =Inputs!$C28*Calculations!$C$13 -> 0 | F8: =Calculations!C14 -> 0 | G8: =Calculations!C9*Inputs!$C40 -> 0 | H8: =Calculations!$C$9*(1-3/Inputs!$C15)*Inputs!$C41 -> 0 | I8: =IF(B8=Inputs!$C23,Inputs!$C29*Calculations!C6*(1-Inputs!$C61)^B8,0) -> 0 | J8: =IF(B8=Inputs!$C15,Inputs!$C30*Calculations!C5-Calculations!C15,0) -> 0 | K8: =SUM(C8:J8) -> 0 | L8: =Inputs!$C$52*Inputs!$C12*1000*(1+Inputs!$D$52)^2*(1-Inputs!$C21)^2 -> 0 | M8: =Inputs!$C$53*Inputs!$C12*1000*(1+Inputs!$D$53)^2*(1-Inputs!$C21)^2 -> 0 | N8: =Inputs!$C$54*Inputs!$C12*1000*(1+Inputs!$D$54)^2*(1-Inputs!$C21)^2 -> 0 | O8: =Inputs!$C$55*Inputs!$C12*1000*(1+Inputs!$D$55)^2*(1-Inputs!$C21)^2 -> 0 | P8: =Inputs!$C$56*Inputs!$C12*1000*(1+Inputs!$D$56)^2*(1-Inputs!$C21)^2 -> 0 | Q8: =Inputs!$C$57*Inputs!$C12*1000*(1+Inputs!$D$57)^2*(1-Inputs!$C21)^2 -> 0 | R8: =Inputs!$C$58*Inputs!$C12*1000*(1+Inputs!$D$58)^2*(1-Inputs!$C21)^2 -> 0 | S8: =Inputs!$C$59*Inputs!$C12*1000*(1+Inputs!$D$59)^2*(1-Inputs!$C21)^2 -> 0 | T8: =SUM(L8:S8) -> 0 | U8: =T8-K8 -> 0 | V8: =1/(1+Inputs!$C16)^B8 -> 0 | W8: =K8*V8 -> 0 | X8: =T8*V8 -> 0 | Y8: =Y7+U8 -> 0
B9: 4 | C9: =0 -> 0 | D9: =Calculations!C12 -> 0 | E9: =Inputs!$C28*Calculations!$C$13 -> 0 | F9: =Calculations!C14 -> 0 | G9: =Calculations!C9*Inputs!$C40 -> 0 | H9: =Calculations!$C$9*(1-4/Inputs!$C15)*Inputs!$C41 -> 0 | I9: =IF(B9=Inputs!$C23,Inputs!$C29*Calculations!C6*(1-Inputs!$C61)^B9,0) -> 0 | J9: =IF(B9=Inputs!$C15,Inputs!$C30*Calculations!C5-Calculations!C15,0) -> 0 | K9: =SUM(C9:J9) -> 0 | L9: =Inputs!$C$52*Inputs!$C12*1000*(1+Inputs!$D$52)^3*(1-Inputs!$C21)^3 -> 0 | M9: =Inputs!$C$53*Inputs!$C12*1000*(1+Inputs!$D$53)^3*(1-Inputs!$C21)^3 -> 0 | N9: =Inputs!$C$54*Inputs!$C12*1000*(1+Inputs!$D$54)^3*(1-Inputs!$C21)^3 -> 0 | O9: =Inputs!$C$55*Inputs!$C12*1000*(1+Inputs!$D$55)^3*(1-Inputs!$C21)^3 -> 0 | P9: =Inputs!$C$56*Inputs!$C12*1000*(1+Inputs!$D$56)^3*(1-Inputs!$C21)^3 -> 0 | Q9: =Inputs!$C$57*Inputs!$C12*1000*(1+Inputs!$D$57)^3*(1-Inputs!$C21)^3 -> 0 | R9: =Inputs!$C$58*Inputs!$C12*1000*(1+Inputs!$D$58)^3*(1-Inputs!$C21)^3 -> 0 | S9: =Inputs!$C$59*Inputs!$C12*1000*(1+Inputs!$D$59)^3*(1-Inputs!$C21)^3 -> 0 | T9: =SUM(L9:S9) -> 0 | U9: =T9-K9 -> 0 | V9: =1/(1+Inputs!$C16)^B9 -> 0 | W9: =K9*V9 -> 0 | X9: =T9*V9 -> 0 | Y9: =Y8+U9 -> 0
B10: 5 | C10: =0 -> 0 | D10: =Calculations!C12 -> 0 | E10: =Inputs!$C28*Calculations!$C$13 -> 0 | F10: =Calculations!C14 -> 0 | G10: =Calculations!C9*Inputs!$C40 -> 0 | H10: =Calculations!$C$9*(1-5/Inputs!$C15)*Inputs!$C41 -> 0 | I10: =IF(B10=Inputs!$C23,Inputs!$C29*Calculations!C6*(1-Inputs!$C61)^B10,0) -> 0 | J10: =IF(B10=Inputs!$C15,Inputs!$C30*Calculations!C5-Calculations!C15,0) -> 0 | K10: =SUM(C10:J10) -> 0 | L10: =Inputs!$C$52*Inputs!$C12*1000*(1+Inputs!$D$52)^4*(1-Inputs!$C21)^4 -> 0 | M10: =Inputs!$C$53*Inputs!$C12*1000*(1+Inputs!$D$53)^4*(1-Inputs!$C21)^4 -> 0 | N10: =Inputs!$C$54*Inputs!$C12*1000*(1+Inputs!$D$54)^4*(1-Inputs!$C21)^4 -> 0 | O10: =Inputs!$C$55*Inputs!$C12*1000*(1+Inputs!$D$55)^4*(1-Inputs!$C21)^4 -> 0 | P10: =Inputs!$C$56*Inputs!$C12*1000*(1+Inputs!$D$56)^4*(1-Inputs!$C21)^4 -> 0 | Q10: =Inputs!$C$57*Inputs!$C12*1000*(1+Inputs!$D$57)^4*(1-Inputs!$C21)^4 -> 0 | R10: =Inputs!$C$58*Inputs!$C12*1000*(1+Inputs!$D$58)^4*(1-Inputs!$C21)^4 -> 0 | S10: =Inputs!$C$59*Inputs!$C12*1000*(1+Inputs!$D$59)^4*(1-Inputs!$C21)^4 -> 0 | T10: =SUM(L10:S10) -> 0 | U10: =T10-K10 -> 0 | V10: =1/(1+Inputs!$C16)^B10 -> 0 | W10: =K10*V10 -> 0 | X10: =T10*V10 -> 0 | Y10: =Y9+U10 -> 0
B11: 6 | C11: =0 -> 0 | D11: =Calculations!C12 -> 0 | E11: =Inputs!$C28*Calculations!$C$13 -> 0 | F11: =Calculations!C14 -> 0 | G11: =Calculations!C9*Inputs!$C40 -> 0 | H11: =Calculations!$C$9*(1-6/Inputs!$C15)*Inputs!$C41 -> 0 | I11: =IF(B11=Inputs!$C23,Inputs!$C29*Calculations!C6*(1-Inputs!$C61)^B11,0) -> 0 | J11: =IF(B11=Inputs!$C15,Inputs!$C30*Calculations!C5-Calculations!C15,0) -> 0 | K11: =SUM(C11:J11) -> 0 | L11: =Inputs!$C$52*Inputs!$C12*1000*(1+Inputs!$D$52)^5*(1-Inputs!$C21)^5 -> 0 | M11: =Inputs!$C$53*Inputs!$C12*1000*(1+Inputs!$D$53)^5*(1-Inputs!$C21)^5 -> 0 | N11: =Inputs!$C$54*Inputs!$C12*1000*(1+Inputs!$D$54)^5*(1-Inputs!$C21)^5 -> 0 | O11: =Inputs!$C$55*Inputs!$C12*1000*(1+Inputs!$D$55)^5*(1-Inputs!$C21)^5 -> 0 | P11: =Inputs!$C$56*Inputs!$C12*1000*(1+Inputs!$D$56)^5*(1-Inputs!$C21)^5 -> 0 | Q11: =Inputs!$C$57*Inputs!$C12*1000*(1+Inputs!$D$57)^5*(1-Inputs!$C21)^5 -> 0 | R11: =Inputs!$C$58*Inputs!$C12*1000*(1+Inputs!$D$58)^5*(1-Inputs!$C21)^5 -> 0 | S11: =Inputs!$C$59*Inputs!$C12*1000*(1+Inputs!$D$59)^5*(1-Inputs!$C21)^5 -> 0 | T11: =SUM(L11:S11) -> 0 | U11: =T11-K11 -> 0 | V11: =1/(1+Inputs!$C16)^B11 -> 0 | W11: =K11*V11 -> 0 | X11: =T11*V11 -> 0 | Y11: =Y10+U11 -> 0
B12: 7 | C12: =0 -> 0 | D12: =Calculations!C12 -> 0 | E12: =Inputs!$C28*Calculations!$C$13 -> 0 | F12: =Calculations!C14 -> 0 | G12: =Calculations!C9*Inputs!$C40 -> 0 | H12: =Calculations!$C$9*(1-7/Inputs!$C15)*Inputs!$C41 -> 0 | I12: =IF(B12=Inputs!$C23,Inputs!$C29*Calculations!C6*(1-Inputs!$C61)^B12,0) -> 0 | J12: =IF(B12=Inputs!$C15,Inputs!$C30*Calculations!C5-Calculations!C15,0) -> 0 | K12: =SUM(C12:J12) -> 0 | L12: =Inputs!$C$52*Inputs!$C12*1000*(1+Inputs!$D$52)^6*(1-Inputs!$C21)^6 -> 0 | M12: =Inputs!$C$53*Inputs!$C12*1000*(1+Inputs!$D$53)^6*(1-Inputs!$C21)^6 -> 0 | N12: =Inputs!$C$54*Inputs!$C12*1000*(1+Inputs!$D$54)^6*(1-Inputs!$C21)^6 -> 0 | O12: =Inputs!$C$55*Inputs!$C12*1000*(1+Inputs!$D$55)^6*(1-Inputs!$C21)^6 -> 0 | P12: =Inputs!$C$56*Inputs!$C12*1000*(1+Inputs!$D$56)^6*(1-Inputs!$C21)^6 -> 0 | Q12: =Inputs!$C$57*Inputs!$C12*1000*(1+Inputs!$D$57)^6*(1-Inputs!$C21)^6 -> 0 | R12: =Inputs!$C$58*Inputs!$C12*1000*(1+Inputs!$D$58)^6*(1-Inputs!$C21)^6 -> 0 | S12: =Inputs!$C$59*Inputs!$C12*1000*(1+Inputs!$D$59)^6*(1-Inputs!$C21)^6 -> 0 | T12: =SUM(L12:S12) -> 0 | U12: =T12-K12 -> 0 | V12: =1/(1+Inputs!$C16)^B12 -> 0 | W12: =K12*V12 -> 0 | X12: =T12*V12 -> 0 | Y12: =Y11+U12 -> 0
B13: 8 | C13: =0 -> 0 | D13: =Calculations!C12 -> 0 | E13: =Inputs!$C28*Calculations!$C$13 -> 0 | F13: =Calculations!C14 -> 0 | G13: =Calculations!C9*Inputs!$C40 -> 0 | H13: =Calculations!$C$9*(1-8/Inputs!$C15)*Inputs!$C41 -> 0 | I13: =IF(B13=Inputs!$C23,Inputs!$C29*Calculations!C6*(1-Inputs!$C61)^B13,0) -> 0 | J13: =IF(B13=Inputs!$C15,Inputs!$C30*Calculations!C5-Calculations!C15,0) -> 0 | K13: =SUM(C13:J13) -> 0 | L13: =Inputs!$C$52*Inputs!$C12*1000*(1+Inputs!$D$52)^7*(1-Inputs!$C21)^7 -> 0 | M13: =Inputs!$C$53*Inputs!$C12*1000*(1+Inputs!$D$53)^7*(1-Inputs!$C21)^7 -> 0 | N13: =Inputs!$C$54*Inputs!$C12*1000*(1+Inputs!$D$54)^7*(1-Inputs!$C21)^7 -> 0 | O13: =Inputs!$C$55*Inputs!$C12*1000*(1+Inputs!$D$55)^7*(1-Inputs!$C21)^7 -> 0 | P13: =Inputs!$C$56*Inputs!$C12*1000*(1+Inputs!$D$56)^7*(1-Inputs!$C21)^7 -> 0 | Q13: =Inputs!$C$57*Inputs!$C12*1000*(1+Inputs!$D$57)^7*(1-Inputs!$C21)^7 -> 0 | R13: =Inputs!$C$58*Inputs!$C12*1000*(1+Inputs!$D$58)^7*(1-Inputs!$C21)^7 -> 0 | S13: =Inputs!$C$59*Inputs!$C12*1000*(1+Inputs!$D$59)^7*(1-Inputs!$C21)^7 -> 0 | T13: =SUM(L13:S13) -> 0 | U13: =T13-K13 -> 0 | V13: =1/(1+Inputs!$C16)^B13 -> 0 | W13: =K13*V13 -> 0 | X13: =T13*V13 -> 0 | Y13: =Y12+U13 -> 0
B14: 9 | C14: =0 -> 0 | D14: =Calculations!C12 -> 0 | E14: =Inputs!$C28*Calculations!$C$13 -> 0 | F14: =Calculations!C14 -> 0 | G14: =Calculations!C9*Inputs!$C40 -> 0 | H14: =Calculations!$C$9*(1-9/Inputs!$C15)*Inputs!$C41 -> 0 | I14: =IF(B14=Inputs!$C23,Inputs!$C29*Calculations!C6*(1-Inputs!$C61)^B14,0) -> 0 | J14: =IF(B14=Inputs!$C15,Inputs!$C30*Calculations!C5-Calculations!C15,0) -> 0 | K14: =SUM(C14:J14) -> 0 | L14: =Inputs!$C$52*Inputs!$C12*1000*(1+Inputs!$D$52)^8*(1-Inputs!$C21)^8 -> 0 | M14: =Inputs!$C$53*Inputs!$C12*1000*(1+Inputs!$D$53)^8*(1-Inputs!$C21)^8 -> 0 | N14: =Inputs!$C$54*Inputs!$C12*1000*(1+Inputs!$D$54)^8*(1-Inputs!$C21)^8 -> 0 | O14: =Inputs!$C$55*Inputs!$C12*1000*(1+Inputs!$D$55)^8*(1-Inputs!$C21)^8 -> 0 | P14: =Inputs!$C$56*Inputs!$C12*1000*(1+Inputs!$D$56)^8*(1-Inputs!$C21)^8 -> 0 | Q14: =Inputs!$C$57*Inputs!$C12*1000*(1+Inputs!$D$57)^8*(1-Inputs!$C21)^8 -> 0 | R14: =Inputs!$C$58*Inputs!$C12*1000*(1+Inputs!$D$58)^8*(1-Inputs!$C21)^8 -> 0 | S14: =Inputs!$C$59*Inputs!$C12*1000*(1+Inputs!$D$59)^8*(1-Inputs!$C21)^8 -> 0 | T14: =SUM(L14:S14) -> 0 | U14: =T14-K14 -> 0 | V14: =1/(1+Inputs!$C16)^B14 -> 0 | W14: =K14*V14 -> 0 | X14: =T14*V14 -> 0 | Y14: =Y13+U14 -> 0
B15: 10 | C15: =0 -> 0 | D15: =Calculations!C12 -> 0 | E15: =Inputs!$C28*Calculations!$C$13 -> 0 | F15: =Calculations!C14 -> 0 | G15: =Calculations!C9*Inputs!$C40 -> 0 | H15: =Calculations!$C$9*(1-10/Inputs!$C15)*Inputs!$C41 -> 0 | I15: =IF(B15=Inputs!$C23,Inputs!$C29*Calculations!C6*(1-Inputs!$C61)^B15,0) -> 0 | J15: =IF(B15=Inputs!$C15,Inputs!$C30*Calculations!C5-Calculations!C15,0) -> 0 | K15: =SUM(C15:J15) -> 0 | L15: =Inputs!$C$52*Inputs!$C12*1000*(1+Inputs!$D$52)^9*(1-Inputs!$C21)^9 -> 0 | M15: =Inputs!$C$53*Inputs!$C12*1000*(1+Inputs!$D$53)^9*(1-Inputs!$C21)^9 -> 0 | N15: =Inputs!$C$54*Inputs!$C12*1000*(1+Inputs!$D$54)^9*(1-Inputs!$C21)^9 -> 0 | O15: =Inputs!$C$55*Inputs!$C12*1000*(1+Inputs!$D$55)^9*(1-Inputs!$C21)^9 -> 0 | P15: =Inputs!$C$56*Inputs!$C12*1000*(1+Inputs!$D$56)^9*(1-Inputs!$C21)^9 -> 0 | Q15: =Inputs!$C$57*Inputs!$C12*1000*(1+Inputs!$D$57)^9*(1-Inputs!$C21)^9 -> 0 | R15: =Inputs!$C$58*Inputs!$C12*1000*(1+Inputs!$D$58)^9*(1-Inputs!$C21)^9 -> 0 | S15: =Inputs!$C$59*Inputs!$C12*1000*(1+Inputs!$D$59)^9*(1-Inputs!$C21)^9 -> 0 | T15: =SUM(L15:S15) -> 0 | U15: =T15-K15 -> 0 | V15: =1/(1+Inputs!$C16)^B15 -> 0 | W15: =K15*V15 -> 0 | X15: =T15*V15 -> 0 | Y15: =Y14+U15 -> 0
B16: 11 | C16: =0 -> 0 | D16: =Calculations!C12 -> 0 | E16: =Inputs!$C28*Calculations!$C$13 -> 0 | F16: =Calculations!C14 -> 0 | G16: =Calculations!C9*Inputs!$C40 -> 0 | H16: =Calculations!$C$9*(1-11/Inputs!$C15)*Inputs!$C41 -> 0 | I16: =IF(B16=Inputs!$C23,Inputs!$C29*Calculations!C6*(1-Inputs!$C61)^B16,0) -> 0 | J16: =IF(B16=Inputs!$C15,Inputs!$C30*Calculations!C5-Calculations!C15,0) -> 0 | K16: =SUM(C16:J16) -> 0 | L16: =Inputs!$C$52*Inputs!$C12*1000*(1+Inputs!$D$52)^10*(1-Inputs!$C21)^10 -> 0 | M16: =Inputs!$C$53*Inputs!$C12*1000*(1+Inputs!$D$53)^10*(1-Inputs!$C21)^10 -> 0 | N16: =Inputs!$C$54*Inputs!$C12*1000*(1+Inputs!$D$54)^10*(1-Inputs!$C21)^10 -> 0 | O16: =Inputs!$C$55*Inputs!$C12*1000*(1+Inputs!$D$55)^10*(1-Inputs!$C21)^10 -> 0 | P16: =Inputs!$C$56*Inputs!$C12*1000*(1+Inputs!$D$56)^10*(1-Inputs!$C21)^10 -> 0 | Q16: =Inputs!$C$57*Inputs!$C12*1000*(1+Inputs!$D$57)^10*(1-Inputs!$C21)^10 -> 0 | R16: =Inputs!$C$58*Inputs!$C12*1000*(1+Inputs!$D$58)^10*(1-Inputs!$C21)^10 -> 0 | S16: =Inputs!$C$59*Inputs!$C12*1000*(1+Inputs!$D$59)^10*(1-Inputs!$C21)^10 -> 0 | T16: =SUM(L16:S16) -> 0 | U16: =T16-K16 -> 0 | V16: =1/(1+Inputs!$C16)^B16 -> 0 | W16: =K16*V16 -> 0 | X16: =T16*V16 -> 0 | Y16: =Y15+U16 -> 0
B17: 12 | C17: =0 -> 0 | D17: =Calculations!C12 -> 0 | E17: =Inputs!$C28*Calculations!$C$13 -> 0 | F17: =Calculations!C14 -> 0 | G17: =Calculations!C9*Inputs!$C40 -> 0 | H17: =Calculations!$C$9*(1-12/Inputs!$C15)*Inputs!$C41 -> 0 | I17: =IF(B17=Inputs!$C23,Inputs!$C29*Calculations!C6*(1-Inputs!$C61)^B17,0) -> 0 | J17: =IF(B17=Inputs!$C15,Inputs!$C30*Calculations!C5-Calculations!C15,0) -> 0 | K17: =SUM(C17:J17) -> 0 | L17: =Inputs!$C$52*Inputs!$C12*1000*(1+Inputs!$D$52)^11*(1-Inputs!$C21)^11 -> 0 | M17: =Inputs!$C$53*Inputs!$C12*1000*(1+Inputs!$D$53)^11*(1-Inputs!$C21)^11 -> 0 | N17: =Inputs!$C$54*Inputs!$C12*1000*(1+Inputs!$D$54)^11*(1-Inputs!$C21)^11 -> 0 | O17: =Inputs!$C$55*Inputs!$C12*1000*(1+Inputs!$D$55)^11*(1-Inputs!$C21)^11 -> 0 | P17: =Inputs!$C$56*Inputs!$C12*1000*(1+Inputs!$D$56)^11*(1-Inputs!$C21)^11 -> 0 | Q17: =Inputs!$C$57*Inputs!$C12*1000*(1+Inputs!$D$57)^11*(1-Inputs!$C21)^11 -> 0 | R17: =Inputs!$C$58*Inputs!$C12*1000*(1+Inputs!$D$58)^11*(1-Inputs!$C21)^11 -> 0 | S17: =Inputs!$C$59*Inputs!$C12*1000*(1+Inputs!$D$59)^11*(1-Inputs!$C21)^11 -> 0 | T17: =SUM(L17:S17) -> 0 | U17: =T17-K17 -> 0 | V17: =1/(1+Inputs!$C16)^B17 -> 0 | W17: =K17*V17 -> 0 | X17: =T17*V17 -> 0 | Y17: =Y16+U17 -> 0
B18: 13 | C18: =0 -> 0 | D18: =Calculations!C12 -> 0 | E18: =Inputs!$C28*Calculations!$C$13 -> 0 | F18: =Calculations!C14 -> 0 | G18: =Calculations!C9*Inputs!$C40 -> 0 | H18: =Calculations!$C$9*(1-13/Inputs!$C15)*Inputs!$C41 -> 0 | I18: =IF(B18=Inputs!$C23,Inputs!$C29*Calculations!C6*(1-Inputs!$C61)^B18,0) -> 0 | J18: =IF(B18=Inputs!$C15,Inputs!$C30*Calculations!C5-Calculations!C15,0) -> 0 | K18: =SUM(C18:J18) -> 0 | L18: =Inputs!$C$52*Inputs!$C12*1000*(1+Inputs!$D$52)^12*(1-Inputs!$C21)^12 -> 0 | M18: =Inputs!$C$53*Inputs!$C12*1000*(1+Inputs!$D$53)^12*(1-Inputs!$C21)^12 -> 0 | N18: =Inputs!$C$54*Inputs!$C12*1000*(1+Inputs!$D$54)^12*(1-Inputs!$C21)^12 -> 0 | O18: =Inputs!$C$55*Inputs!$C12*1000*(1+Inputs!$D$55)^12*(1-Inputs!$C21)^12 -> 0 | P18: =Inputs!$C$56*Inputs!$C12*1000*(1+Inputs!$D$56)^12*(1-Inputs!$C21)^12 -> 0 | Q18: =Inputs!$C$57*Inputs!$C12*1000*(1+Inputs!$D$57)^12*(1-Inputs!$C21)^12 -> 0 | R18: =Inputs!$C$58*Inputs!$C12*1000*(1+Inputs!$D$58)^12*(1-Inputs!$C21)^12 -> 0 | S18: =Inputs!$C$59*Inputs!$C12*1000*(1+Inputs!$D$59)^12*(1-Inputs!$C21)^12 -> 0 | T18: =SUM(L18:S18) -> 0 | U18: =T18-K18 -> 0 | V18: =1/(1+Inputs!$C16)^B18 -> 0 | W18: =K18*V18 -> 0 | X18: =T18*V18 -> 0 | Y18: =Y17+U18 -> 0
B19: 14 | C19: =0 -> 0 | D19: =Calculations!C12 -> 0 | E19: =Inputs!$C28*Calculations!$C$13 -> 0 | F19: =Calculations!C14 -> 0 | G19: =Calculations!C9*Inputs!$C40 -> 0 | H19: =Calculations!$C$9*(1-14/Inputs!$C15)*Inputs!$C41 -> 0 | I19: =IF(B19=Inputs!$C23,Inputs!$C29*Calculations!C6*(1-Inputs!$C61)^B19,0) -> 0 | J19: =IF(B19=Inputs!$C15,Inputs!$C30*Calculations!C5-Calculations!C15,0) -> 0 | K19: =SUM(C19:J19) -> 0 | L19: =Inputs!$C$52*Inputs!$C12*1000*(1+Inputs!$D$52)^13*(1-Inputs!$C21)^13 -> 0 | M19: =Inputs!$C$53*Inputs!$C12*1000*(1+Inputs!$D$53)^13*(1-Inputs!$C21)^13 -> 0 | N19: =Inputs!$C$54*Inputs!$C12*1000*(1+Inputs!$D$54)^13*(1-Inputs!$C21)^13 -> 0 | O19: =Inputs!$C$55*Inputs!$C12*1000*(1+Inputs!$D$55)^13*(1-Inputs!$C21)^13 -> 0 | P19: =Inputs!$C$56*Inputs!$C12*1000*(1+Inputs!$D$56)^13*(1-Inputs!$C21)^13 -> 0 | Q19: =Inputs!$C$57*Inputs!$C12*1000*(1+Inputs!$D$57)^13*(1-Inputs!$C21)^13 -> 0 | R19: =Inputs!$C$58*Inputs!$C12*1000*(1+Inputs!$D$58)^13*(1-Inputs!$C21)^13 -> 0 | S19: =Inputs!$C$59*Inputs!$C12*1000*(1+Inputs!$D$59)^13*(1-Inputs!$C21)^13 -> 0 | T19: =SUM(L19:S19) -> 0 | U19: =T19-K19 -> 0 | V19: =1/(1+Inputs!$C16)^B19 -> 0 | W19: =K19*V19 -> 0 | X19: =T19*V19 -> 0 | Y19: =Y18+U19 -> 0
B20: 15 | C20: =0 -> 0 | D20: =Calculations!C12 -> 0 | E20: =Inputs!$C28*Calculations!$C$13 -> 0 | F20: =Calculations!C14 -> 0 | G20: =Calculations!C9*Inputs!$C40 -> 0 | H20: =Calculations!$C$9*(1-15/Inputs!$C15)*Inputs!$C41 -> 0 | I20: =IF(B20=Inputs!$C23,Inputs!$C29*Calculations!C6*(1-Inputs!$C61)^B20,0) -> 0 | J20: =IF(B20=Inputs!$C15,Inputs!$C30*Calculations!C5-Calculations!C15,0) -> 0 | K20: =SUM(C20:J20) -> 0 | L20: =Inputs!$C$52*Inputs!$C12*1000*(1+Inputs!$D$52)^14*(1-Inputs!$C21)^14 -> 0 | M20: =Inputs!$C$53*Inputs!$C12*1000*(1+Inputs!$D$53)^14*(1-Inputs!$C21)^14 -> 0 | N20: =Inputs!$C$54*Inputs!$C12*1000*(1+Inputs!$D$54)^14*(1-Inputs!$C21)^14 -> 0 | O20: =Inputs!$C$55*Inputs!$C12*1000*(1+Inputs!$D$55)^14*(1-Inputs!$C21)^14 -> 0 | P20: =Inputs!$C$56*Inputs!$C12*1000*(1+Inputs!$D$56)^14*(1-Inputs!$C21)^14 -> 0 | Q20: =Inputs!$C$57*Inputs!$C12*1000*(1+Inputs!$D$57)^14*(1-Inputs!$C21)^14 -> 0 | R20: =Inputs!$C$58*Inputs!$C12*1000*(1+Inputs!$D$58)^14*(1-Inputs!$C21)^14 -> 0 | S20: =Inputs!$C$59*Inputs!$C12*1000*(1+Inputs!$D$59)^14*(1-Inputs!$C21)^14 -> 0 | T20: =SUM(L20:S20) -> 0 | U20: =T20-K20 -> 0 | V20: =1/(1+Inputs!$C16)^B20 -> 0 | W20: =K20*V20 -> 0 | X20: =T20*V20 -> 0 | Y20: =Y19+U20 -> 0
B21: 16 | C21: =0 -> 0 | D21: =Calculations!C12 -> 0 | E21: =Inputs!$C28*Calculations!$C$13 -> 0 | F21: =Calculations!C14 -> 0 | G21: =Calculations!C9*Inputs!$C40 -> 0 | H21: =Calculations!$C$9*(1-16/Inputs!$C15)*Inputs!$C41 -> 0 | I21: =IF(B21=Inputs!$C23,Inputs!$C29*Calculations!C6*(1-Inputs!$C61)^B21,0) -> 0 | J21: =IF(B21=Inputs!$C15,Inputs!$C30*Calculations!C5-Calculations!C15,0) -> 0 | K21: =SUM(C21:J21) -> 0 | L21: =Inputs!$C$52*Inputs!$C12*1000*(1+Inputs!$D$52)^15*(1-Inputs!$C21)^15 -> 0 | M21: =Inputs!$C$53*Inputs!$C12*1000*(1+Inputs!$D$53)^15*(1-Inputs!$C21)^15 -> 0 | N21: =Inputs!$C$54*Inputs!$C12*1000*(1+Inputs!$D$54)^15*(1-Inputs!$C21)^15 -> 0 | O21: =Inputs!$C$55*Inputs!$C12*1000*(1+Inputs!$D$55)^15*(1-Inputs!$C21)^15 -> 0 | P21: =Inputs!$C$56*Inputs!$C12*1000*(1+Inputs!$D$56)^15*(1-Inputs!$C21)^15 -> 0 | Q21: =Inputs!$C$57*Inputs!$C12*1000*(1+Inputs!$D$57)^15*(1-Inputs!$C21)^15 -> 0 | R21: =Inputs!$C$58*Inputs!$C12*1000*(1+Inputs!$D$58)^15*(1-Inputs!$C21)^15 -> 0 | S21: =Inputs!$C$59*Inputs!$C12*1000*(1+Inputs!$D$59)^15*(1-Inputs!$C21)^15 -> 0 | T21: =SUM(L21:S21) -> 0 | U21: =T21-K21 -> 0 | V21: =1/(1+Inputs!$C16)^B21 -> 0 | W21: =K21*V21 -> 0 | X21: =T21*V21 -> 0 | Y21: =Y20+U21 -> 0
B22: 17 | C22: =0 -> 0 | D22: =Calculations!C12 -> 0 | E22: =Inputs!$C28*Calculations!$C$13 -> 0 | F22: =Calculations!C14 -> 0 | G22: =Calculations!C9*Inputs!$C40 -> 0 | H22: =Calculations!$C$9*(1-17/Inputs!$C15)*Inputs!$C41 -> 0 | I22: =IF(B22=Inputs!$C23,Inputs!$C29*Calculations!C6*(1-Inputs!$C61)^B22,0) -> 0 | J22: =IF(B22=Inputs!$C15,Inputs!$C30*Calculations!C5-Calculations!C15,0) -> 0 | K22: =SUM(C22:J22) -> 0 | L22: =Inputs!$C$52*Inputs!$C12*1000*(1+Inputs!$D$52)^16*(1-Inputs!$C21)^16 -> 0 | M22: =Inputs!$C$53*Inputs!$C12*1000*(1+Inputs!$D$53)^16*(1-Inputs!$C21)^16 -> 0 | N22: =Inputs!$C$54*Inputs!$C12*1000*(1+Inputs!$D$54)^16*(1-Inputs!$C21)^16 -> 0 | O22: =Inputs!$C$55*Inputs!$C12*1000*(1+Inputs!$D$55)^16*(1-Inputs!$C21)^16 -> 0 | P22: =Inputs!$C$56*Inputs!$C12*1000*(1+Inputs!$D$56)^16*(1-Inputs!$C21)^16 -> 0 | Q22: =Inputs!$C$57*Inputs!$C12*1000*(1+Inputs!$D$57)^16*(1-Inputs!$C21)^16 -> 0 | R22: =Inputs!$C$58*Inputs!$C12*1000*(1+Inputs!$D$58)^16*(1-Inputs!$C21)^16 -> 0 | S22: =Inputs!$C$59*Inputs!$C12*1000*(1+Inputs!$D$59)^16*(1-Inputs!$C21)^16 -> 0 | T22: =SUM(L22:S22) -> 0 | U22: =T22-K22 -> 0 | V22: =1/(1+Inputs!$C16)^B22 -> 0 | W22: =K22*V22 -> 0 | X22: =T22*V22 -> 0 | Y22: =Y21+U22 -> 0
B23: 18 | C23: =0 -> 0 | D23: =Calculations!C12 -> 0 | E23: =Inputs!$C28*Calculations!$C$13 -> 0 | F23: =Calculations!C14 -> 0 | G23: =Calculations!C9*Inputs!$C40 -> 0 | H23: =Calculations!$C$9*(1-18/Inputs!$C15)*Inputs!$C41 -> 0 | I23: =IF(B23=Inputs!$C23,Inputs!$C29*Calculations!C6*(1-Inputs!$C61)^B23,0) -> 0 | J23: =IF(B23=Inputs!$C15,Inputs!$C30*Calculations!C5-Calculations!C15,0) -> 0 | K23: =SUM(C23:J23) -> 0 | L23: =Inputs!$C$52*Inputs!$C12*1000*(1+Inputs!$D$52)^17*(1-Inputs!$C21)^17 -> 0 | M23: =Inputs!$C$53*Inputs!$C12*1000*(1+Inputs!$D$53)^17*(1-Inputs!$C21)^17 -> 0 | N23: =Inputs!$C$54*Inputs!$C12*1000*(1+Inputs!$D$54)^17*(1-Inputs!$C21)^17 -> 0 | O23: =Inputs!$C$55*Inputs!$C12*1000*(1+Inputs!$D$55)^17*(1-Inputs!$C21)^17 -> 0 | P23: =Inputs!$C$56*Inputs!$C12*1000*(1+Inputs!$D$56)^17*(1-Inputs!$C21)^17 -> 0 | Q23: =Inputs!$C$57*Inputs!$C12*1000*(1+Inputs!$D$57)^17*(1-Inputs!$C21)^17 -> 0 | R23: =Inputs!$C$58*Inputs!$C12*1000*(1+Inputs!$D$58)^17*(1-Inputs!$C21)^17 -> 0 | S23: =Inputs!$C$59*Inputs!$C12*1000*(1+Inputs!$D$59)^17*(1-Inputs!$C21)^17 -> 0 | T23: =SUM(L23:S23) -> 0 | U23: =T23-K23 -> 0 | V23: =1/(1+Inputs!$C16)^B23 -> 0 | W23: =K23*V23 -> 0 | X23: =T23*V23 -> 0 | Y23: =Y22+U23 -> 0
B24: 19 | C24: =0 -> 0 | D24: =Calculations!C12 -> 0 | E24: =Inputs!$C28*Calculations!$C$13 -> 0 | F24: =Calculations!C14 -> 0 | G24: =Calculations!C9*Inputs!$C40 -> 0 | H24: =Calculations!$C$9*(1-19/Inputs!$C15)*Inputs!$C41 -> 0 | I24: =IF(B24=Inputs!$C23,Inputs!$C29*Calculations!C6*(1-Inputs!$C61)^B24,0) -> 0 | J24: =IF(B24=Inputs!$C15,Inputs!$C30*Calculations!C5-Calculations!C15,0) -> 0 | K24: =SUM(C24:J24) -> 0 | L24: =Inputs!$C$52*Inputs!$C12*1000*(1+Inputs!$D$52)^18*(1-Inputs!$C21)^18 -> 0 | M24: =Inputs!$C$53*Inputs!$C12*1000*(1+Inputs!$D$53)^18*(1-Inputs!$C21)^18 -> 0 | N24: =Inputs!$C$54*Inputs!$C12*1000*(1+Inputs!$D$54)^18*(1-Inputs!$C21)^18 -> 0 | O24: =Inputs!$C$55*Inputs!$C12*1000*(1+Inputs!$D$55)^18*(1-Inputs!$C21)^18 -> 0 | P24: =Inputs!$C$56*Inputs!$C12*1000*(1+Inputs!$D$56)^18*(1-Inputs!$C21)^18 -> 0 | Q24: =Inputs!$C$57*Inputs!$C12*1000*(1+Inputs!$D$57)^18*(1-Inputs!$C21)^18 -> 0 | R24: =Inputs!$C$58*Inputs!$C12*1000*(1+Inputs!$D$58)^18*(1-Inputs!$C21)^18 -> 0 | S24: =Inputs!$C$59*Inputs!$C12*1000*(1+Inputs!$D$59)^18*(1-Inputs!$C21)^18 -> 0 | T24: =SUM(L24:S24) -> 0 | U24: =T24-K24 -> 0 | V24: =1/(1+Inputs!$C16)^B24 -> 0 | W24: =K24*V24 -> 0 | X24: =T24*V24 -> 0 | Y24: =Y23+U24 -> 0
B25: 20 | C25: =0 -> 0 | D25: =Calculations!C12 -> 0 | E25: =Inputs!$C28*Calculations!$C$13 -> 0 | F25: =Calculations!C14 -> 0 | G25: =Calculations!C9*Inputs!$C40 -> 0 | H25: =Calculations!$C$9*(1-20/Inputs!$C15)*Inputs!$C41 -> 0 | I25: =IF(B25=Inputs!$C23,Inputs!$C29*Calculations!C6*(1-Inputs!$C61)^B25,0) -> 0 | J25: =IF(B25=Inputs!$C15,Inputs!$C30*Calculations!C5-Calculations!C15,0) -> 0 | K25: =SUM(C25:J25) -> 0 | L25: =Inputs!$C$52*Inputs!$C12*1000*(1+Inputs!$D$52)^19*(1-Inputs!$C21)^19 -> 0 | M25: =Inputs!$C$53*Inputs!$C12*1000*(1+Inputs!$D$53)^19*(1-Inputs!$C21)^19 -> 0 | N25: =Inputs!$C$54*Inputs!$C12*1000*(1+Inputs!$D$54)^19*(1-Inputs!$C21)^19 -> 0 | O25: =Inputs!$C$55*Inputs!$C12*1000*(1+Inputs!$D$55)^19*(1-Inputs!$C21)^19 -> 0 | P25: =Inputs!$C$56*Inputs!$C12*1000*(1+Inputs!$D$56)^19*(1-Inputs!$C21)^19 -> 0 | Q25: =Inputs!$C$57*Inputs!$C12*1000*(1+Inputs!$D$57)^19*(1-Inputs!$C21)^19 -> 0 | R25: =Inputs!$C$58*Inputs!$C12*1000*(1+Inputs!$D$58)^19*(1-Inputs!$C21)^19 -> 0 | S25: =Inputs!$C$59*Inputs!$C12*1000*(1+Inputs!$D$59)^19*(1-Inputs!$C21)^19 -> 0 | T25: =SUM(L25:S25) -> 0 | U25: =T25-K25 -> 0 | V25: =1/(1+Inputs!$C16)^B25 -> 0 | W25: =K25*V25 -> 0 | X25: =T25*V25 -> 0 | Y25: =Y24+U25 -> 0
B27: TOTALS | K27: =SUM(K5:K25) -> 0 | T27: =SUM(T5:T25) -> 0 | W27: =SUM(W5:W25) -> 0 | X27: =SUM(X5:X25) -> 0

Sheet Calculations
B2: Calculation Engine
B4: DERIVED VALUES
B5: Capacity (kW) | C5: =Inputs!C12*1000 -> 0 | D5: Convert MW to kW
B6: Capacity (kWh) | C6: =Inputs!C14*1000 -> 0 | D6: Convert MWh to kWh
B7: Battery CapEx ($) | C7: =Inputs!C26*C6 -> 0 | D7: CapEx/kWh x kWh
B8: Infrastructure ($) | C8: =(Inputs!C37+Inputs!C38+Inputs!C39)*C5 -> 0 | D8: Interconnect+Land+Permit
B9: Total CapEx ($) | C9: =C7+C8 -> 0 | D9: Battery + Infrastructure
B10: ITC Credit ($) | C10: =C7*(Inputs!C34+Inputs!C35) -> 0 | D10: ITC on battery only
B11: Net Year 0 Cost ($) | C11: =C9-C10 -> 0 | D11: CapEx minus ITC
B12: Annual Fixed O&M ($) | C12: =Inputs!C27*C5 -> 0 | D12: FOM/kW x kW
B13: Annual Energy (MWh) | C13: =Inputs!C14*Inputs!C24*365*Inputs!C20 -> 0 | D13: MWh x cycles/day x 365 x RTE
B14: Annual Charging Cost ($) | C14: =C13/Inputs!C20*Inputs!C31 -> 0 | D14: Energy/RTE x charging cost
B15: Residual Value ($) | C15: =C9*Inputs!C32 -> 0 | D15: CapEx x residual %
B17: KEY FORMULAS
B18: NPV | C18: Sum(CFt / (1+r)^t) for t=0 to N | D18: Brealey & Myers (2020)
B19: BCR | C19: PV(Benefits) / PV(Costs) | D19: CPUC Standard Practice Manual
B20: IRR | C20: Rate where NPV = 0 | D20: Brealey & Myers (2020)
B21: LCOS | C21: PV(Costs) / PV(Energy) | D21: Lazard Methodology
B22: Payback | C22: Year where cumulative CF > 0 | D22: Standard finance

Sheet Sensitivity
B2: Sensitivity Analysis - NPV & BCR Impact
B4: These tables show how key metrics change with different CapEx and Benefit multipliers.
B6: NET PRESENT VALUE ($) SENSITIVITY
B7: NPV ($) | C7: 70% Benefits | D7: 80% Benefits | E7: 90% Benefits | F7: 100% Benefits | G7: 110% Benefits | H7: 120% Benefits | I7: 130% Benefits
B8: $100/kWh | C8: =(Cash_Flows!X27*0.7)-(Cash_Flows!W27*(1+(100-Inputs!$C26)/Inputs!$C26)) -> 0 | D8: =(Cash_Flows!X27*0.8)-(Cash_Flows!W27*(1+(100-Inputs!$C26)/Inputs!$C26)) -> 0 | E8: =(Cash_Flows!X27*0.9)-(Cash_Flows!W27*(1+(100-Inputs!$C26)/Inputs!$C26)) -> 0 | F8: =(Cash_Flows!X27*1.0)-(Cash_Flows!W27*(1+(100-Inputs!$C26)/Inputs!$C26)) -> 0 | G8: =(Cash_Flows!X27*1.1)-(Cash_Flows!W27*(1+(100-Inputs!$C26)/Inputs!$C26)) -> 0 | H8: =(Cash_Flows!X27*1.2)-(Cash_Flows!W27*(1+(100-Inputs!$C26)/Inputs!$C26)) -> 0 | I8: =(Cash_Flows!X27*1.3)-(Cash_Flows!W27*(1+(100-Inputs!$C26)/Inputs!$C26)) -> 0
B9: $120/kWh | C9: =(Cash_Flows!X27*0.7)-(Cash_Flows!W27*(1+(120-Inputs!$C26)/Inputs!$C26)) -> 0 | D9: =(Cash_Flows!X27*0.8)-(Cash_Flows!W27*(1+(120-Inputs!$C26)/Inputs!$C26)) -> 0 | E9: =(Cash_Flows!X27*0.9)-(Cash_Flows!W27*(1+(120-Inputs!$C26)/Inputs!$C26)) -> 0 | F9: =(Cash_Flows!X27*1.0)-(Cash_Flows!W27*(1+(120-Inputs!$C26)/Inputs!$C26)) -> 0 | G9: =(Cash_Flows!X27*1.1)-(Cash_Flows!W27*(1+(120-Inputs!$C26)/Inputs!$C26)) -> 0 | H9: =(Cash_Flows!X27*1.2)-(Cash_Flows!W27*(1+(120-Inputs!$C26)/Inputs!$C26)) -> 0 | I9: =(Cash_Flows!X27*1.3)-(Cash_Flows!W27*(1+(120-Inputs!$C26)/Inputs!$C26)) -> 0
B10: $140/kWh | C10: =(Cash_Flows!X27*0.7)-(Cash_Flows!W27*(1+(140-Inputs!$C26)/Inputs!$C26)) -> 0 | D10: =(Cash_Flows!X27*0.8)-(Cash_Flows!W27*(1+(140-Inputs!$C26)/Inputs!$C26)) -> 0 | E10: =(Cash_Flows!X27*0.9)-(Cash_Flows!W27*(1+(140-Inputs!$C26)/Inputs!$C26)) -> 0 | F10: =(Cash_Flows!X27*1.0)-(Cash_Flows!W27*(1+(140-Inputs!$C26)/Inputs!$C26)) -> 0 | G10: =(Cash_Flows!X27*1.1)-(Cash_Flows!W27*(1+(140-Inputs!$C26)/Inputs!$C26)) -> 0 | H10: =(Cash_Flows!X27*1.2)-(Cash_Flows!W27*(1+(140-Inputs!$C26)/Inputs!$C26)) -> 0 | I10: =(Cash_Flows!X27*1.3)-(Cash_Flows!W27*(1+(140-Inputs!$C26)/Inputs!$C26)) -> 0
B11: $160/kWh | C11: =(Cash_Flows!X27*0.7)-(Cash_Flows!W27*(1+(160-Inputs!$C26)/Inputs!$C26)) -> 0 | D11: =(Cash_Flows!X27*0.8)-(Cash_Flows!W27*(1+(160-Inputs!$C26)/Inputs!$C26)) -> 0 | E11: =(Cash_Flows!X27*0.9)-(Cash_Flows!W27*(1+(160-Inputs!$C26)/Inputs!$C26)) -> 0 | F11: =(Cash_Flows!X27*1.0)-(Cash_Flows!W27*(1+(160-Inputs!$C26)/Inputs!$C26)) -> 0 | G11: =(Cash_Flows!X27*1.1)-(Cash_Flows!W27*(1+(160-Inputs!$C26)/Inputs!$C26)) -> 0 | H11: =(Cash_Flows!X27*1.2)-(Cash_Flows!W27*(1+(160-Inputs!$C26)/Inputs!$C26)) -> 0 | I11: =(Cash_Flows!X27*1.3)-(Cash_Flows!W27*(1+(160-Inputs!$C26)/Inputs!$C26)) -> 0
B12: $180/kWh | C12: =(Cash_Flows!X27*0.7)-(Cash_Flows!W27*(1+(180-Inputs!$C26)/Inputs!$C26)) -> 0 | D12: =(Cash_Flows!X27*0.8)-(Cash_Flows!W27*(1+(180-Inputs!$C26)/Inputs!$C26)) -> 0 | E12: =(Cash_Flows!X27*0.9)-(Cash_Flows!W27*(1+(180-Inputs!$C26)/Inputs!$C26)) -> 0 | F12: =(Cash_Flows!X27*1.0)-(Cash_Flows!W27*(1+(180-Inputs!$C26)/Inputs!$C26)) -> 0 | G12: =(Cash_Flows!X27*1.1)-(Cash_Flows!W27*(1+(180-Inputs!$C26)/Inputs!$C26)) -> 0 | H12: =(Cash_Flows!X27*1.2)-(Cash_Flows!W27*(1+(180-Inputs!$C26)/Inputs!$C26)) -> 0 | I12: =(Cash_Flows!X27*1.3)-(Cash_Flows!W27*(1+(180-Inputs!$C26)/Inputs!$C26)) -> 0
B13: $200/kWh | C13: =(Cash_Flows!X27*0.7)-(Cash_Flows!W27*(1+(200-Inputs!$C26)/Inputs!$C26)) -> 0 | D13: =(Cash_Flows!X27*0.8)-(Cash_Flows!W27*(1+(200-Inputs!$C26)/Inputs!$C26)) -> 0 | E13: =(Cash_Flows!X27*0.9)-(Cash_Flows!W27*(1+(200-Inputs!$C26)/Inputs!$C26)) -> 0 | F13: =(Cash_Flows!X27*1.0)-(Cash_Flows!W27*(1+(200-Inputs!$C26)/Inputs!$C26)) -> 0 | G13: =(Cash_Flows!X27*1.1)-(Cash_Flows!W27*(1+(200-Inputs!$C26)/Inputs!$C26)) -> 0 | H13: =(Cash_Flows!X27*1.2)-(Cash_Flows!W27*(1+(200-Inputs!$C26)/Inputs!$C26)) -> 0 | I13: =(Cash_Flows!X27*1.3)-(Cash_Flows!W27*(1+(200-Inputs!$C26)/Inputs!$C26)) -> 0
B14: $220/kWh | C14: =(Cash_Flows!X27*0.7)-(Cash_Flows!W27*(1+(220-Inputs!$C26)/Inputs!$C26)) -> 0 | D14: =(Cash_Flows!X27*0.8)-(Cash_Flows!W27*(1+(220-Inputs!$C26)/Inputs!$C26)) -> 0 | E14: =(Cash_Flows!X27*0.9)-(Cash_Flows!W27*(1+(220-Inputs!$C26)/Inputs!$C26)) -> 0 | F14: =(Cash_Flows!X27*1.0)-(Cash_Flows!W27*(1+(220-Inputs!$C26)/Inputs!$C26)) -> 0 | G14: =(Cash_Flows!X27*1.1)-(Cash_Flows!W27*(1+(220-Inputs!$C26)/Inputs!$C26)) -> 0 | H14: =(Cash_Flows!X27*1.2)-(Cash_Flows!W27*(1+(220-Inputs!$C26)/Inputs!$C26)) -> 0 | I14: =(Cash_Flows!X27*1.3)-(Cash_Flows!W27*(1+(220-Inputs!$C26)/Inputs!$C26)) -> 0
B17: BENEFIT-COST RATIO SENSITIVITY
B18: BCR | C18: 70% Benefits | D18: 80% Benefits | E18: 90% Benefits | F18: 100% Benefits | G18: 110% Benefits | H18: 120% Benefits | I18: 130% Benefits
B19: $100/kWh | C19: =(Cash_Flows!X27*0.7)/(Cash_Flows!W27*(1+(100-Inputs!$C26)/Inputs!$C26)) -> 0 | D19: =(Cash_Flows!X27*0.8)/(Cash_Flows!W27*(1+(100-Inputs!$C26)/Inputs!$C26)) -> 0 | E19: =(Cash_Flows!X27*0.9)/(Cash_Flows!W27*(1+(100-Inputs!$C26)/Inputs!$C26)) -> 0 | F19: =(Cash_Flows!X27*1.0)/(Cash_Flows!W27*(1+(100-Inputs!$C26)/Inputs!$C26)) -> 0 | G19: =(Cash_Flows!X27*1.1)/(Cash_Flows!W27*(1+(100-Inputs!$C26)/Inputs!$C26)) -> 0 | H19: =(Cash_Flows!X27*1.2)/(Cash_Flows!W27*(1+(100-Inputs!$C26)/Inputs!$C26)) -> 0 | I19: =(Cash_Flows!X27*1.3)/(Cash_Flows!W27*(1+(100-Inputs!$C26)/Inputs!$C26)) -> 0
B20: $120/kWh | C20: =(Cash_Flows!X27*0.7)/(Cash_Flows!W27*(1+(120-Inputs!$C26)/Inputs!$C26)) -> 0 | D20: =(Cash_Flows!X27*0.8)/(Cash_Flows!W27*(1+(120-Inputs!$C26)/Inputs!$C26)) -> 0 | E20: =(Cash_Flows!X27*0.9)/(Cash_Flows!W27*(1+(120-Inputs!$C26)/Inputs!$C26)) -> 0 | F20: =(Cash_Flows!X27*1.0)/(Cash_Flows!W27*(1+(120-Inputs!$C26)/Inputs!$C26)) -> 0 | G20: =(Cash_Flows!X27*1.1)/(Cash_Flows!W27*(1+(120-Inputs!$C26)/Inputs!$C26)) -> 0 | H20: =(Cash_Flows!X27*1.2)/(Cash_Flows!W27*(1+(120-Inputs!$C26)/Inputs!$C26)) -> 0 | I20: =(Cash_Flows!X27*1.3)/(Cash_Flows!W27*(1+(120-Inputs!$C26)/Inputs!$C26)) -> 0
B21: $140/kWh | C21: =(Cash_Flows!X27*0.7)/(Cash_Flows!W27*(1+(140-Inputs!$C26)/Inputs!$C26)) -> 0 | D21: =(Cash_Flows!X27*0.8)/(Cash_Flows!W27*(1+(140-Inputs!$C26)/Inputs!$C26)) -> 0 | E21: =(Cash_Flows!X27*0.9)/(Cash_Flows!W27*(1+(140-Inputs!$C26)/Inputs!$C26)) -> 0 | F21: =(Cash_Flows!X27*1.0)/(Cash_Flows!W27*(1+(140-Inputs!$C26)/Inputs!$C26)) -> 0 | G21: =(Cash_Flows!X27*1.1)/(Cash_Flows!W27*(1+(140-Inputs!$C26)/Inputs!$C26)) -> 0 | H21: =(Cash_Flows!X27*1.2)/(Cash_Flows!W27*(1+(140-Inputs!$C26)/Inputs!$C26)) -> 0 | I21: =(Cash_Flows!X27*1.3)/(Cash_Flows!W27*(1+(140-Inputs!$C26)/Inputs!$C26)) -> 0
B22: $160/kWh | C22: =(Cash_Flows!X27*0.7)/(Cash_Flows!W27*(1+(160-Inputs!$C26)/Inputs!$C26)) -> 0 | D22: =(Cash_Flows!X27*0.8)/(Cash_Flows!W27*(1+(160-Inputs!$C26)/Inputs!$C26)) -> 0 | E22: =(Cash_Flows!X27*0.9)/(Cash_Flows!W27*(1+(160-Inputs!$C26)/Inputs!$C26)) -> 0 | F22: =(Cash_Flows!X27*1.0)/(Cash_Flows!W27*(1+(160-Inputs!$C26)/Inputs!$C26)) -> 0 | G22: =(Cash_Flows!X27*1.1)/(Cash_Flows!W27*(1+(160-Inputs!$C26)/Inputs!$C26)) -> 0 | H22: =(Cash_Flows!X27*1.2)/(Cash_Flows!W27*(1+(160-Inputs!$C26)/Inputs!$C26)) -> 0 | I22: =(Cash_Flows!X27*1.3)/(Cash_Flows!W27*(1+(160-Inputs!$C26)/Inputs!$C26)) -> 0
B23: $180/kWh | C23: =(Cash_Flows!X27*0.7)/(Cash_Flows!W27*(1+(180-Inputs!$C26)/Inputs!$C26)) -> 0 | D23: =(Cash_Flows!X27*0.8)/(Cash_Flows!W27*(1+(180-Inputs!$C26)/Inputs!$C26)) -> 0 | E23: =(Cash_Flows!X27*0.9)/(Cash_Flows!W27*(1+(180-Inputs!$C26)/Inputs!$C26)) -> 0 | F23: =(Cash_Flows!X27*1.0)/(Cash_Flows!W27*(1+(180-Inputs!$C26)/Inputs!$C26)) -> 0 | G23: =(Cash_Flows!X27*1.1)/(Cash_Flows!W27*(1+(180-Inputs!$C26)/Inputs!$C26)) -> 0 | H23: =(Cash_Flows!X27*1.2)/(Cash_Flows!W27*(1+(180-Inputs!$C26)/Inputs!$C26)) -> 0 | I23: =(Cash_Flows!X27*1.3)/(Cash_Flows!W27*(1+(180-Inputs!$C26)/Inputs!$C26)) -> 0
B24: $200/kWh | C24: =(Cash_Flows!X27*0.7)/(Cash_Flows!W27*(1+(200-Inputs!$C26)/Inputs!$C26)) -> 0 | D24: =(Cash_Flows!X27*0.8)/(Cash_Flows!W27*(1+(200-Inputs!$C26)/Inputs!$C26)) -> 0 | E24: =(Cash_Flows!X27*0.9)/(Cash_Flows!W27*(1+(200-Inputs!$C26)/Inputs!$C26)) -> 0 | F24: =(Cash_Flows!X27*1.0)/(Cash_Flows!W27*(1+(200-Inputs!$C26)/Inputs!$C26)) -> 0 | G24: =(Cash_Flows!X27*1.1)/(Cash_Flows!W27*(1+(200-Inputs!$C26)/Inputs!$C26)) -> 0 | H24: =(Cash_Flows!X27*1.2)/(Cash_Flows!W27*(1+(200-Inputs!$C26)/Inputs!$C26)) -> 0 | I24: =(Cash_Flows!X27*1.3)/(Cash_Flows!W27*(1+(200-Inputs!$C26)/Inputs!$C26)) -> 0
B25: $220/kWh | C25: =(Cash_Flows!X27*0.7)/(Cash_Flows!W27*(1+(220-Inputs!$C26)/Inputs!$C26)) -> 0 | D25: =(Cash_Flows!X27*0.8)/(Cash_Flows!W27*(1+(220-Inputs!$C26)/Inputs!$C26)) -> 0 | E25: =(Cash_Flows!X27*0.9)/(Cash_Flows!W27*(1+(220-Inputs!$C26)/Inputs!$C26)) -> 0 | F25: =(Cash_Flows!X27*1.0)/(Cash_Flows!W27*(1+(220-Inputs!$C26)/Inputs!$C26)) -> 0 | G25: =(Cash_Flows!X27*1.1)/(Cash_Flows!W27*(1+(220-Inputs!$C26)/Inputs!$C26)) -> 0 | H25: =(Cash_Flows!X27*1.2)/(Cash_Flows!W27*(1+(220-Inputs!$C26)/Inputs!$C26)) -> 0 | I25: =(Cash_Flows!X27*1.3)/(Cash_Flows!W27*(1+(220-Inputs!$C26)/Inputs!$C26)) -> 0
B28: SINGLE VARIABLE IMPACTS
B29: Parameter | C29: Base Value | D29: -20% NPV | E29: +20% NPV
B30: CapEx ($/kWh) | C30: =Inputs!C26 -> 0 | D30: =Results!C12-(Calculations!C9*0.2/(1+Inputs!C16)^0) -> 0 | E30: =Results!C12+(Calculations!C9*0.2/(1+Inputs!C16)^0) -> 0
B31: Total Benefits | C31: =Cash_Flows!X27 -> 0 | D31: =Results!C12-Cash_Flows!X27*0.2 -> 0 | E31: =Results!C12+Cash_Flows!X27*0.2 -> 0
B32: Discount Rate | C32: =Inputs!C16 -> 0 | D32: =Results!C12*1.15 -> 0 | E32: =Results!C12*0.85 -> 0
B33: Cycles per Day | C33: =Inputs!C24 -> 0 | D33: =Results!C12*0.85 -> 0 | E33: =Results!C12*1.15 -> 0
B36: NOTES
B37: • Green cells indicate BCR >= 1.5 (strong project economics)
B38: • Yellow cells indicate BCR between 1.0-1.5 (marginal economics)
B39: • Red cells indicate BCR < 1.0 (costs exceed benefits)
B40: • Sensitivity tables assume proportional scaling of CapEx-related costs
B41: • Single variable impacts show approximate NPV change for ±20% parameter change

Sheet Methodology
B2: Methodology & References
B4: OVERVIEW
B5: This workbook performs economic analysis of battery energy storage system (BESS) projects using standard discounted cash flow (DCF) methodology. All calculations follow industry-standard approaches from NREL, Lazard, and the California Public Utilities Commission (CPUC).
B7: KEY FORMULAS
B8: Net Present Value (NPV)
B9: Formula: NPV = Sum(CFt / (1+r)^t) for t=0 to N
B10: Where CFt = cash flow in year t, r = discount rate, N = analysis period
B12: Benefit-Cost Ratio (BCR)
B13: Formula: BCR = PV(Benefits) / PV(Costs)
B14: BCR > 1.0 indicates project creates net value; BCR > 1.5 is strong
B16: Internal Rate of Return (IRR)
B17: Formula: IRR: Find r where NPV = 0
... B39: This model is provided for analytical purposes only. Results should be validated against independent sources before use in investment decisions. Actual project economics will vary based on site-specific conditions, market dynamics, and evolving technology costs.

Sheet Library_Data
A1: Assumption Library Data
A3: Parameter | B3: NREL ATB 2024 | C3: Lazard LCOS 2025 | D3: CPUC CA 2024
A4: CapEx ($/kWh) | B4: 160 | C4: 145 | D4: 155
A5: Fixed O&M ($/kW-yr) | B5: 25 | C5: 22 | D5: 26
A6: Variable O&M ($/MWh) | B6: 0 | C6: 0.5 | D6: 0
A7: Augmentation ($/kWh) | B7: 55 | C7: 50 | D7: 52
A8: Decommissioning ($/kW) | B8: 10 | C8: 8 | D8: 12
A9: Charging Cost ($/MWh) | B9: 30 | C9: 35 | D9: 25
A10: Residual Value | B10: 10% | C10: 10% | D10: 10%
A11: Round-Trip Efficiency | B11: 85% | C11: 86% | D11: 85%
A12: Annual Degradation | B12: 2.5% | C12: 2.0% | D12: 2.5%
A13: Cycle Life | B13: 6000 | C13: 6500 | D13: 6000
A14: Cycles per Day | B14: 1 | C14: 1 | D14: 1
A15: Learning Rate | B15: 12% | C15: 10% | D15: 11%
A17: Tax Credits (BESS-Specific)
A18: ITC Base Rate | B18: 30% | C18: 30% | D18: 30%
A19: ITC Adders | B19: 0% | C19: 0% | D19: 10%
A21: Infrastructure (Common)
A22: Interconnection ($/kW) | B22: 100 | C22: 90 | D22: 120
A23: Land ($/kW) | B23: 10 | C23: 8 | D23: 15
A24: Permitting ($/kW) | B24: 15 | C24: 12 | D24: 20
A25: Insurance (% CapEx) | B25: 0.5% | C25: 0.5% | D25: 0.5%
A26: Property Tax (%) | B26: 1.0% | C26: 1.0% | D26: 1.05%
A28: Financing Structure
A29: Debt Percentage | B29: 60% | C29: 55% | D29: 65%
A30: Interest Rate | B30: 4.5% | C30: 5.0% | D30: 4.0%
A31: Loan Term (years) | B31: 15 | C31: 15 | D31: 20
A32: Cost of Equity | B32: 10% | C32: 12% | D32: 9.5%
A33: Tax Rate | B33: 21% | C33: 21% | D33: 21%
A34: Calculated WACC | B34: 6.5% | C34: 7.5% | D34: 6.0%
A36: Benefits ($/kW-yr)
A37: Resource Adequacy [common] | B37: 150 | C37: 140 | D37: 180
A38: Energy Arbitrage [common] | B38: 40 | C38: 45 | D38: 35
A39: Ancillary Services [common] | B39: 15 | C39: 12 | D39: 10
A40: T&D Deferral [common] | B40: 25 | C40: 20 | D40: 25
A41: Resilience Value [common] | B41: 50 | C41: 45 | D41: 60
A42: Renewable Integration [bess] | B42: 25 | C42: 20 | D42: 30
A43: GHG Emissions Value [bess] | B43: 15 | C43: 12 | D43: 20
A44: Voltage Support [common] | B44: 8 | C44: 6 | D44: 10

Sheet VBA_Code
B1: VBA Macro Code & Setup Instructions
B3: STEP-BY-STEP INSTRUCTIONS TO ENABLE MACROS
B4: Step 1: | C4: Save this workbook as a Macro-Enabled Workbook (.xlsm)
B5: File > Save As > Choose 'Excel Macro-Enabled Workbook (*.xlsm)'
B6: Step 2: | C6: Open the VBA Editor
B7: Press Alt + F11 (Windows) or Option + F11 (Mac)
B8: Step 3: | C8: Insert a new Module
B9: Right-click on 'VBAProject' in the left panel > Insert > Module
B10: Step 4: | C10: Copy the VBA code below and paste it into the Module
B11: Select all the code in the 'COMPLETE VBA CODE' section below
B12: Step 5: | C12: Close the VBA Editor (File > Close and Return to Microsoft Excel)
B13: Step 6: | C13: Create buttons on the Inputs sheet (optional)
B14: Developer tab > Insert > Button (Form Control) > Draw button > Assign macro
B15: Create buttons for: LoadNRELLibrary, LoadLazardLibrary, LoadCPUCLibrary
B16: Step 7: | C16: Save the workbook again to preserve the macros
B19: COMPLETE VBA CODE - COPY ALL BELOW
B21: Option Explicit
B23: '=================================================================
B24: ' BESS ANALYZER VBA MACROS
B25: ' Copy this entire module into your VBA project
B26: '
B27: ' CELL REFERENCE MAP (Inputs sheet):
B28: ' - Selected Library: C6
B29: ' - Capacity MW: C12, Duration: C13
B30: ' - Technology: C19 to C24
B31: ' - Costs: C26 to C32
B32: ' - ITC: C34, C35
... B443: AVAILABLE MACROS - QUICK REFERENCE
B444: LoadNRELLibrary | C444: Loads NREL Annual Technology Baseline 2024 (Moderate) assumptions
B445: LoadLazardLibrary | C445: Loads Lazard Levelized Cost of Storage v10.0 (2025) assumptions
B446: LoadCPUCLibrary | C446: Loads CPUC California 2024 assumptions with 10% ITC Energy Community Adder
B447: GenerateReport | C447: Creates a summary report on a new 'Report' sheet
B448: ExportToPDF | C448: Exports the Report sheet to a PDF file
B449: RefreshCalculations | C449: Forces full recalculation of all workbook formulas
B450: ShowAbout | C450: Displays information about the BESS Analyzer
B453: CELL REFERENCE MAP (Inputs Sheet)
B454: Selected Library | C454: C6
B455: Capacity (MW) | C455: C12
B456: Duration (hours) | C456: C13
B457: Energy Capacity (MWh) | C457: C14
...
